Workbook

Sheet Sheet1
A1: 1/10集計 ＯＳＳ様 ＢＨ出荷計画情報（25年度ボギー集計） | N1: 注：T-No＝V8累計台数+ 13台（破損機）
H2: Ｖ８(VUS-) | P2: V９（ | Q2: YBS-）
B3: 光真ss 出荷月 | C3: LAZ901 LA001～4 LC001 | D3: LAZ001 LB001 LB003～5 LD001 | E3: LAZ002 LA007,9,10 LB002,6 LB105 LC002 LD003 | F3: LAZ003 LD002 LD002(H) | G3: LAZ004 LD004 | H3: LAZ101 LA001～6､8 LA011,012 LB001,3～5 LB101,3,4,6～9 LB112 LC001,LD001 | I3: LAZ102 LB102 LB112 | J3: LAZ103 ＬＢ110 ＬＢ111 | K3: LAZ201 LC091 LD091 LD092 | L3: Ｖ８ 合計 | M3: Ｖ８ 累計 | N3: LAY 001 | O3: LAY 002 | P3: LAZ001 LAZ002 | Q3: Ｖ９ 累計 | R3: ＢＨ合計 | S3: VU-LA004 | T3: VU-LA007 | U3: VU-LA012 | V3: VU-LB002 | W3: VU-LB006 | X3: VU-LB101 | Y3: VU-LB102 | Z3: VU-LB106 | AA3: VU-LB112 | AB3: VU-LC002 | AC3: VU-LD091 | AD3: YB-LA001 | AE3: YB-LA002
A4: 10年度 | B4: ５月 | C4: 3 | D4: 3 | L4: 6 | M4: 6 | N4: 6 | O4: 0 | R4: =L4+P4 -> 6
B5: ６月 | C5: 0 | D5: 51 | L5: 51 | M5: 57 | N5: 51 | O5: 0 | R5: =L5+P5 -> 51
B6: ７月 | C6: 7 | D6: 65 | L6: 72 | M6: 129 | N6: 72 | O6: 0 | R6: =L6+P6 -> 72
B7: ８月 | C7: 2 | D7: 69 | L7: 71 | M7: 200 | N7: 71 | O7: 0 | R7: =L7+P7 -> 71
A8: 【Ｖ８】 | B8: ９月 | C8: 76 | D8: 18 | L8: 94 | M8: 294 | N8: 94 | O8: 0 | R8: =L8+P8 -> 94
A9: =SUM(L4:L15) -> 838 | B9: １０月 | C9: 86 | D9: 40 | L9: 126 | M9: 420 | N9: 126 | O9: 0 | R9: =L9+P9 -> 126
B10: １１月 | C10: 101 | D10: 29 | L10: 130 | M10: 550 | N10: 130 | O10: 0 | R10: =L10+P10 -> 130
A11: 【合計】 | B11: １２月 | C11: 106 | D11: 6 | L11: 112 | M11: 662 | N11: 112 | O11: 0 | R11: =L11+P11 -> 112
A12: =A6+A9 -> 838 | B12: 11/１月 | C12: 45 | D12: 42 | L12: 87 | M12: 749 | N12: 87 | O12: 0 | R12: =L12+P12 -> 87
B13: ２月 | C13: 3 | D13: 73 | L13: 76 | M13: 825 | N13: 76 | O13: 0 | R13: =L13+P13 -> 76
B14: ３月 | C14: 0 | D14: 3 | L14: 3 | M14: 828 | N14: 3 | O14: 0 | R14: =L14+P14 -> 3
B15: ４月 | C15: 10 | D15: 0 | L15: 10 | M15: 838 | N15: 10 | O15: 0 | R15: =L15+P15 -> 10
A16: 11年度 | B16: ５月 | C16: 5 | D16: 1 | E16: 0 | L16: 6 | M16: 844 | N16: 6 | O16: 0 | R16: =L16+P16 -> 6
B17: ６月 | C17: 12 | D17: 0 | E17: 0 | L17: 12 | M17: 856 | N17: 12 | O17: 0 | R17: =L17+P17 -> 12
B18: ７月 | C18: 25 | D18: 0 | E18: 0 | L18: 25 | M18: 881 | N18: 25 | O18: 0 | R18: =L18+P18 -> 25
B19: ８月 | C19: 16 | D19: 0 | E19: 0 | L19: 16 | M19: 897 | N19: 16 | O19: 0 | R19: =L19+P19 -> 16
A20: 【Ｖ８】 | B20: ９月 | C20: 31 | D20: 0 | E20: 1 | L20: 32 | M20: 929 | N20: 31 | O20: 1 | R20: =L20+P20 -> 32
A21: =SUM(L16:L27) -> 422 | B21: １０月 | C21: 28 | D21: 8 | E21: 0 | L21: 36 | M21: 965 | N21: 36 | O21: 0 | R21: =L21+P21 -> 36
B22: １１月 | C22: 19 | D22: 46 | E22: 9 | L22: 74 | M22: 1039 | N22: 65 | O22: 9 | R22: =L22+P22 -> 74
A23: 【合計】 | B23: １２月 | C23: 17 | D23: 25 | E23: 15 | L23: 57 | M23: 1096 | N23: 42 | O23: 15 | R23: =L23+P23 -> 57
A24: =A18+A21 -> 422 | B24: 12/１月 | C24: 23 | D24: 40 | E24: 0 | L24: 63 | M24: 1159 | N24: 63 | O24: 0 | R24: =L24+P24 -> 63
B25: ２月 | C25: 7 | D25: 22 | E25: 0 | L25: 29 | M25: 1188 | N25: 29 | O25: 0 | R25: =L25+P25 -> 29
B26: ３月 | C26: 14 | D26: 7 | E26: 0 | L26: 21 | M26: 1209 | N26: 21 | O26: 0 | R26: =L26+P26 -> 21
B27: ４月 | C27: 39 | D27: 12 | E27: 0 | L27: 51 | M27: 1260 | N27: 51 | O27: 0 | R27: =L27+P27 -> 51
A28: １２年度 | B28: ５月 | C28: 23 | D28: 11 | E28: 0 | F28: 0 | H28: 0 | L28: 34 | M28: 1294 | N28: 34 | O28: 0 | R28: =L28+P28 -> 34
B29: ６月 | C29: 46 | D29: 28 | E29: 3 | F29: 0 | H29: 0 | L29: 77 | M29: 1371 | N29: 74 | O29: 3 | R29: =L29+P29 -> 77
B30: ７月 | C30: 15 | D30: 24 | E30: 14 | F30: 0 | H30: 0 | L30: 53 | M30: 1424 | N30: 39 | O30: 14 | R30: =L30+P30 -> 53
B31: ８月 | C31: 0 | D31: 5 | E31: 2 | F31: 0 | H31: 0 | L31: 7 | M31: 1431 | N31: 5 | O31: 2 | R31: =L31+P31 -> 7
A32: 【Ｖ８】 | B32: ９月 | C32: 0 | D32: 4 | E32: 0 | F32: 0 | H32: 0 | L32: 4 | M32: 1435 | N32: 4 | O32: 0 | R32: =L32+P32 -> 4
A33: =SUM(L28:L39) -> 362 | B33: １０月 | C33: 0 | D33: 41 | E33: 3 | F33: 0 | H33: 0 | L33: 44 | M33: 1479 | N33: 41 | O33: 3 | R33: =L33+P33 -> 44
B34: １１月 | C34: 19 | D34: 17 | E34: 4 | F34: 13 | H34: 0 | L34: 53 | M34: 1532 | N34: 49 | O34: 4 | R34: =L34+P34 -> 53
A35: 【合計】 | B35: １２月 | C35: 10 | D35: 20 | E35: 0 | F35: 0 | H35: 27 | L35: 57 | M35: 1589 | N35: 57 | O35: 0 | R35: =L35+P35 -> 57
A36: =A30+A33 -> 362 | B36: 13/1月 | C36: 5 | D36: 22 | E36: 0 | F36: 0 | H36: 0 | L36: 27 | M36: 1616 | N36: 27 | O36: 0 | R36: =L36+P36 -> 27
B37: ２月 | C37: 0 | D37: 0 | E37: 0 | F37: 0 | H37: 0 | L37: 0 | M37: 1616 | N37: 0 | O37: 0 | R37: =L37+P37 -> 0
B38: ３月 | C38: 1 | D38: 4 | E38: 0 | F38: 0 | H38: 1 | L38: 6 | M38: 1622 | N38: 6 | O38: 0 | R38: =L38+P38 -> 6
B39: ４月 | C39: 0 | D39: 0 | E39: 0 | F39: 0 | H39: 0 | I39: 0 | L39: 0 | M39: 1622 | N39: 0 | O39: 0 | R39: =L39+P39 -> 0
A40: １３年度 | B40: ５月 | C40: 0 | D40: 0 | E40: 0 | F40: 34 | H40: 39 | I40: 0 | L40: 73 | M40: 1695 | N40: 73 | O40: 0 | R40: =L40+P40 -> 73
...

Sheet Sheet2
A3: 行ラベル | B3: 合計 / LAA101Q | C3: 合計 / LAF001Q | D3: 合計 / LAF002Q | E3: 合計 / LAF003Q | F3: 合計 / LAG001Q | G3: 合計 / LAG002Q | H3: 合計 / LAE101Q | I3: 合計 / LAE102Q | J3: 合計 / LAE201Q | K3: 合計 / LBL001Q | L3: 合計 / LBL002Q | M3: 合計 / LAL001Q | N3: 合計 / LAN001Q | O3: 合計 / LAN002Q | P3: 合計 / LCN001Q | Q3: 合計 / LAC001Q | R3: 合計 / LAC002Q | S3: 合計 / LCC001Q | T3: 合計 / LCC002Q | U3: 合計 / LAD001Q | V3: 合計 / LAD002Q | W3: 合計 / LCD001Q | X3: 合計 / LCD002Q | Y3: 合計 / LAH001Q | Z3: 合計 / 新LAA001Q | AA3: 合計 / 新LAＦ001Q | AB3: 合計 / 新LAＧ001Q | AC3: 合計 / 新LAＥ001Q | AD3: 合計 / 新LAL001Q | AE3: 合計 / 新LAN001Q | AF3: 合計 / 新LAC001Q | AG3: 合計 / 新LAD001Q | AH3: 合計 / 新LAH001Q
A4: 25/12 | B4: 6 | C4: 6 | D4: 0 | E4: 0 | F4: 6 | G4: 0 | H4: 6 | I4: 0 | J4: 0 | K4: 0 | L4: 4 | M4: 2 | N4: 6 | O4: 0 | P4: 0 | Q4: 6 | R4: 0 | S4: 0 | T4: 0 | U4: 6 | V4: 0 | W4: 0 | X4: 0 | Y4: 6 | Z4: 0 | AA4: 0 | AB4: 0 | AC4: 0 | AD4: 0 | AE4: 0 | AF4: 0 | AG4: 0 | AH4: 0
A5: 26/01 | B5: 60 | C5: 41 | D5: 0 | E5: 0 | F5: 64 | G5: 0 | H5: 31 | I5: 2 | J5: 8 | K5: 5 | L5: 19 | M5: 17 | N5: 29 | O5: 0 | P5: 8 | Q5: 29 | R5: 0 | S5: 0 | T5: 8 | U5: 42 | V5: 0 | W5: 0 | X5: 8 | Y5: 36 | Z5: 61 | AA5: 61 | AB5: 61 | AC5: 61 | AD5: 61 | AE5: 64 | AF5: 61 | AG5: 61 | AH5: 11
A6: 26/02 | B6: 9 | C6: 8 | D6: 0 | E6: 0 | F6: 54 | G6: 0 | H6: 6 | I6: 2 | J6: 1 | K6: 0 | L6: 9 | M6: 2 | N6: 5 | O6: 0 | P6: 1 | Q6: 11 | R6: 0 | S6: 0 | T6: 1 | U6: 9 | V6: 0 | W6: 0 | X6: 1 | Y6: 6 | Z6: 25 | AA6: 30 | AB6: 25 | AC6: 25 | AD6: 25 | AE6: 31 | AF6: 33 | AG6: 30 | AH6: 8
A7: 26/03 | B7: 18 | C7: 16 | D7: 0 | E7: 0 | F7: 18 | G7: 0 | H7: 7 | I7: 5 | J7: 4 | K7: 0 | L7: 9 | M7: 7 | N7: 12 | O7: 0 | P7: 4 | Q7: 12 | R7: 0 | S7: 0 | T7: 4 | U7: 12 | V7: 0 | W7: 0 | X7: 4 | Y7: 16 | Z7: 14 | AA7: 14 | AB7: 14 | AC7: 14 | AD7: 14 | AE7: 14 | AF7: 14 | AG7: 14 | AH7: 14
A8: 26/04 | B8: 13 | C8: 13 | D8: 0 | E8: 0 | F8: 13 | G8: 0 | H8: 1 | I8: 7 | J8: 5 | K8: 0 | L8: 13 | M8: 0 | N8: 8 | O8: 0 | P8: 5 | Q8: 8 | R8: 0 | S8: 0 | T8: 5 | U8: 8 | V8: 0 | W8: 0 | X8: 5 | Y8: 13 | Z8: 68 | AA8: 68 | AB8: 68 | AC8: 68 | AD8: 68 | AE8: 68 | AF8: 68 | AG8: 68 | AH8: 68
A9: 26/05 | B9: 33 | C9: 33 | D9: 0 | E9: 0 | F9: 33 | G9: 0 | H9: 30 | I9: 3 | J9: 0 | K9: 9 | L9: 3 | M9: 21 | N9: 28 | O9: 0 | P9: 5 | Q9: 28 | R9: 0 | S9: 0 | T9: 5 | U9: 28 | V9: 0 | W9: 0 | X9: 5 | Y9: 33 | Z9: 104 | AA9: 104 | AB9: 104 | AC9: 104 | AD9: 104 | AE9: 104 | AF9: 104 | AG9: 104 | AH9: 104
A10: 26/06 | B10: 35 | C10: 35 | D10: 0 | E10: 0 | F10: 35 | G10: 0 | H10: 32 | I10: 3 | J10: 0 | K10: 16 | L10: 3 | M10: 16 | N10: 35 | O10: 0 | P10: 0 | Q10: 35 | R10: 0 | S10: 0 | T10: 0 | U10: 35 | V10: 0 | W10: 0 | X10: 0 | Y10: 35 | Z10: 138 | AA10: 138 | AB10: 138 | AC10: 138 | AD10: 138 | AE10: 138 | AF10: 138 | AG10: 138 | AH10: 138
A11: 26/07 | B11: 7 | C11: 7 | D11: 0 | E11: 0 | F11: 7 | G11: 0 | H11: 2 | I11: 5 | J11: 0 | K11: 0 | L11: 5 | M11: 2 | N11: 7 | O11: 0 | P11: 0 | Q11: 7 | R11: 0 | S11: 0 | T11: 0 | U11: 7 | V11: 0 | W11: 0 | X11: 0 | Y11: 7 | Z11: 91 | AA11: 91 | AB11: 91 | AC11: 91 | AD11: 91 | AE11: 91 | AF11: 91 | AG11: 91 | AH11: 91
A12: 26/08 | B12: 35 | C12: 35 | D12: 0 | E12: 0 | F12: 35 | G12: 0 | H12: 15 | I12: 12 | J12: 8 | K12: 0 | L12: 26 | M12: 9 | N12: 27 | O12: 0 | P12: 8 | Q12: 27 | R12: 0 | S12: 0 | T12: 8 | U12: 27 | V12: 0 | W12: 0 | X12: 8 | Y12: 35 | Z12: 163 | AA12: 163 | AB12: 163 | AC12: 163 | AD12: 163 | AE12: 163 | AF12: 163 | AG12: 163 | AH12: 163
A13: 26/09 | B13: 20 | C13: 20 | D13: 0 | E13: 0 | F13: 20 | G13: 0 | H13: 16 | I13: 4 | J13: 0 | K13: 0 | L13: 4 | M13: 16 | N13: 20 | O13: 0 | P13: 0 | Q13: 20 | R13: 0 | S13: 0 | T13: 0 | U13: 20 | V13: 0 | W13: 0 | X13: 0 | Y13: 20 | Z13: 131 | AA13: 131 | AB13: 131 | AC13: 131 | AD13: 131 | AE13: 131 | AF13: 131 | AG13: 131 | AH13: 90
A14: 26/10 | B14: 39 | C14: 39 | D14: 0 | E14: 0 | F14: 39 | G14: 0 | H14: 39 | I14: 0 | J14: 0 | K14: 0 | L14: 10 | M14: 29 | N14: 27 | O14: 0 | P14: 12 | Q14: 27 | R14: 0 | S14: 0 | T14: 12 | U14: 27 | V14: 0 | W14: 0 | X14: 12 | Y14: 39 | Z14: 90 | AA14: 90 | AB14: 90 | AC14: 90 | AD14: 90 | AE14: 90 | AF14: 90 | AG14: 90 | AH14: 90
A15: 26/11 | B15: 32 | C15: 32 | D15: 0 | E15: 0 | F15: 32 | G15: 0 | H15: 32 | I15: 0 | J15: 0 | K15: 0 | L15: 10 | M15: 22 | N15: 32 | O15: 0 | P15: 0 | Q15: 32 | R15: 0 | S15: 0 | T15: 0 | U15: 32 | V15: 0 | W15: 0 | X15: 0 | Y15: 32 | Z15: 135 | AA15: 135 | AB15: 135 | AC15: 135 | AD15: 135 | AE15: 135 | AF15: 135 | AG15: 135 | AH15: 85
... A21: 総計 | B21: 527 | C21: 505 | D21: 0 | E21: 0 | F21: 576 | G21: 0 | H21: 435 | I21: 45 | J21: 26 | K21: 30 | L21: 241 | M21: 237 | N21: 441 | O21: 0 | P21: 58 | Q21: 447 | R21: 0 | S21: 0 | T21: 58 | U21: 458 | V21: 0 | W21: 0 | X21: 58 | Y21: 498 | Z21: 1195 | AA21: 1200 | AB21: 1195 | AC21: 1195 | AD21: 1195 | AE21: 1204 | AF21: 1203 | AG21: 1200 | AH21: 987

Sheet 日程表
BO1: 合計数量→ | BP1: =SUM(BP5:BP410) -> 527 | BQ1: =SUM(BQ5:BQ410) -> 505 | BR1: =SUM(BR5:BR410) -> 0 | BS1: =SUM(BS5:BS410) -> 0 | BT1: =SUM(BT5:BT410) -> 576 | BU1: =SUM(BU5:BU410) -> 0 | BV1: =SUM(BV5:BV410) -> 435 | BW1: =SUM(BW5:BW410) -> 45 | ... CV1: =SUM(CV5:CV410) -> 987
B3: 1 | C3: 2 | D3: 3 | E3: 4 | F3: 5 | G3: 6 | H3: 7 | I3: 8 | J3: 9 | K3: 10 | L3: 11 | M3: 12 | N3: 13 | O3: 14 | P3: 15 | Q3: 16 | R3: 17 | S3: 18 | T3: 19 | U3: 20 | V3: 21 | W3: 22 | X3: 23 | Y3: 24 | Z3: 25 | AA3: 26 | AB3: 27 | AC3: 28 | AD3: 29 | AE3: 30 | AF3: 31 | AG3: 32 | AH3: 33 | AI3: V8P/S2 | AJ3: V8P/S3 | AK3: V8P/S4 | AL3: V8P/S5 | AM3: V8P/S6 | AN3: V8P/S7 | AO3: V8P/S8 | AP3: V8P/S9 | AQ3: V8P/S10 | AR3: V8P/S11 | AS3: V8P/S12 | AT3: V8P/S13 | AU3: V8P/S14 | AV3: V8P/S15 | AW3: V8P/S16 | AX3: V8P/S17 | AY3: V8P/S18 | AZ3: V8P/S19 | BA3: V8P/S20 | BB3: V8P/S21 | BC3: V8P/S22 | BD3: V8P/S23 | BE3: V8P/S24 | BF3: V8P/S34 | BG3: V9P/S2 | BH3: V9P/S3 | BI3: V9P/S4 | BJ3: V9P/S5 | BK3: V9P/S6 | BL3: V9P/S7 | BM3: V9P/S8 | BN3: V9P/S9 | BO3: V9P/S10 | BP3: V8 QYT | BQ3: V8 QYT | BR3: V8 QYT | BS3: V8 QYT | BT3: V8 QYT | BU3: V8 QYT | BV3: V8 QYT | BW3: V8 QYT | BX3: V8 QYT | BY3: V8 QYT | BZ3: V8 QYT | CA3: V8 QYT | CB3: V8 QYT | CC3: V8 QYT | CD3: V8 QYT | CE3: V8 QYT | CF3: V8 QYT | CG3: V8 QYT | CH3: V8 QYT | CI3: V8 QYT | CJ3: V8 QYT | CK3: V8 QYT | CL3: V8 QYT | CM3: V8 QYT | CN3: Ｖ９ QYT | CO3: Ｖ９ QYT | CP3: Ｖ９ QYT | CQ3: Ｖ９ QYT | CR3: Ｖ９ QYT | CS3: Ｖ９ QYT | CT3: Ｖ９ QYT | CU3: Ｖ９ QYT | CV3: Ｖ９ QYT
A4: № | B4: 生産計画№ | C4: 客先名 | D4: 駅名 | E4: コーナー | F4: 機種名 | G4: 型式 | H4: 機器品番 | I4: 属性 | J4: 正式 品番 | K4: 追加 仕様 | L4: 数量 | M4: 順序指示 発行日 | N4: 光真ss 出荷日 | O4: M/C 着手日 | P4: 機器 ﾘﾘｰｽ日 | Q4: 実出荷 | R4: KP-No | S4: BH型式 TYPE | T4: V7ｶｾｯﾄ 品番 | U4: MODEL | V4: shipment month | W4: T-No | X4: V７号機 | Y4: V8-LAZ 型式 | Z4: V8-LAY 型式 | AA4: Z002 号機 | AB4: Z003 号機 | AC4: Z004 号機 | AD4: Z101 号機 | AE4: Z102 号機 | AF4: Z103 号機 | AG4: Z201 号機 | AH4: 備考 | AI4: LAA101 | AJ4: LAF001 | AK4: LAF002 | AL4: LAF003 | AM4: LAG001 | AN4: LAG002 | AO4: LAE101 | AP4: LAE102 | AQ4: LAE201 | AR4: LBL001 | AS4: LBL002 | AT4: LAL001 | AU4: LAN001 | AV4: LAN002 | AW4: LCN001 | AX4: LAC001 | AY4: LAC002 | AZ4: LCC001 | BA4: LCC002 | BB4: LAD001 | BC4: LAD002 | BD4: LCD001 | BE4: LCD002 | BF4: LAH001 | BG4: LAA001 | BH4: LAF001 | BI4: LAG001 | BJ4: LAE001 | BK4: LAL001 | BL4: LAN001 | BM4: LAC001 | BN4: LAD001 | BO4: LAH001 | BP4: LAA101Q | BQ4: LAF001Q | BR4: LAF002Q | BS4: LAF003Q | BT4: LAG001Q | BU4: LAG002Q | BV4: LAE101Q | BW4: LAE102Q | BX4: LAE201Q | BY4: LBL001Q | BZ4: LBL002Q | CA4: LAL001Q | CB4: LAN001Q | CC4: LAN002Q | CD4: LCN001Q | CE4: LAC001Q | CF4: LAC002Q | CG4: LCC001Q | CH4: LCC002Q | CI4: LAD001Q | CJ4: LAD002Q | CK4: LCD001Q | CL4: LCD002Q | CM4: LAH001Q | CN4: 新LAA001Q | CO4: 新LAＦ001Q | CP4: 新LAＧ001Q | CQ4: 新LAＥ001Q | CR4: 新LAL001Q | CS4: 新LAN001Q | CT4: 新LAC001Q | CU4: 新LAD001Q | CV4: 新LAH001Q
A5: 31 | B5: 000377924 | C5: 南海 | D5: 新今宮 | E5: ４F | F5: 南海V8EXV | G5: 3S2EU-FBP-1001 | H5: 2800681-5 | I5: 機器 | J5: 1 | K5: 回転台 | L5: 1 | M5: 45995 | N5: 46007 | O5: 46006 | P5: 46009 | R5: VV-26749 | S5: VU-LB106 | U5: V8 | V5: =TEXT(N5,"YY/MM") -> 25/12 | W5: 21326 | Y5: LAZ101 | Z5: LAY001 | AD5: 8201 | AI5: 1 | AJ5: 1 | AK5: 0 | AL5: 0 | AM5: 1 | AN5: 0 | AO5: 1 | AP5: 0 | AQ5: 0 | AR5: 0 | AS5: 1 | AT5: 0 | AU5: 1 | AV5: 0 | AW5: 0 | AX5: 1 | AY5: 0 | AZ5: 0 | BA5: 0 | BB5: 1 | BC5: 0 | BD5: 0 | BE5: 0 | BF5: 1 | BG5: 0 | BH5: 0 | BI5: 0 | BJ5: 0 | BK5: 0 | BL5: 0 | BM5: 0 | BN5: 0 | BO5: 0 | BP5: =$L5*AI5 -> 1 | BQ5: =$L5*AJ5 -> 1 | BR5: =$L5*AK5 -> 0 | BS5: =$L5*AL5 -> 0 | BT5: =$L5*AM5 -> 1 | BU5: =$L5*AN5 -> 0 | BV5: =$L5*AO5 -> 1 | BW5: =$L5*AP5 -> 0 | ... CV5: =$L5*BO5 -> 0
A6: 25 | B6: 000391729 | C6: N社（Ｎ） | E6: VU-LA007 | F6: V8-4BH | G6: VU-LA007 | H6: 3251849-9 | I6: 単体 | J6: 1 | L6: 1 | M6: 45999 | N6: 46009 | O6: 46008 | P6: 46008 | R6: MC-51692 | S6: VU-LA007 | U6: V8 | V6: =TEXT(N6,"YY/MM") -> 25/12 | W6: 21328 | Y6: LAZ002 | Z6: LAY002 | AA6: 3217 | AI6: 1 | AJ6: 1 | AK6: 0 | AL6: 0 | AM6: 1 | AN6: 0 | AO6: 1 | AP6: 0 | AQ6: 0 | AR6: 0 | AS6: 0 | AT6: 1 | AU6: 1 | AV6: 0 | AW6: 0 | AX6: 1 | AY6: 0 | AZ6: 0 | BA6: 0 | BB6: 1 | BC6: 0 | BD6: 0 | BE6: 0 | BF6: 1 | BG6: 0 | BH6: 0 | BI6: 0 | BJ6: 0 | BK6: 0 | BL6: 0 | BM6: 0 | BN6: 0 | BO6: 0 | BP6: =$L6*AI6 -> 1 | BQ6: =$L6*AJ6 -> 1 | BR6: =$L6*AK6 -> 0 | BS6: =$L6*AL6 -> 0 | BT6: =$L6*AM6 -> 1 | BU6: =$L6*AN6 -> 0 | BV6: =$L6*AO6 -> 1 | BW6: =$L6*AP6 -> 0 | ... CV6: =$L6*BO6 -> 0
A7: 43 | B7: 000378623 | C7: 小田急 | D7: 本鵠沼 | E7: 西口 | F7: 小田急V8EXV | G7: 3S2EU-FFP-1001 | H7: 2841859-5 | I7: 機器 | J7: 1 | K7: ｽﾀﾝﾄﾞ | L7: 1 | M7: 46000 | N7: 46010 | O7: 46009 | P7: 46014 | R7: VV-26755 | S7: VU-LA012 | U7: V8 | V7: =TEXT(N7,"YY/MM") -> 25/12 | W7: 21330 | Y7: LAZ101 | Z7: LAY001 | AD7: 8202 | AI7: 1 | AJ7: 1 | AK7: 0 | AL7: 0 | AM7: 1 | AN7: 0 | AO7: 1 | AP7: 0 | AQ7: 0 | AR7: 0 | AS7: 0 | AT7: 1 | AU7: 1 | AV7: 0 | AW7: 0 | AX7: 1 | AY7: 0 | AZ7: 0 | BA7: 0 | BB7: 1 | BC7: 0 | BD7: 0 | BE7: 0 | BF7: 1 | BG7: 0 | BH7: 0 | BI7: 0 | BJ7: 0 | BK7: 0 | BL7: 0 | BM7: 0 | BN7: 0 | BO7: 0 | BP7: =$L7*AI7 -> 1 | BQ7: =$L7*AJ7 -> 1 | BR7: =$L7*AK7 -> 0 | BS7: =$L7*AL7 -> 0 | BT7: =$L7*AM7 -> 1 | BU7: =$L7*AN7 -> 0 | BV7: =$L7*AO7 -> 1 | BW7: =$L7*AP7 -> 0 | ... CV7: =$L7*BO7 -> 0
A8: 52 | B8: 000377925 | C8: 南海 | D8: 天下茶屋 | F8: 南海V8EXV | G8: 3S2EU-FBP-1001 | H8: 2800681-5 | I8: 機器 | J8: 1 | K8: 回転台 | L8: 1 | M8: 46002 | N8: 46014 | O8: 46013 | P8: 46016 | R8: VV-26760 | S8: VU-LB106 | U8: V8 | V8: =TEXT(N8,"YY/MM") -> 25/12 | W8: 21331 | Y8: LAZ101 | Z8: LAY001 | AD8: 8203 | AI8: 1 | AJ8: 1 | AK8: 0 | AL8: 0 | AM8: 1 | AN8: 0 | AO8: 1 | AP8: 0 | AQ8: 0 | AR8: 0 | AS8: 1 | AT8: 0 | AU8: 1 | AV8: 0 | AW8: 0 | AX8: 1 | AY8: 0 | AZ8: 0 | BA8: 0 | BB8: 1 | BC8: 0 | BD8: 0 | BE8: 0 | BF8: 1 | BG8: 0 | BH8: 0 | BI8: 0 | BJ8: 0 | BK8: 0 | BL8: 0 | BM8: 0 | BN8: 0 | BO8: 0 | BP8: =$L8*AI8 -> 1 | BQ8: =$L8*AJ8 -> 1 | BR8: =$L8*AK8 -> 0 | BS8: =$L8*AL8 -> 0 | BT8: =$L8*AM8 -> 1 | BU8: =$L8*AN8 -> 0 | BV8: =$L8*AO8 -> 1 | BW8: =$L8*AP8 -> 0 | ... CV8: =$L8*BO8 -> 0
A9: 56 | B9: 000381123 | C9: 南海 | D9: 萩ノ茶屋 | F9: 南海V8 | G9: 3S2VU-FBP-0003 | H9: 3690047-9 | I9: 機器 | J9: 1 | L9: 1 | M9: 46003 | N9: 46015 | O9: 46014 | P9: 46017 | R9: VV-26763 | S9: VU-LB106 | U9: V8 | V9: =TEXT(N9,"YY/MM") -> 25/12 | W9: 21332 | Y9: LAZ101 | Z9: LAY001 | AD9: 8204 | AI9: 1 | AJ9: 1 | AK9: 0 | AL9: 0 | AM9: 1 | AN9: 0 | AO9: 1 | AP9: 0 | AQ9: 0 | AR9: 0 | AS9: 1 | AT9: 0 | AU9: 1 | AV9: 0 | AW9: 0 | AX9: 1 | AY9: 0 | AZ9: 0 | BA9: 0 | BB9: 1 | BC9: 0 | BD9: 0 | BE9: 0 | BF9: 1 | BG9: 0 | BH9: 0 | BI9: 0 | BJ9: 0 | BK9: 0 | BL9: 0 | BM9: 0 | BN9: 0 | BO9: 0 | BP9: =$L9*AI9 -> 1 | BQ9: =$L9*AJ9 -> 1 | BR9: =$L9*AK9 -> 0 | BS9: =$L9*AL9 -> 0 | BT9: =$L9*AM9 -> 1 | BU9: =$L9*AN9 -> 0 | BV9: =$L9*AO9 -> 1 | BW9: =$L9*AP9 -> 0 | ... CV9: =$L9*BO9 -> 0
A10: 57 | B10: 000381124 | C10: 南海 | D10: 粉浜 | F10: 南海V8 | G10: 3S2VU-FBP-0003 | H10: 3690047-9 | I10: 機器 | J10: 1 | L10: 1 | M10: 46003 | N10: 46015 | O10: 46014 | P10: 46017 | R10: VV-26764 | S10: VU-LB106 | U10: V8 | V10: =TEXT(N10,"YY/MM") -> 25/12 | W10: 21333 | Y10: LAZ101 | Z10: LAY001 | AD10: 8205 | AI10: 1 | AJ10: 1 | AK10: 0 | AL10: 0 | AM10: 1 | AN10: 0 | AO10: 1 | AP10: 0 | AQ10: 0 | AR10: 0 | AS10: 1 | AT10: 0 | AU10: 1 | AV10: 0 | AW10: 0 | AX10: 1 | AY10: 0 | AZ10: 0 | BA10: 0 | BB10: 1 | BC10: 0 | BD10: 0 | BE10: 0 | BF10: 1 | BG10: 0 | BH10: 0 | BI10: 0 | BJ10: 0 | BK10: 0 | BL10: 0 | BM10: 0 | BN10: 0 | BO10: 0 | BP10: =$L10*AI10 -> 1 | BQ10: =$L10*AJ10 -> 1 | BR10: =$L10*AK10 -> 0 | BS10: =$L10*AL10 -> 0 | BT10: =$L10*AM10 -> 1 | BU10: =$L10*AN10 -> 0 | BV10: =$L10*AO10 -> 1 | BW10: =$L10*AP10 -> 0 | ... CV10: =$L10*BO10 -> 0
A11: 75 | B11: 000385490 | C11: 設計設備 | D11: 下諏訪(本屋)駅設定 | F11: JR東EX20総（V） | G11: 3S2EU-RBP-0001 | H11: 5647075-6 | I11: 機器 | J11: 0 | L11: 1 | M11: 46008 | N11: 46027 | O11: 46017 | P11: 46029 | R11: VV-26775 | S11: VU-LD091 | U11: V8 | V11: =TEXT(N11,"YY/MM") -> 26/01 | W11: 21334 | Y11: LAZ201 | Z11: LAY001 | AG11: 3524 | AI11: 1 | AJ11: 1 | AK11: 0 | AL11: 0 | AM11: 1 | AN11: 0 | AO11: 0 | AP11: 0 | AQ11: 1 | AR11: 0 | AS11: 1 | AT11: 0 | AU11: 0 | AV11: 0 | AW11: 1 | AX11: 0 | AY11: 0 | AZ11: 0 | BA11: 1 | BB11: 0 | BC11: 0 | BD11: 0 | BE11: 1 | BF11: 1 | BG11: 0 | BH11: 0 | BI11: 0 | BJ11: 0 | BK11: 0 | BL11: 0 | BM11: 0 | BN11: 0 | BO11: 0 | BP11: =$L11*AI11 -> 1 | BQ11: =$L11*AJ11 -> 1 | BR11: =$L11*AK11 -> 0 | BS11: =$L11*AL11 -> 0 | BT11: =$L11*AM11 -> 1 | BU11: =$L11*AN11 -> 0 | BV11: =$L11*AO11 -> 0 | BW11: =$L11*AP11 -> 0 | ... CV11: =$L11*BO11 -> 0
A12: 80 | B12: 000393963 | C12: 設計設備 | D12: 下諏訪(本屋)駅設定 | F12: JR東EX20総（V） | G12: 3S2EU-RBP-0001 | H12: 5647075-6 | I12: 機器 | J12: 0 | L12: 1 | M12: 46009 | N12: 46028 | O12: 46027 | P12: 46030 | R12: VV-26777 | S12: VU-LD091 | U12: V8 | V12: =TEXT(N12,"YY/MM") -> 26/01 | W12: 21335 | Y12: LAZ201 | Z12: LAY001 | AG12: 3525 | AI12: 1 | AJ12: 1 | AK12: 0 | AL12: 0 | AM12: 1 | AN12: 0 | AO12: 0 | AP12: 0 | AQ12: 1 | AR12: 0 | AS12: 1 | AT12: 0 | AU12: 0 | AV12: 0 | AW12: 1 | AX12: 0 | AY12: 0 | AZ12: 0 | BA12: 1 | BB12: 0 | BC12: 0 | BD12: 0 | BE12: 1 | BF12: 1 | BG12: 0 | BH12: 0 | BI12: 0 | BJ12: 0 | BK12: 0 | BL12: 0 | BM12: 0 | BN12: 0 | BO12: 0 | BP12: =$L12*AI12 -> 1 | BQ12: =$L12*AJ12 -> 1 | BR12: =$L12*AK12 -> 0 | BS12: =$L12*AL12 -> 0 | BT12: =$L12*AM12 -> 1 | BU12: =$L12*AN12 -> 0 | BV12: =$L12*AO12 -> 0 | BW12: =$L12*AP12 -> 0 | ... CV12: =$L12*BO12 -> 0
A13: 88 | B13: 000393965 | C13: JREM | D13: 天王洲アイル | E13: 南 | F13: 東モノEX20総（V） | G13: 3S2EU-KRP-0001 | H13: 5821604-0 | I13: 機器 | J13: 1 | K13: めこみ | L13: 1 | M13: 46013 | N13: 46030 | O13: 46029 | P13: 46035 | R13: VV-26782 | S13: VU-LD091 | U13: V8 | V13: =TEXT(N13,"YY/MM") -> 26/01 | W13: 21336 | Y13: LAZ201 | Z13: LAY001 | AG13: 3526 | AI13: 1 | AJ13: 1 | AK13: 0 | AL13: 0 | AM13: 1 | AN13: 0 | AO13: 0 | AP13: 0 | AQ13: 1 | AR13: 0 | AS13: 1 | AT13: 0 | AU13: 0 | AV13: 0 | AW13: 1 | AX13: 0 | AY13: 0 | AZ13: 0 | BA13: 1 | BB13: 0 | BC13: 0 | BD13: 0 | BE13: 1 | BF13: 1 | BG13: 0 | BH13: 0 | BI13: 0 | BJ13: 0 | BK13: 0 | BL13: 0 | BM13: 0 | BN13: 0 | BO13: 0 | BP13: =$L13*AI13 -> 1 | BQ13: =$L13*AJ13 -> 1 | BR13: =$L13*AK13 -> 0 | BS13: =$L13*AL13 -> 0 | BT13: =$L13*AM13 -> 1 | BU13: =$L13*AN13 -> 0 | BV13: =$L13*AO13 -> 0 | BW13: =$L13*AP13 -> 0 | ... CV13: =$L13*BO13 -> 0
A14: 89 | B14: 000393967 | C14: JREM | D14: 天空橋 | E14: HiCity | F14: 東モノEX20総（V） | G14: 3S2EU-KRP-0001 | H14: 5821604-0 | I14: 機器 | J14: 1 | K14: めこみ | L14: 1 | M14: 46013 | N14: 46030 | O14: 46029 | P14: 46035 | R14: VV-26783 | S14: VU-LD091 | U14: V8 | V14: =TEXT(N14,"YY/MM") -> 26/01 | W14: 21337 | Y14: LAZ201 | Z14: LAY001 | AG14: 3527 | AI14: 1 | AJ14: 1 | AK14: 0 | AL14: 0 | AM14: 1 | AN14: 0 | AO14: 0 | AP14: 0 | AQ14: 1 | AR14: 0 | AS14: 1 | AT14: 0 | AU14: 0 | AV14: 0 | AW14: 1 | AX14: 0 | AY14: 0 | AZ14: 0 | BA14: 1 | BB14: 0 | BC14: 0 | BD14: 0 | BE14: 1 | BF14: 1 | BG14: 0 | BH14: 0 | BI14: 0 | BJ14: 0 | BK14: 0 | BL14: 0 | BM14: 0 | BN14: 0 | BO14: 0 | BP14: =$L14*AI14 -> 1 | BQ14: =$L14*AJ14 -> 1 | BR14: =$L14*AK14 -> 0 | BS14: =$L14*AL14 -> 0 | BT14: =$L14*AM14 -> 1 | BU14: =$L14*AN14 -> 0 | BV14: =$L14*AO14 -> 0 | BW14: =$L14*AP14 -> 0 | ... CV14: =$L14*BO14 -> 0
A15: 94 | B15: 000371187 | C15: JREM | D15: 天王洲アイル | E15: 中央 | F15: 東モノEX20総（V） | G15: 3S2EU-KRP-1001 | H15: 5833401-9 | I15: 機器 | J15: 1 | K15: 回転台 | L15: 1 | M15: 46014 | N15: 46031 | O15: 46030 | P15: 46036 | R15: VV-26786 | S15: VU-LD091 | U15: V8 | V15: =TEXT(N15,"YY/MM") -> 26/01 | W15: 21338 | Y15: LAZ201 | Z15: LAY001 | AG15: 3528 | AI15: 1 | AJ15: 1 | AK15: 0 | AL15: 0 | AM15: 1 | AN15: 0 | AO15: 0 | AP15: 0 | AQ15: 1 | AR15: 0 | AS15: 1 | AT15: 0 | AU15: 0 | AV15: 0 | AW15: 1 | AX15: 0 | AY15: 0 | AZ15: 0 | BA15: 1 | BB15: 0 | BC15: 0 | BD15: 0 | BE15: 1 | BF15: 1 | BG15: 0 | BH15: 0 | BI15: 0 | BJ15: 0 | BK15: 0 | BL15: 0 | BM15: 0 | BN15: 0 | BO15: 0 | BP15: =$L15*AI15 -> 1 | BQ15: =$L15*AJ15 -> 1 | BR15: =$L15*AK15 -> 0 | BS15: =$L15*AL15 -> 0 | BT15: =$L15*AM15 -> 1 | BU15: =$L15*AN15 -> 0 | BV15: =$L15*AO15 -> 0 | BW15: =$L15*AP15 -> 0 | ... CV15: =$L15*BO15 -> 0
A16: 95 | B16: 000393964 | C16: JREM | D16: 天空橋 | E16: 本屋 | F16: 東モノEX20総（V） | G16: 3S2EU-KRP-1001 | H16: 5833401-9 | I16: 機器 | J16: 1 | K16: 回転台 | L16: 1 | M16: 46014 | N16: 46031 | O16: 46030 | P16: 46036 | R16: VV-26787 | S16: VU-LD091 | U16: V8 | V16: =TEXT(N16,"YY/MM") -> 26/01 | W16: 21339 | Y16: LAZ201 | Z16: LAY001 | AG16: 3529 | AI16: 1 | AJ16: 1 | AK16: 0 | AL16: 0 | AM16: 1 | AN16: 0 | AO16: 0 | AP16: 0 | AQ16: 1 | AR16: 0 | AS16: 1 | AT16: 0 | AU16: 0 | AV16: 0 | AW16: 1 | AX16: 0 | AY16: 0 | AZ16: 0 | BA16: 1 | BB16: 0 | BC16: 0 | BD16: 0 | BE16: 1 | BF16: 1 | BG16: 0 | BH16: 0 | BI16: 0 | BJ16: 0 | BK16: 0 | BL16: 0 | BM16: 0 | BN16: 0 | BO16: 0 | BP16: =$L16*AI16 -> 1 | BQ16: =$L16*AJ16 -> 1 | BR16: =$L16*AK16 -> 0 | BS16: =$L16*AL16 -> 0 | BT16: =$L16*AM16 -> 1 | BU16: =$L16*AN16 -> 0 | BV16: =$L16*AO16 -> 0 | BW16: =$L16*AP16 -> 0 | ... CV16: =$L16*BO16 -> 0
A17: 100 | B17: 000375150 | C17: JREM | D17: JREM機械設備技術センター | F17: JR東EX20総（V） | G17: 3S2EU-RBP-0001 | H17: 5647075-6 | I17: 機器 | J17: 1 | L17: 1 | M17: 46015 | N17: 46035 | O17: 46031 | P17: 46037 | R17: VV-26790 | S17: VU-LD091 | U17: V8 | V17: =TEXT(N17,"YY/MM") -> 26/01 | W17: 21340 | Y17: LAZ201 | Z17: LAY001 | AG17: 3530 | AI17: 1 | AJ17: 1 | AK17: 0 | AL17: 0 | AM17: 1 | AN17: 0 | AO17: 0 | AP17: 0 | AQ17: 1 | AR17: 0 | AS17: 1 | AT17: 0 | AU17: 0 | AV17: 0 | AW17: 1 | AX17: 0 | AY17: 0 | AZ17: 0 | BA17: 1 | BB17: 0 | BC17: 0 | BD17: 0 | BE17: 1 | BF17: 1 | BG17: 0 | BH17: 0 | BI17: 0 | BJ17: 0 | BK17: 0 | BL17: 0 | BM17: 0 | BN17: 0 | BO17: 0 | BP17: =$L17*AI17 -> 1 | BQ17: =$L17*AJ17 -> 1 | BR17: =$L17*AK17 -> 0 | BS17: =$L17*AL17 -> 0 | BT17: =$L17*AM17 -> 1 | BU17: =$L17*AN17 -> 0 | BV17: =$L17*AO17 -> 0 | BW17: =$L17*AP17 -> 0 | ... CV17: =$L17*BO17 -> 0
A18: 101 | B18: 000393966 | C18: JREM | D18: 新整備場 | F18: 東モノEX20総（V） | G18: 3S2EU-KRP-1001 | H18: 5833401-9 | I18: 機器 | J18: 1 | K18: 回転台 | L18: 1 | M18: 46015 | N18: 46035 | O18: 46031 | P18: 46037 | R18: VV-26791 | S18: VU-LD091 | U18: V8 | V18: =TEXT(N18,"YY/MM") -> 26/01 | W18: 21341 | Y18: LAZ201 | Z18: LAY001 | AG18: 3531 | AI18: 1 | AJ18: 1 | AK18: 0 | AL18: 0 | AM18: 1 | AN18: 0 | AO18: 0 | AP18: 0 | AQ18: 1 | AR18: 0 | AS18: 1 | AT18: 0 | AU18: 0 | AV18: 0 | AW18: 1 | AX18: 0 | AY18: 0 | AZ18: 0 | BA18: 1 | BB18: 0 | BC18: 0 | BD18: 0 | BE18: 1 | BF18: 1 | BG18: 0 | BH18: 0 | BI18: 0 | BJ18: 0 | BK18: 0 | BL18: 0 | BM18: 0 | BN18: 0 | BO18: 0 | BP18: =$L18*AI18 -> 1 | BQ18: =$L18*AJ18 -> 1 | BR18: =$L18*AK18 -> 0 | BS18: =$L18*AL18 -> 0 | BT18: =$L18*AM18 -> 1 | BU18: =$L18*AN18 -> 0 | BV18: =$L18*AO18 -> 0 | BW18: =$L18*AP18 -> 0 | ... CV18: =$L18*BO18 -> 0
A19: 111 | B19: 000381125 | C19: 南海 | D19: 七道 | F19: 南海V8 | G19: 3S2VU-FBP-0003 | H19: 3690047-9 | I19: 機器 | J19: 1 | L19: 1 | M19: 46016 | N19: 46036 | O19: 46035 | P19: 46038 | R19: VV-26794 | S19: VU-LB106 | U19: V8 | V19: =TEXT(N19,"YY/MM") -> 26/01 | W19: 21342 | Y19: LAZ101 | Z19: LAY001 | AD19: 8206 | AI19: 1 | AJ19: 1 | AK19: 0 | AL19: 0 | AM19: 1 | AN19: 0 | AO19: 1 | AP19: 0 | AQ19: 0 | AR19: 0 | AS19: 1 | AT19: 0 | AU19: 1 | AV19: 0 | AW19: 0 | AX19: 1 | AY19: 0 | AZ19: 0 | BA19: 0 | BB19: 1 | BC19: 0 | BD19: 0 | BE19: 0 | BF19: 1 | BG19: 0 | BH19: 0 | BI19: 0 | BJ19: 0 | BK19: 0 | BL19: 0 | BM19: 0 | BN19: 0 | BO19: 0 | BP19: =$L19*AI19 -> 1 | BQ19: =$L19*AJ19 -> 1 | BR19: =$L19*AK19 -> 0 | BS19: =$L19*AL19 -> 0 | BT19: =$L19*AM19 -> 1 | BU19: =$L19*AN19 -> 0 | BV19: =$L19*AO19 -> 1 | BW19: =$L19*AP19 -> 0 | ... CV19: =$L19*BO19 -> 0
A20: 98 | B20: 000394016 | C20: M社（Ｎ） | E20: VU-LA004 | F20: V8-4BH | G20: VU-LA004 | H20: 1892581-2 | I20: 単体 | J20: 1 | L20: 1 | M20: 46017 | N20: 46037 | O20: 46036 | P20: 46036 | R20: MC-51868 | S20: VU-LA004 | U20: V8 | V20: =TEXT(N20,"YY/MM") -> 26/01 | W20: 21343 | Y20: LAZ101 | Z20: LAY001 | AD20: 8207 | AI20: 1 | AJ20: 1 | AK20: 0 | AL20: 0 | AM20: 1 | AN20: 0 | AO20: 1 | AP20: 0 | AQ20: 0 | AR20: 0 | AS20: 0 | AT20: 1 | AU20: 1 | AV20: 0 | AW20: 0 | AX20: 1 | AY20: 0 | AZ20: 0 | BA20: 0 | BB20: 1 | BC20: 0 | BD20: 0 | BE20: 0 | BF20: 1 | BG20: 0 | BH20: 0 | BI20: 0 | BJ20: 0 | BK20: 0 | BL20: 0 | BM20: 0 | BN20: 0 | BO20: 0 | BP20: =$L20*AI20 -> 1 | BQ20: =$L20*AJ20 -> 1 | BR20: =$L20*AK20 -> 0 | BS20: =$L20*AL20 -> 0 | BT20: =$L20*AM20 -> 1 | BU20: =$L20*AN20 -> 0 | BV20: =$L20*AO20 -> 1 | BW20: =$L20*AP20 -> 0 | ... CV20: =$L20*BO20 -> 0
A21: 97 | B21: 000371238 | C21: M社（Ｎ） | E21: VU-LA004 | F21: V8-4BH | G21: VU-LA004 | H21: 1892581-2 | I21: 単体 | J21: 1 | L21: 1 | M21: 46017 | N21: 46037 | O21: 46036 | P21: 46036 | R21: MC-51869 | S21: VU-LA004 | U21: V8 | V21: =TEXT(N21,"YY/MM") -> 26/01 | W21: 21344 | Y21: LAZ101 | Z21: LAY001 | AD21: 8208 | AI21: 1 | AJ21: 1 | AK21: 0 | AL21: 0 | AM21: 1 | AN21: 0 | AO21: 1 | AP21: 0 | AQ21: 0 | AR21: 0 | AS21: 0 | AT21: 1 | AU21: 1 | AV21: 0 | AW21: 0 | AX21: 1 | AY21: 0 | AZ21: 0 | BA21: 0 | BB21: 1 | BC21: 0 | BD21: 0 | BE21: 0 | BF21: 1 | BG21: 0 | BH21: 0 | BI21: 0 | BJ21: 0 | BK21: 0 | BL21: 0 | BM21: 0 | BN21: 0 | BO21: 0 | BP21: =$L21*AI21 -> 1 | BQ21: =$L21*AJ21 -> 1 | BR21: =$L21*AK21 -> 0 | BS21: =$L21*AL21 -> 0 | BT21: =$L21*AM21 -> 1 | BU21: =$L21*AN21 -> 0 | BV21: =$L21*AO21 -> 1 | BW21: =$L21*AP21 -> 0 | ... CV21: =$L21*BO21 -> 0
A22: 99 | B22: 000384916 | C22: N社（Ｎ） | E22: VU-LA007 | F22: V8-4BH | G22: VU-LA007 | H22: 3251849-9 | I22: 単体 | J22: 1 | L22: 1 | M22: 46017 | N22: 46037 | O22: 46036 | P22: 46036 | R22: MC-51870 | S22: VU-LA007 | U22: V8 | V22: =TEXT(N22,"YY/MM") -> 26/01 | W22: 21345 | Y22: LAZ002 | Z22: LAY002 | AA22: 3219 | AI22: 1 | AJ22: 1 | AK22: 0 | AL22: 0 | AM22: 1 | AN22: 0 | AO22: 1 | AP22: 0 | AQ22: 0 | AR22: 0 | AS22: 0 | AT22: 1 | AU22: 1 | AV22: 0 | AW22: 0 | AX22: 1 | AY22: 0 | AZ22: 0 | BA22: 0 | BB22: 1 | BC22: 0 | BD22: 0 | BE22: 0 | BF22: 1 | BG22: 0 | BH22: 0 | BI22: 0 | BJ22: 0 | BK22: 0 | BL22: 0 | BM22: 0 | BN22: 0 | BO22: 0 | BP22: =$L22*AI22 -> 1 | BQ22: =$L22*AJ22 -> 1 | BR22: =$L22*AK22 -> 0 | BS22: =$L22*AL22 -> 0 | BT22: =$L22*AM22 -> 1 | BU22: =$L22*AN22 -> 0 | BV22: =$L22*AO22 -> 1 | BW22: =$L22*AP22 -> 0 | ... CV22: =$L22*BO22 -> 0
A23: 117 | B23: 000381128 | C23: 南海 | D23: 湊 | F23: 南海V8 | G23: 3S2VU-FBP-0003 | H23: 3690047-9 | I23: 機器 | J23: 1 | L23: 1 | M23: 46017 | N23: 46037 | O23: 46036 | P23: 46041 | R23: VV-26797 | S23: VU-LB106 | U23: V8 | V23: =TEXT(N23,"YY/MM") -> 26/01 | W23: 21346 | Y23: LAZ101 | Z23: LAY001 | AD23: 8209 | AI23: 1 | AJ23: 1 | AK23: 0 | AL23: 0 | AM23: 1 | AN23: 0 | AO23: 1 | AP23: 0 | AQ23: 0 | AR23: 0 | AS23: 1 | AT23: 0 | AU23: 1 | AV23: 0 | AW23: 0 | AX23: 1 | AY23: 0 | AZ23: 0 | BA23: 0 | BB23: 1 | BC23: 0 | BD23: 0 | BE23: 0 | BF23: 1 | BG23: 0 | BH23: 0 | BI23: 0 | BJ23: 0 | BK23: 0 | BL23: 0 | BM23: 0 | BN23: 0 | BO23: 0 | BP23: =$L23*AI23 -> 1 | BQ23: =$L23*AJ23 -> 1 | BR23: =$L23*AK23 -> 0 | BS23: =$L23*AL23 -> 0 | BT23: =$L23*AM23 -> 1 | BU23: =$L23*AN23 -> 0 | BV23: =$L23*AO23 -> 1 | BW23: =$L23*AP23 -> 0 | ... CV23: =$L23*BO23 -> 0
A24: 102 | B24: 000394022 | C24: M社（Ｎ） | E24: VU-LA004 | F24: V8-4BH | G24: VU-LA004 | H24: 1892581-2 | I24: 単体 | J24: 1 | L24: 1 | M24: 46027 | N24: 46038 | O24: 46037 | P24: 46037 | R24: MC-51875 | S24: VU-LA004 | U24: V8 | V24: =TEXT(N24,"YY/MM") -> 26/01 | W24: 21347 | Y24: LAZ101 | Z24: LAY001 | AD24: 8210 | AI24: 1 | AJ24: 1 | AK24: 0 | AL24: 0 | AM24: 1 | AN24: 0 | AO24: 1 | AP24: 0 | AQ24: 0 | AR24: 0 | AS24: 0 | AT24: 1 | AU24: 1 | AV24: 0 | AW24: 0 | AX24: 1 | AY24: 0 | AZ24: 0 | BA24: 0 | BB24: 1 | BC24: 0 | BD24: 0 | BE24: 0 | BF24: 1 | BG24: 0 | BH24: 0 | BI24: 0 | BJ24: 0 | BK24: 0 | BL24: 0 | BM24: 0 | BN24: 0 | BO24: 0 | BP24: =$L24*AI24 -> 1 | BQ24: =$L24*AJ24 -> 1 | BR24: =$L24*AK24 -> 0 | BS24: =$L24*AL24 -> 0 | BT24: =$L24*AM24 -> 1 | BU24: =$L24*AN24 -> 0 | BV24: =$L24*AO24 -> 1 | BW24: =$L24*AP24 -> 0 | ... CV24: =$L24*BO24 -> 0
A25: 105 | B25: 000394020 | C25: M社（Ｎ） | E25: VU-LA004 | F25: V8-4BH | G25: VU-LA004 | H25: 1892581-2 | I25: 単体 | J25: 1 | L25: 1 | M25: 46027 | N25: 46038 | O25: 46037 | P25: 46037 | R25: MC-51876 | S25: VU-LA004 | U25: V8 | V25: =TEXT(N25,"YY/MM") -> 26/01 | W25: 21348 | Y25: LAZ101 | Z25: LAY001 | AD25: 8211 | AI25: 1 | AJ25: 1 | AK25: 0 | AL25: 0 | AM25: 1 | AN25: 0 | AO25: 1 | AP25: 0 | AQ25: 0 | AR25: 0 | AS25: 0 | AT25: 1 | AU25: 1 | AV25: 0 | AW25: 0 | AX25: 1 | AY25: 0 | AZ25: 0 | BA25: 0 | BB25: 1 | BC25: 0 | BD25: 0 | BE25: 0 | BF25: 1 | BG25: 0 | BH25: 0 | BI25: 0 | BJ25: 0 | BK25: 0 | BL25: 0 | BM25: 0 | BN25: 0 | BO25: 0 | BP25: =$L25*AI25 -> 1 | BQ25: =$L25*AJ25 -> 1 | BR25: =$L25*AK25 -> 0 | BS25: =$L25*AL25 -> 0 | BT25: =$L25*AM25 -> 1 | BU25: =$L25*AN25 -> 0 | BV25: =$L25*AO25 -> 1 | BW25: =$L25*AP25 -> 0 | ... CV25: =$L25*BO25 -> 0
A26: 104 | B26: 000394024 | C26: M社（Ｎ） | E26: VU-LA004 | F26: V8-4BH | G26: VU-LA004 | H26: 1892581-2 | I26: 単体 | J26: 1 | L26: 1 | M26: 46027 | N26: 46038 | O26: 46037 | P26: 46037 | R26: MC-51877 | S26: VU-LA004 | U26: V8 | V26: =TEXT(N26,"YY/MM") -> 26/01 | W26: 21349 | Y26: LAZ101 | Z26: LAY001 | AD26: 8212 | AI26: 1 | AJ26: 1 | AK26: 0 | AL26: 0 | AM26: 1 | AN26: 0 | AO26: 1 | AP26: 0 | AQ26: 0 | AR26: 0 | AS26: 0 | AT26: 1 | AU26: 1 | AV26: 0 | AW26: 0 | AX26: 1 | AY26: 0 | AZ26: 0 | BA26: 0 | BB26: 1 | BC26: 0 | BD26: 0 | BE26: 0 | BF26: 1 | BG26: 0 | BH26: 0 | BI26: 0 | BJ26: 0 | BK26: 0 | BL26: 0 | BM26: 0 | BN26: 0 | BO26: 0 | BP26: =$L26*AI26 -> 1 | BQ26: =$L26*AJ26 -> 1 | BR26: =$L26*AK26 -> 0 | BS26: =$L26*AL26 -> 0 | BT26: =$L26*AM26 -> 1 | BU26: =$L26*AN26 -> 0 | BV26: =$L26*AO26 -> 1 | BW26: =$L26*AP26 -> 0 | ... CV26: =$L26*BO26 -> 0
A27: 103 | B27: 000394018 | C27: M社（Ｎ） | E27: VU-LA004 | F27: V8-4BH | G27: VU-LA004 | H27: 1892581-2 | I27: 単体 | J27: 1 | L27: 1 | M27: 46027 | N27: 46038 | O27: 46037 | P27: 46037 | R27: MC-51878 | S27: VU-LA004 | U27: V8 | V27: =TEXT(N27,"YY/MM") -> 26/01 | W27: 21350 | Y27: LAZ101 | Z27: LAY001 | AD27: 8213 | AI27: 1 | AJ27: 1 | AK27: 0 | AL27: 0 | AM27: 1 | AN27: 0 | AO27: 1 | AP27: 0 | AQ27: 0 | AR27: 0 | AS27: 0 | AT27: 1 | AU27: 1 | AV27: 0 | AW27: 0 | AX27: 1 | AY27: 0 | AZ27: 0 | BA27: 0 | BB27: 1 | BC27: 0 | BD27: 0 | BE27: 0 | BF27: 1 | BG27: 0 | BH27: 0 | BI27: 0 | BJ27: 0 | BK27: 0 | BL27: 0 | BM27: 0 | BN27: 0 | BO27: 0 | BP27: =$L27*AI27 -> 1 | BQ27: =$L27*AJ27 -> 1 | BR27: =$L27*AK27 -> 0 | BS27: =$L27*AL27 -> 0 | BT27: =$L27*AM27 -> 1 | BU27: =$L27*AN27 -> 0 | BV27: =$L27*AO27 -> 1 | BW27: =$L27*AP27 -> 0 | ... CV27: =$L27*BO27 -> 0
A28: 119 | B28: 000380740 | C28: JR西 | D28: 摩耶 | F28: JR西FA70(EXV) | G28: 3S2EU-RDP-0001 | H28: 2874359-3 | I28: 機器 | J28: 1 | L28: 1 | M28: 46027 | N28: 46038 | O28: 46037 | P28: 46042 | R28: VV-26801 | S28: VU-LB112 | U28: V8 | V28: =TEXT(N28,"YY/MM") -> 26/01 | W28: 21351 | Y28: LAZ102 | Z28: LAY001 | AE28: 1253 | AI28: 1 | AJ28: 1 | AK28: 0 | AL28: 0 | AM28: 1 | AN28: 0 | AO28: 0 | AP28: 1 | AQ28: 0 | AR28: 0 | AS28: 1 | AT28: 0 | AU28: 1 | AV28: 0 | AW28: 0 | AX28: 1 | AY28: 0 | AZ28: 0 | BA28: 0 | BB28: 1 | BC28: 0 | BD28: 0 | BE28: 0 | BF28: 1 | BG28: 0 | BH28: 0 | BI28: 0 | BJ28: 0 | BK28: 0 | BL28: 0 | BM28: 0 | BN28: 0 | BO28: 0 | BP28: =$L28*AI28 -> 1 | BQ28: =$L28*AJ28 -> 1 | BR28: =$L28*AK28 -> 0 | BS28: =$L28*AL28 -> 0 | BT28: =$L28*AM28 -> 1 | BU28: =$L28*AN28 -> 0 | BV28: =$L28*AO28 -> 0 | BW28: =$L28*AP28 -> 1 | ... CV28: =$L28*BO28 -> 0
A29: 109 | B29: 000394015 | C29: M社（Ｎ） | E29: VU-LA004 | F29: V8-4BH | G29: VU-LA004 | H29: 1892581-2 | I29: 単体 | J29: 1 | L29: 1 | M29: 46028 | N29: 46041 | O29: 46038 | P29: 46038 | R29: MC-51883 | S29: VU-LA004 | U29: V8 | V29: =TEXT(N29,"YY/MM") -> 26/01 | W29: 21352 | Y29: LAZ101 | Z29: LAY001 | AD29: 8214 | AI29: 1 | AJ29: 1 | AK29: 0 | AL29: 0 | AM29: 1 | AN29: 0 | AO29: 1 | AP29: 0 | AQ29: 0 | AR29: 0 | AS29: 0 | AT29: 1 | AU29: 1 | AV29: 0 | AW29: 0 | AX29: 1 | AY29: 0 | AZ29: 0 | BA29: 0 | BB29: 1 | BC29: 0 | BD29: 0 | BE29: 0 | BF29: 1 | BG29: 0 | BH29: 0 | BI29: 0 | BJ29: 0 | BK29: 0 | BL29: 0 | BM29: 0 | BN29: 0 | BO29: 0 | BP29: =$L29*AI29 -> 1 | BQ29: =$L29*AJ29 -> 1 | BR29: =$L29*AK29 -> 0 | BS29: =$L29*AL29 -> 0 | BT29: =$L29*AM29 -> 1 | BU29: =$L29*AN29 -> 0 | BV29: =$L29*AO29 -> 1 | BW29: =$L29*AP29 -> 0 | ... CV29: =$L29*BO29 -> 0
A30: 107 | B30: 000394025 | C30: M社（Ｎ） | E30: VU-LA004 | F30: V8-4BH | G30: VU-LA004 | H30: 1892581-2 | I30: 単体 | J30: 1 | L30: 1 | M30: 46028 | N30: 46041 | O30: 46038 | P30: 46038 | R30: MC-51884 | S30: VU-LA004 | U30: V8 | V30: =TEXT(N30,"YY/MM") -> 26/01 | W30: 21353 | Y30: LAZ101 | Z30: LAY001 | AD30: 8215 | AI30: 1 | AJ30: 1 | AK30: 0 | AL30: 0 | AM30: 1 | AN30: 0 | AO30: 1 | AP30: 0 | AQ30: 0 | AR30: 0 | AS30: 0 | AT30: 1 | AU30: 1 | AV30: 0 | AW30: 0 | AX30: 1 | AY30: 0 | AZ30: 0 | BA30: 0 | BB30: 1 | BC30: 0 | BD30: 0 | BE30: 0 | BF30: 1 | BG30: 0 | BH30: 0 | BI30: 0 | BJ30: 0 | BK30: 0 | BL30: 0 | BM30: 0 | BN30: 0 | BO30: 0 | BP30: =$L30*AI30 -> 1 | BQ30: =$L30*AJ30 -> 1 | BR30: =$L30*AK30 -> 0 | BS30: =$L30*AL30 -> 0 | BT30: =$L30*AM30 -> 1 | BU30: =$L30*AN30 -> 0 | BV30: =$L30*AO30 -> 1 | BW30: =$L30*AP30 -> 0 | ... CV30: =$L30*BO30 -> 0
A31: 108 | B31: 000394013 | C31: M社（Ｎ） | E31: VU-LA004 | F31: V8-4BH | G31: VU-LA004 | H31: 1892581-2 | I31: 単体 | J31: 1 | L31: 1 | M31: 46028 | N31: 46041 | O31: 46038 | P31: 46038 | R31: MC-51885 | S31: VU-LA004 | U31: V8 | V31: =TEXT(N31,"YY/MM") -> 26/01 | W31: 21354 | Y31: LAZ101 | Z31: LAY001 | AD31: 8216 | AI31: 1 | AJ31: 1 | AK31: 0 | AL31: 0 | AM31: 1 | AN31: 0 | AO31: 1 | AP31: 0 | AQ31: 0 | AR31: 0 | AS31: 0 | AT31: 1 | AU31: 1 | AV31: 0 | AW31: 0 | AX31: 1 | AY31: 0 | AZ31: 0 | BA31: 0 | BB31: 1 | BC31: 0 | BD31: 0 | BE31: 0 | BF31: 1 | BG31: 0 | BH31: 0 | BI31: 0 | BJ31: 0 | BK31: 0 | BL31: 0 | BM31: 0 | BN31: 0 | BO31: 0 | BP31: =$L31*AI31 -> 1 | BQ31: =$L31*AJ31 -> 1 | BR31: =$L31*AK31 -> 0 | BS31: =$L31*AL31 -> 0 | BT31: =$L31*AM31 -> 1 | BU31: =$L31*AN31 -> 0 | BV31: =$L31*AO31 -> 1 | BW31: =$L31*AP31 -> 0 | ... CV31: =$L31*BO31 -> 0
A32: 106 | B32: 000394026 | C32: M社（Ｎ） | E32: VU-LA004 | F32: V8-4BH | G32: VU-LA004 | H32: 1892581-2 | I32: 単体 | J32: 1 | L32: 1 | M32: 46028 | N32: 46041 | O32: 46038 | P32: 46038 | R32: MC-51886 | S32: VU-LA004 | U32: V8 | V32: =TEXT(N32,"YY/MM") -> 26/01 | W32: 21355 | Y32: LAZ101 | Z32: LAY001 | AD32: 8217 | AI32: 1 | AJ32: 1 | AK32: 0 | AL32: 0 | AM32: 1 | AN32: 0 | AO32: 1 | AP32: 0 | AQ32: 0 | AR32: 0 | AS32: 0 | AT32: 1 | AU32: 1 | AV32: 0 | AW32: 0 | AX32: 1 | AY32: 0 | AZ32: 0 | BA32: 0 | BB32: 1 | BC32: 0 | BD32: 0 | BE32: 0 | BF32: 1 | BG32: 0 | BH32: 0 | BI32: 0 | BJ32: 0 | BK32: 0 | BL32: 0 | BM32: 0 | BN32: 0 | BO32: 0 | BP32: =$L32*AI32 -> 1 | BQ32: =$L32*AJ32 -> 1 | BR32: =$L32*AK32 -> 0 | BS32: =$L32*AL32 -> 0 | BT32: =$L32*AM32 -> 1 | BU32: =$L32*AN32 -> 0 | BV32: =$L32*AO32 -> 1 | BW32: =$L32*AP32 -> 0 | ... CV32: =$L32*BO32 -> 0
A33: 127 | B33: 000385410 | C33: 南海 | D33: 春木 | E33: 東 | F33: 南海V8 | G33: 3S2VU-FBP-0003 | H33: 3690047-9 | I33: 機器 | J33: 1 | K33: DVR内蔵 | L33: 1 | M33: 46028 | N33: 46041 | O33: 46038 | P33: 46043 | R33: VV-26806 | S33: VU-LB106 | U33: V8 | V33: =TEXT(N33,"YY/MM") -> 26/01 | W33: 21356 | Y33: LAZ101 | Z33: LAY001 | AD33: 8218 | AI33: 1 | AJ33: 1 | AK33: 0 | AL33: 0 | AM33: 1 | AN33: 0 | AO33: 1 | AP33: 0 | AQ33: 0 | AR33: 0 | AS33: 1 | AT33: 0 | AU33: 1 | AV33: 0 | AW33: 0 | AX33: 1 | AY33: 0 | AZ33: 0 | BA33: 0 | BB33: 1 | BC33: 0 | BD33: 0 | BE33: 0 | BF33: 1 | BG33: 0 | BH33: 0 | BI33: 0 | BJ33: 0 | BK33: 0 | BL33: 0 | BM33: 0 | BN33: 0 | BO33: 0 | BP33: =$L33*AI33 -> 1 | BQ33: =$L33*AJ33 -> 1 | BR33: =$L33*AK33 -> 0 | BS33: =$L33*AL33 -> 0 | BT33: =$L33*AM33 -> 1 | BU33: =$L33*AN33 -> 0 | BV33: =$L33*AO33 -> 1 | BW33: =$L33*AP33 -> 0 | ... CV33: =$L33*BO33 -> 0
A34: 115 | B34: 000394023 | C34: M社（Ｎ） | E34: VU-LA004 | F34: V8-4BH | G34: VU-LA004 | H34: 1892581-2 | I34: 単体 | J34: 1 | L34: 1 | M34: 46029 | N34: 46042 | O34: 46041 | P34: 46041 | R34: MC-51891 | S34: VU-LA004 | U34: V8 | V34: =TEXT(N34,"YY/MM") -> 26/01 | W34: 21357 | Y34: LAZ101 | Z34: LAY001 | AD34: 8219 | AI34: 1 | AJ34: 1 | AK34: 0 | AL34: 0 | AM34: 1 | AN34: 0 | AO34: 1 | AP34: 0 | AQ34: 0 | AR34: 0 | AS34: 0 | AT34: 1 | AU34: 1 | AV34: 0 | AW34: 0 | AX34: 1 | AY34: 0 | AZ34: 0 | BA34: 0 | BB34: 1 | BC34: 0 | BD34: 0 | BE34: 0 | BF34: 1 | BG34: 0 | BH34: 0 | BI34: 0 | BJ34: 0 | BK34: 0 | BL34: 0 | BM34: 0 | BN34: 0 | BO34: 0 | BP34: =$L34*AI34 -> 1 | BQ34: =$L34*AJ34 -> 1 | BR34: =$L34*AK34 -> 0 | BS34: =$L34*AL34 -> 0 | BT34: =$L34*AM34 -> 1 | BU34: =$L34*AN34 -> 0 | BV34: =$L34*AO34 -> 1 | BW34: =$L34*AP34 -> 0 | ... CV34: =$L34*BO34 -> 0
A35: 113 | B35: 000394017 | C35: M社（Ｎ） | E35: VU-LA004 | F35: V8-4BH | G35: VU-LA004 | H35: 1892581-2 | I35: 単体 | J35: 1 | L35: 1 | M35: 46029 | N35: 46042 | O35: 46041 | P35: 46041 | R35: MC-51892 | S35: VU-LA004 | U35: V8 | V35: =TEXT(N35,"YY/MM") -> 26/01 | W35: 21358 | Y35: LAZ101 | Z35: LAY001 | AD35: 8220 | AI35: 1 | AJ35: 1 | AK35: 0 | AL35: 0 | AM35: 1 | AN35: 0 | AO35: 1 | AP35: 0 | AQ35: 0 | AR35: 0 | AS35: 0 | AT35: 1 | AU35: 1 | AV35: 0 | AW35: 0 | AX35: 1 | AY35: 0 | AZ35: 0 | BA35: 0 | BB35: 1 | BC35: 0 | BD35: 0 | BE35: 0 | BF35: 1 | BG35: 0 | BH35: 0 | BI35: 0 | BJ35: 0 | BK35: 0 | BL35: 0 | BM35: 0 | BN35: 0 | BO35: 0 | BP35: =$L35*AI35 -> 1 | BQ35: =$L35*AJ35 -> 1 | BR35: =$L35*AK35 -> 0 | BS35: =$L35*AL35 -> 0 | BT35: =$L35*AM35 -> 1 | BU35: =$L35*AN35 -> 0 | BV35: =$L35*AO35 -> 1 | BW35: =$L35*AP35 -> 0 | ... CV35: =$L35*BO35 -> 0
A36: 112 | B36: 000394027 | C36: M社（Ｎ） | E36: VU-LA004 | F36: V8-4BH | G36: VU-LA004 | H36: 1892581-2 | I36: 単体 | J36: 1 | L36: 1 | M36: 46029 | N36: 46042 | O36: 46041 | P36: 46041 | R36: MC-51893 | S36: VU-LA004 | U36: V8 | V36: =TEXT(N36,"YY/MM") -> 26/01 | W36: 21359 | Y36: LAZ101 | Z36: LAY001 | AD36: 8221 | AI36: 1 | AJ36: 1 | AK36: 0 | AL36: 0 | AM36: 1 | AN36: 0 | AO36: 1 | AP36: 0 | AQ36: 0 | AR36: 0 | AS36: 0 | AT36: 1 | AU36: 1 | AV36: 0 | AW36: 0 | AX36: 1 | AY36: 0 | AZ36: 0 | BA36: 0 | BB36: 1 | BC36: 0 | BD36: 0 | BE36: 0 | BF36: 1 | BG36: 0 | BH36: 0 | BI36: 0 | BJ36: 0 | BK36: 0 | BL36: 0 | BM36: 0 | BN36: 0 | BO36: 0 | BP36: =$L36*AI36 -> 1 | BQ36: =$L36*AJ36 -> 1 | BR36: =$L36*AK36 -> 0 | BS36: =$L36*AL36 -> 0 | BT36: =$L36*AM36 -> 1 | BU36: =$L36*AN36 -> 0 | BV36: =$L36*AO36 -> 1 | BW36: =$L36*AP36 -> 0 | ... CV36: =$L36*BO36 -> 0
A37: 114 | B37: 000394014 | C37: M社（Ｎ） | E37: VU-LA004 | F37: V8-4BH | G37: VU-LA004 | H37: 1892581-2 | I37: 単体 | J37: 1 | L37: 1 | M37: 46029 | N37: 46042 | O37: 46041 | P37: 46041 | R37: MC-51894 | S37: VU-LA004 | U37: V8 | V37: =TEXT(N37,"YY/MM") -> 26/01 | W37: 21360 | Y37: LAZ101 | Z37: LAY001 | AD37: 8222 | AI37: 1 | AJ37: 1 | AK37: 0 | AL37: 0 | AM37: 1 | AN37: 0 | AO37: 1 | AP37: 0 | AQ37: 0 | AR37: 0 | AS37: 0 | AT37: 1 | AU37: 1 | AV37: 0 | AW37: 0 | AX37: 1 | AY37: 0 | AZ37: 0 | BA37: 0 | BB37: 1 | BC37: 0 | BD37: 0 | BE37: 0 | BF37: 1 | BG37: 0 | BH37: 0 | BI37: 0 | BJ37: 0 | BK37: 0 | BL37: 0 | BM37: 0 | BN37: 0 | BO37: 0 | BP37: =$L37*AI37 -> 1 | BQ37: =$L37*AJ37 -> 1 | BR37: =$L37*AK37 -> 0 | BS37: =$L37*AL37 -> 0 | BT37: =$L37*AM37 -> 1 | BU37: =$L37*AN37 -> 0 | BV37: =$L37*AO37 -> 1 | BW37: =$L37*AP37 -> 0 | ... CV37: =$L37*BO37 -> 0
A38: 131 | B38: 000385411 | C38: 南海 | D38: 貝塚 | E38: 東 | F38: 南海V8 | G38: 3S2VU-FBP-0003 | H38: 3690047-9 | I38: 機器 | J38: 1 | K38: DVR内蔵 | L38: 1 | M38: 46029 | N38: 46042 | O38: 46041 | P38: 46044 | R38: VV-26809 | S38: VU-LB106 | U38: V8 | V38: =TEXT(N38,"YY/MM") -> 26/01 | W38: 21361 | Y38: LAZ101 | Z38: LAY001 | AD38: 8223 | AI38: 1 | AJ38: 1 | AK38: 0 | AL38: 0 | AM38: 1 | AN38: 0 | AO38: 1 | AP38: 0 | AQ38: 0 | AR38: 0 | AS38: 1 | AT38: 0 | AU38: 1 | AV38: 0 | AW38: 0 | AX38: 1 | AY38: 0 | AZ38: 0 | BA38: 0 | BB38: 1 | BC38: 0 | BD38: 0 | BE38: 0 | BF38: 1 | BG38: 0 | BH38: 0 | BI38: 0 | BJ38: 0 | BK38: 0 | BL38: 0 | BM38: 0 | BN38: 0 | BO38: 0 | BP38: =$L38*AI38 -> 1 | BQ38: =$L38*AJ38 -> 1 | BR38: =$L38*AK38 -> 0 | BS38: =$L38*AL38 -> 0 | BT38: =$L38*AM38 -> 1 | BU38: =$L38*AN38 -> 0 | BV38: =$L38*AO38 -> 1 | BW38: =$L38*AP38 -> 0 | ... CV38: =$L38*BO38 -> 0
A39: 132 | B39: 000385416 | C39: 南海 | D39: 初芝 | F39: 南海V8(ﾏﾙﾁ) | G39: 3S2VU-FBP-5002 | H39: 3690049-5 | I39: 機器 | J39: 1 | K39: DVR内蔵 | L39: 1 | M39: 46029 | N39: 46042 | O39: 46041 | P39: 46044 | R39: VV-26810 | S39: VU-LB106 | U39: V8 | V39: =TEXT(N39,"YY/MM") -> 26/01 | W39: 21362 | Y39: LAZ101 | Z39: LAY001 | AD39: 8224 | AI39: 1 | AJ39: 1 | AK39: 0 | AL39: 0 | AM39: 1 | AN39: 0 | AO39: 1 | AP39: 0 | AQ39: 0 | AR39: 0 | AS39: 1 | AT39: 0 | AU39: 1 | AV39: 0 | AW39: 0 | AX39: 1 | AY39: 0 | AZ39: 0 | BA39: 0 | BB39: 1 | BC39: 0 | BD39: 0 | BE39: 0 | BF39: 1 | BG39: 0 | BH39: 0 | BI39: 0 | BJ39: 0 | BK39: 0 | BL39: 0 | BM39: 0 | BN39: 0 | BO39: 0 | BP39: =$L39*AI39 -> 1 | BQ39: =$L39*AJ39 -> 1 | BR39: =$L39*AK39 -> 0 | BS39: =$L39*AL39 -> 0 | BT39: =$L39*AM39 -> 1 | BU39: =$L39*AN39 -> 0 | BV39: =$L39*AO39 -> 1 | BW39: =$L39*AP39 -> 0 | ... CV39: =$L39*BO39 -> 0
A40: 120 | B40: 000394019 | C40: M社（Ｎ） | E40: VU-LA004 | F40: V8-4BH | G40: VU-LA004 | H40: 1892581-2 | I40: 単体 | J40: 1 | L40: 1 | M40: 46030 | N40: 46043 | O40: 46042 | P40: 46042 | R40: MC-51900 | S40: VU-LA004 | U40: V8 | V40: =TEXT(N40,"YY/MM") -> 26/01 | W40: 21363 | Y40: LAZ101 | Z40: LAY001 | AD40: 8225 | AI40: 1 | AJ40: 1 | AK40: 0 | AL40: 0 | AM40: 1 | AN40: 0 | AO40: 1 | AP40: 0 | AQ40: 0 | AR40: 0 | AS40: 0 | AT40: 1 | AU40: 1 | AV40: 0 | AW40: 0 | AX40: 1 | AY40: 0 | AZ40: 0 | BA40: 0 | BB40: 1 | BC40: 0 | BD40: 0 | BE40: 0 | BF40: 1 | BG40: 0 | BH40: 0 | BI40: 0 | BJ40: 0 | BK40: 0 | BL40: 0 | BM40: 0 | BN40: 0 | BO40: 0 | BP40: =$L40*AI40 -> 1 | BQ40: =$L40*AJ40 -> 1 | BR40: =$L40*AK40 -> 0 | BS40: =$L40*AL40 -> 0 | BT40: =$L40*AM40 -> 1 | BU40: =$L40*AN40 -> 0 | BV40: =$L40*AO40 -> 1 | BW40: =$L40*AP40 -> 0 | ... CV40: =$L40*BO40 -> 0
A41: 121 | B41: 000394021 | C41: M社（Ｎ） | E41: VU-LA004 | F41: V8-4BH | G41: VU-LA004 | H41: 1892581-2 | I41: 単体 | J41: 1 | L41: 1 | M41: 46030 | N41: 46043 | O41: 46042 | P41: 46042 | R41: MC-51901 | S41: VU-LA004 | U41: V8 | V41: =TEXT(N41,"YY/MM") -> 26/01 | W41: 21364 | Y41: LAZ101 | Z41: LAY001 | AD41: 8226 | AI41: 1 | AJ41: 1 | AK41: 0 | AL41: 0 | AM41: 1 | AN41: 0 | AO41: 1 | AP41: 0 | AQ41: 0 | AR41: 0 | AS41: 0 | AT41: 1 | AU41: 1 | AV41: 0 | AW41: 0 | AX41: 1 | AY41: 0 | AZ41: 0 | BA41: 0 | BB41: 1 | BC41: 0 | BD41: 0 | BE41: 0 | BF41: 1 | BG41: 0 | BH41: 0 | BI41: 0 | BJ41: 0 | BK41: 0 | BL41: 0 | BM41: 0 | BN41: 0 | BO41: 0 | BP41: =$L41*AI41 -> 1 | BQ41: =$L41*AJ41 -> 1 | BR41: =$L41*AK41 -> 0 | BS41: =$L41*AL41 -> 0 | BT41: =$L41*AM41 -> 1 | BU41: =$L41*AN41 -> 0 | BV41: =$L41*AO41 -> 1 | BW41: =$L41*AP41 -> 0 | ... CV41: =$L41*BO41 -> 0
...

Sheet V8集計
C1: 67 | D1: 45 | G1: 106 | I1: 21 | J1: 15 | K1: 10 | L1: 5 | M1: 37 | N1: 15 | O1: 38 | Q1: 10 | R1: 42 | U1: 10 | V1: 55 | Y1: 10
C2: =SUM(C4:C61) -> 67 | D2: =SUM(D4:D61) -> 45 | E2: =SUM(E4:E61) -> 0 | F2: =SUM(F4:F61) -> 0 | G2: =SUM(G4:G61) -> 106 | H2: =SUM(H4:H61) -> 0 | I2: =SUM(I4:I61) -> 21 | J2: =SUM(J4:J61) -> 15 | ... Y2: =SUM(Y4:Y61) -> 10
B3: 行ラベル | C3: LAA101 | D3: LAF001 | E3: LAF002 | F3: LAF003 | G3: LAG001 | H3: LAG002 | I3: LAE101 | J3: LAE102 | K3: LAE201 | L3: LBL001 | M3: LBL002 | N3: LAL001 | O3: LAN001 | P3: LAN002 | Q3: LCN001 | R3: LAC001 | S3: LAC002 | T3: LCC001 | U3: LCC002 | V3: LAD001 | W3: LAD002 | X3: LCD001 | Y3: LCD002
A4: 46031 | B4: 46038 | C4: 1 | D4: 1 | G4: 1 | I4: 1 | M4: 1 | N4: 4 | O4: 5 | R4: 5 | V4: 5
B5: 46039 | C5: 7 | D5: 1 | G5: 6 | I5: 3 | M5: 2 | N5: 2 | O5: 4 | R5: 4 | V5: 4
B6: 46041 | C6: 6 | D6: 1 | G6: 5 | I6: 3 | J6: 1 | L6: 5 | M6: 1 | O6: 2 | R6: 2 | V6: 6
B7: 46042 | C7: 4 | D7: 4 | G7: 5 | M7: 1 | O7: 1 | R7: 1 | V7: 5
B8: 46043 | C8: 4 | D8: 1 | G8: 4 | M8: 1 | O8: 1 | R8: 1 | V8: 5
B9: 46044 | V9: 1
B10: 46045 | C10: 6 | D10: 1 | G10: 1 | I10: 1
B11: 46048 | C11: 1 | D11: 1 | G11: 16 | I11: 1
A12: 46042 | B12: 46049 | C12: 1 | D12: 1 | I12: 1
B13: 46050 | N13: 2 | O13: 2 | R13: 2 | V13: 2
B14: 46051 | M14: 1 | O14: 1 | R14: 1 | V14: 1
B15: 46052 | G15: 5
B16: 46055 | G16: 5
B17: 46056 | C17: 1 | D17: 1 | G17: 4 | K17: 1
B18: 46057 | C18: 3 | D18: 2 | G18: 4 | I18: 3
B19: 46058 | G19: 4 | M19: 1 | Q19: 1 | R19: 4 | U19: 1 | V19: 4 | Y19: 1
B20: 46059 | G20: 3
B21: 46062 | G21: 5
B22: 46063 | C22: 1 | D22: 1 | G22: 1 | J22: 1
B23: 46065 | C23: 1 | D23: 1 | G23: 6 | J23: 1 | M23: 5
B24: 46066 | M24: 1 | O24: 1 | R24: 1 | V24: 1
B25: 46069 | M25: 1 | O25: 1 | R25: 1 | V25: 1
A26: 46063 | B26: 46073 | C26: 1 | D26: 1 | G26: 1 | I26: 1
B27: 46077 | C27: 1 | D27: 1 | G27: 1 | I27: 1
B28: 46078 | C28: 1 | D28: 1 | G28: 3 | I28: 1
B29: 46079 | C29: 1 | D29: 1 | G29: 1 | I29: 1
B30: 46080 | C30: 1 | D30: 1 | G30: 1 | I30: 1 | N30: 1 | O30: 1 | R30: 1 | V30: 1
B31: 46083 | C31: 1 | D31: 1 | G31: 1 | I31: 1 | N31: 1 | O31: 1 | R31: 1 | V31: 1
B32: 46084 | C32: 1 | D32: 1 | G32: 1 | K32: 1 | N32: 1 | O32: 1 | R32: 1 | V32: 1
B33: 46085 | C33: 3 | D33: 1 | G33: 1 | I33: 1 | N33: 1 | O33: 1 | R33: 1 | V33: 1
B34: 46086 | C34: 1 | D34: 1 | G34: 1 | K34: 1 | N34: 1 | O34: 1 | R34: 1 | V34: 1
B35: 46087 | M35: 1 | N35: 1 | O35: 1 | Q35: 1 | R35: 1 | U35: 1 | V35: 1 | Y35: 1
B36: 46090 | C36: 1 | D36: 1 | G36: 1 | K36: 1 | M36: 1 | N36: 1 | O36: 1 | Q36: 1 | R36: 1 | U36: 1 | V36: 1 | Y36: 1
B37: 46091 | C37: 1 | D37: 1 | G37: 1 | J37: 1
B38: 46092 | C38: 1 | D38: 1 | G38: 1 | K38: 1 | M38: 1 | Q38: 1 | U38: 1 | Y38: 1
B39: 46093 | C39: 1 | D39: 1 | G39: 1 | J39: 1
B40: 46094 | C40: 1 | D40: 1 | G40: 1 | J40: 1 | M40: 2 | O40: 1 | Q40: 1 | R40: 1 | U40: 1 | V40: 1 | Y40: 1
...

Sheet V8
A1: T-No （LAY） | B1: Z002 号機 | C1: Z003 号機 | D1: Z004 号機 | E1: Z101 号機 | F1: Z102 号機 | G1: Z103 号機 | H1: Z201 号機 | I1: ＢＨ型式 | J1: 順序 確定日 | K1: 光真 順序 出荷日 | L1: 実出荷 | M1: KP-No | N1: LAZ 完了 計画 | O1: KMP ユニット 日本着日 | P1: LAZ/ｶｾｯﾄ LAL/LBL J-光真 出荷計画 | Q1: メンテ | R1: LAA101 | S1: LAF001 | T1: LAF002 | U1: LAF003 | V1: LAG001 | W1: LAG002 | X1: LAE101 | Y1: LAE102 | Z1: LAE201 | AA1: KMP ユニット 日本着日 | AB1: LBL001 | AC1: LBL002 | AD1: LAL001 | AE1: LAN001 | AF1: LAN002 | AG1: LCN001 | AH1: LAC001 | AI1: LAC002 | AJ1: LCC001 | AK1: LCC002 | AL1: LAD001 | AM1: LAD002 | AN1: LCD001 | AO1: LCD002 | AP1: LAZ002 | AQ1: LAZ003 | AR1: LAZ004 | AS1: LAZ101 | AT1: LAZ102 | AU1: LAZ103 | AV1: LAZ201 | AW1: LAY001 | AX1: LAY002 | AY1: LAH001 | AZ1: 生産 計画 No | BA1: 客先名 | BB1: 駅名 ﾒﾝﾃﾕﾆｯﾄ型式（個/ﾛｯﾄ） | BC1: コーナー メンテ：情報提供者 （情報入手日） | BD1: ﾕﾆｯﾄ 種類数 | BE1: BH型式 | BF1: 出荷日 | BG1: T-No （LAY） | BH1: LAZ ﾕﾆｯﾄ | BI1: 1F 出荷 | BJ1: ﾒﾝﾃﾕﾆｯﾄ 型式 | BK1: 5311189-5 | BL1: 5311167-4
A2: 21357 | E2: 8219 | I2: VU-LA004 | J2: 46029 | K2: 46042 | M2: MC-51891 | N2: 46038 | O2: 46031 | P2: 46042 | AA2: 46038 | AD2: ・ | AS2: ・ | AW2: ・ | AY2: ・ | AZ2: 000394014 | BA2: M社（Ｎ） | BC2: VU-LA004 | BD2: 11 | BE2: =I2 -> VU-LA004 | BF2: =K2 -> 46042 | BG2: =A2 -> 21357 | BH2: =COUNTA(R2:Z2) -> 0 | BI2: =COUNTA(AB2:AO2) -> 1
A3: 21358 | E3: 8220 | I3: VU-LA004 | J3: 46029 | K3: 46042 | M3: MC-51892 | N3: 46039 | O3: 46035 | P3: 46042 | AA3: 46038 | AD3: ・ | AE3: ・ | AH3: ・ | AL3: ・ | AS3: ・ | AW3: ・ | AY3: ・ | AZ3: 000394017 | BA3: M社（Ｎ） | BC3: VU-LA004 | BD3: 11 | BE3: =I3 -> VU-LA004 | BF3: =K3 -> 46042 | BG3: =A3 -> 21358 | BH3: =COUNTA(R3:Z3) -> 0 | BI3: =COUNTA(AB3:AO3) -> 4
A4: 21359 | E4: 8221 | I4: VU-LA004 | J4: 46029 | K4: 46042 | M4: MC-51893 | N4: 46039 | O4: 46035 | P4: 46042 | AA4: 46038 | AD4: ・ | AE4: ・ | AH4: ・ | AL4: ・ | AS4: ・ | AW4: ・ | AY4: ・ | AZ4: 000394023 | BA4: M社（Ｎ） | BC4: VU-LA004 | BD4: 11 | BE4: =I4 -> VU-LA004 | BF4: =K4 -> 46042 | BG4: =A4 -> 21359 | BH4: =COUNTA(R4:Z4) -> 0 | BI4: =COUNTA(AB4:AO4) -> 4
A5: 21360 | E5: 8222 | I5: VU-LA004 | J5: 46029 | K5: 46042 | M5: MC-51894 | N5: 46039 | O5: 46035 | P5: 46042 | AA5: 46038 | AD5: ・ | AE5: ・ | AH5: ・ | AL5: ・ | AS5: ・ | AW5: ・ | AY5: ・ | AZ5: 000394027 | BA5: M社（Ｎ） | BC5: VU-LA004 | BD5: 11 | BE5: =I5 -> VU-LA004 | BF5: =K5 -> 46042 | BG5: =A5 -> 21360 | BH5: =COUNTA(R5:Z5) -> 0 | BI5: =COUNTA(AB5:AO5) -> 4
A6: 21361 | E6: 8223 | I6: VU-LB106 | J6: 46029 | K6: 46042 | M6: VV-26809 | N6: 46041 | O6: 46036 | P6: 46042 | AA6: 46038 | AE6: ・ | AH6: ・ | AL6: ・ | AS6: ・ | AW6: ・ | AY6: ・ | AZ6: 000385411 | BA6: 南海 | BB6: 貝塚 | BC6: 東 | BD6: 11 | BE6: =I6 -> VU-LB106 | BF6: =K6 -> 46042 | BG6: =A6 -> 21361 | BH6: =COUNTA(R6:Z6) -> 0 | BI6: =COUNTA(AB6:AO6) -> 3
A7: 21362 | E7: 8224 | I7: VU-LB106 | J7: 46029 | K7: 46042 | M7: VV-26810 | N7: 46041 | O7: 46036 | P7: 46042 | AA7: 46038 | AC7: ・ | AE7: ・ | AH7: ・ | AL7: ・ | AS7: ・ | AW7: ・ | AY7: ・ | AZ7: 000385416 | BA7: 南海 | BB7: 初芝 | BD7: 11 | BE7: =I7 -> VU-LB106 | BF7: =K7 -> 46042 | BG7: =A7 -> 21362 | BH7: =COUNTA(R7:Z7) -> 0 | BI7: =COUNTA(AB7:AO7) -> 4
A8: 21363 | E8: 8225 | I8: VU-LA004 | J8: 46030 | K8: 46043 | M8: MC-51900 | N8: 46041 | O8: 46036 | P8: 46043 | AA8: 46039 | AD8: ・ | AE8: ・ | AH8: ・ | AL8: ・ | AS8: ・ | AW8: ・ | AY8: ・ | AZ8: 000394019 | BA8: M社（Ｎ） | BC8: VU-LA004 | BD8: 11 | BE8: =I8 -> VU-LA004 | BF8: =K8 -> 46043 | BG8: =A8 -> 21363 | BH8: =COUNTA(R8:Z8) -> 0 | BI8: =COUNTA(AB8:AO8) -> 4
A9: 21364 | E9: 8226 | I9: VU-LA004 | J9: 46030 | K9: 46043 | M9: MC-51901 | N9: 46042 | O9: 46037 | P9: 46043 | AA9: 46039 | AD9: ・ | AE9: ・ | AH9: ・ | AL9: ・ | AS9: ・ | AW9: ・ | AY9: ・ | AZ9: 000394021 | BA9: M社（Ｎ） | BC9: VU-LA004 | BD9: 11 | BE9: =I9 -> VU-LA004 | BF9: =K9 -> 46043 | BG9: =A9 -> 21364 | BH9: =COUNTA(R9:Z9) -> 0 | BI9: =COUNTA(AB9:AO9) -> 4
A10: 21365 | E10: 8227 | I10: VU-LB106 | J10: 46030 | K10: 46043 | M10: VV-26813 | N10: 46042 | O10: 46037 | P10: 46043 | AA10: 46039 | AC10: ・ | AE10: ・ | AH10: ・ | AL10: ・ | AS10: ・ | AW10: ・ | AY10: ・ | AZ10: 000385413 | BA10: 南海 | BB10: 沢ノ町 | BC10: 西 | BD10: 11 | BE10: =I10 -> VU-LB106 | BF10: =K10 -> 46043 | BG10: =A10 -> 21365 | BH10: =COUNTA(R10:Z10) -> 0 | BI10: =COUNTA(AB10:AO10) -> 4
A11: 21366 | E11: 8228 | I11: VU-LB106 | J11: 46030 | K11: 46043 | M11: VV-26814 | N11: 46042 | O11: 46037 | P11: 46043 | AA11: 46039 | AC11: ・ | AE11: ・ | AH11: ・ | AL11: ・ | AS11: ・ | AW11: ・ | AY11: ・ | AZ11: 000385414 | BA11: 南海 | BB11: 百舌鳥八幡 | BC11: 西 | BD11: 11 | BE11: =I11 -> VU-LB106 | BF11: =K11 -> 46043 | BG11: =A11 -> 21366 | BH11: =COUNTA(R11:Z11) -> 0 | BI11: =COUNTA(AB11:AO11) -> 4
A12: 21367 | E12: 8229 | I12: VU-LB106 | J12: 46031 | K12: 46044 | M12: VV-26817 | N12: 46043 | O12: 46038 | P12: 46044 | R12: ・ | S12: ・ | V12: ・ | X12: ・ | AA12: 46041 | AC12: ・ | AE12: ・ | AH12: ・ | AL12: ・ | AS12: ・ | AW12: ・ | AY12: ・ | AZ12: 000385412 | BA12: 南海 | BB12: 羽倉崎 | BC12: 東 | BD12: 11 | BE12: =I12 -> VU-LB106 | BF12: =K12 -> 46044 | BG12: =A12 -> 21367 | BH12: =COUNTA(R12:Z12) -> 4 | BI12: =COUNTA(AB12:AO12) -> 4
J13: 46010 | K13: 46044 | M13: MB-08182 | O13: =INDEX([3]光真稼働日早見表!$M:$M,MATCH($P13,[3]光真稼働日早見表!$Q:$Q,0),1) -> 46039 | P13: 46044 | Q13: M | R13: ・ | AZ13: 000394355 | BA13: JRMS | BB13: LAA101(1/1) | BC13: （25/11/10DB公開） | BD13: =COUNTA(R13:AY13) -> 1 | BE13: =I13 -> 0 | BF13: =K13 -> 46044 | BG13: =A13 -> 0 | BH13: =COUNTA(R13:Z13) -> 1 | BI13: =COUNTA(AB13:AO13) -> 0 | BJ13: LAA101
J14: 46001 | K14: 46044 | M14: MB-08151 | O14: =INDEX([3]光真稼働日早見表!$M:$M,MATCH($P14,[3]光真稼働日早見表!$Q:$Q,0),1) -> 46039 | P14: 46044 | Q14: M | R14: ・ | AZ14: 000395943 | BA14: OFET | BB14: LAA101(1/18) | BC14: （11/5林ひ様情報） | BD14: =COUNTA(R14:AY14) -> 1 | BE14: =I14 -> 0 | BF14: =K14 -> 46044 | BG14: =A14 -> 0 | BH14: =COUNTA(R14:Z14) -> 1 | BI14: =COUNTA(AB14:AO14) -> 0 | BJ14: LAA101
J15: 46001 | K15: 46044 | M15: MB-08151 | O15: =INDEX([3]光真稼働日早見表!$M:$M,MATCH($P15,[3]光真稼働日早見表!$Q:$Q,0),1) -> 46039 | P15: 46044 | Q15: M | R15: ・ | AZ15: 000395943 | BA15: OFET | BB15: LAA101(2/18) | BC15: （11/5林ひ様情報） | BD15: =COUNTA(R15:AY15) -> 1 | BE15: =I15 -> 0 | BF15: =K15 -> 46044 | BG15: =A15 -> 0 | BH15: =COUNTA(R15:Z15) -> 1 | BI15: =COUNTA(AB15:AO15) -> 0 | BJ15: LAA101
J16: 46001 | K16: 46044 | M16: MB-08151 | O16: =INDEX([3]光真稼働日早見表!$M:$M,MATCH($P16,[3]光真稼働日早見表!$Q:$Q,0),1) -> 46039 | P16: 46044 | Q16: M | R16: ・ | AZ16: 000395943 | BA16: OFET | BB16: LAA101(3/18) | BC16: （11/5林ひ様情報） | BD16: =COUNTA(R16:AY16) -> 1 | BE16: =I16 -> 0 | BF16: =K16 -> 46044 | BG16: =A16 -> 0 | BH16: =COUNTA(R16:Z16) -> 1 | BI16: =COUNTA(AB16:AO16) -> 0 | BJ16: LAA101
J17: 46001 | K17: 46044 | M17: MB-08151 | O17: =INDEX([3]光真稼働日早見表!$M:$M,MATCH($P17,[3]光真稼働日早見表!$Q:$Q,0),1) -> 46039 | P17: 46044 | Q17: M | R17: ・ | AZ17: 000395943 | BA17: OFET | BB17: LAA101(4/18) | BC17: （11/5林ひ様情報） | BD17: =COUNTA(R17:AY17) -> 1 | BE17: =I17 -> 0 | BF17: =K17 -> 46044 | BG17: =A17 -> 0 | BH17: =COUNTA(R17:Z17) -> 1 | BI17: =COUNTA(AB17:AO17) -> 0 | BJ17: LAA101
J18: 46001 | K18: 46044 | M18: MB-08151 | O18: =INDEX([3]光真稼働日早見表!$M:$M,MATCH($P18,[3]光真稼働日早見表!$Q:$Q,0),1) -> 46039 | P18: 46044 | Q18: M | R18: ・ | AZ18: 000395943 | BA18: OFET | BB18: LAA101(5/18) | BC18: （11/5林ひ様情報） | BD18: =COUNTA(R18:AY18) -> 1 | BE18: =I18 -> 0 | BF18: =K18 -> 46044 | BG18: =A18 -> 0 | BH18: =COUNTA(R18:Z18) -> 1 | BI18: =COUNTA(AB18:AO18) -> 0 | BJ18: LAA101
J19: 46001 | K19: 46044 | M19: MB-08150 | O19: =INDEX([3]光真稼働日早見表!$M:$M,MATCH($P19,[3]光真稼働日早見表!$Q:$Q,0),1) -> 46039 | P19: 46044 | Q19: M | V19: ・ | AZ19: 000395944 | BA19: OFET | BB19: LAG001(1/18) | BC19: （11/5林ひ様情報） | BD19: =COUNTA(R19:AY19) -> 1 | BE19: =I19 -> 0 | BF19: =K19 -> 46044 | BG19: =A19 -> 0 | BH19: =COUNTA(R19:Z19) -> 1 | BI19: =COUNTA(AB19:AO19) -> 0 | BJ19: LAG001
J20: 46001 | K20: 46044 | M20: MB-08150 | O20: =INDEX([3]光真稼働日早見表!$M:$M,MATCH($P20,[3]光真稼働日早見表!$Q:$Q,0),1) -> 46039 | P20: 46044 | Q20: M | V20: ・ | AZ20: 000395944 | BA20: OFET | BB20: LAG001(2/18) | BC20: （11/5林ひ様情報） | BD20: =COUNTA(R20:AY20) -> 1 | BE20: =I20 -> 0 | BF20: =K20 -> 46044 | BG20: =A20 -> 0 | BH20: =COUNTA(R20:Z20) -> 1 | BI20: =COUNTA(AB20:AO20) -> 0 | BJ20: LAG001
J21: 46001 | K21: 46044 | M21: MB-08150 | O21: =INDEX([3]光真稼働日早見表!$M:$M,MATCH($P21,[3]光真稼働日早見表!$Q:$Q,0),1) -> 46039 | P21: 46044 | Q21: M | V21: ・ | AZ21: 000395944 | BA21: OFET | BB21: LAG001(3/18) | BC21: （11/5林ひ様情報） | BD21: =COUNTA(R21:AY21) -> 1 | BE21: =I21 -> 0 | BF21: =K21 -> 46044 | BG21: =A21 -> 0 | BH21: =COUNTA(R21:Z21) -> 1 | BI21: =COUNTA(AB21:AO21) -> 0 | BJ21: LAG001
J22: 46001 | K22: 46044 | M22: MB-08150 | O22: =INDEX([3]光真稼働日早見表!$M:$M,MATCH($P22,[3]光真稼働日早見表!$Q:$Q,0),1) -> 46039 | P22: 46044 | Q22: M | V22: ・ | AZ22: 000395944 | BA22: OFET | BB22: LAG001(4/18) | BC22: （11/5林ひ様情報） | BD22: =COUNTA(R22:AY22) -> 1 | BE22: =I22 -> 0 | BF22: =K22 -> 46044 | BG22: =A22 -> 0 | BH22: =COUNTA(R22:Z22) -> 1 | BI22: =COUNTA(AB22:AO22) -> 0 | BJ22: LAG001
J23: 46001 | K23: 46044 | M23: MB-08150 | O23: =INDEX([3]光真稼働日早見表!$M:$M,MATCH($P23,[3]光真稼働日早見表!$Q:$Q,0),1) -> 46039 | P23: 46044 | Q23: M | V23: ・ | AZ23: 000395944 | BA23: OFET | BB23: LAG001(5/18) | BC23: （11/5林ひ様情報） | BD23: =COUNTA(R23:AY23) -> 1 | BE23: =I23 -> 0 | BF23: =K23 -> 46044 | BG23: =A23 -> 0 | BH23: =COUNTA(R23:Z23) -> 1 | BI23: =COUNTA(AB23:AO23) -> 0 | BJ23: LAG001
J24: 46001 | K24: 46044 | M24: MB-08149 | O24: =INDEX([3]光真稼働日早見表!$M:$M,MATCH($P24,[3]光真稼働日早見表!$Q:$Q,0),1) -> 46039 | P24: 46044 | Q24: M | X24: ・ | AZ24: 000395936 | BA24: OFET | BB24: LAE101(1/2) | BC24: （11/5林ひ様情報） | BD24: =COUNTA(R24:AY24) -> 1 | BE24: =I24 -> 0 | BF24: =K24 -> 46044 | BG24: =A24 -> 0 | BH24: =COUNTA(R24:Z24) -> 1 | BI24: =COUNTA(AB24:AO24) -> 0 | BJ24: LAE101
J25: 46001 | K25: 46044 | M25: MB-08149 | O25: =INDEX([3]光真稼働日早見表!$M:$M,MATCH($P25,[3]光真稼働日早見表!$Q:$Q,0),1) -> 46039 | P25: 46044 | Q25: M | X25: ・ | AZ25: 000395936 | BA25: OFET | BB25: LAE101(2/2) | BC25: （11/5林ひ様情報） | BD25: =COUNTA(R25:AY25) -> 1 | BE25: =I25 -> 0 | BF25: =K25 -> 46044 | BG25: =A25 -> 0 | BH25: =COUNTA(R25:Z25) -> 1 | BI25: =COUNTA(AB25:AO25) -> 0 | BJ25: LAE101
J26: 46001 | K26: 46044 | M26: MB-08152 | P26: 46044 | Q26: M | AA26: =INDEX([3]光真稼働日早見表!$N:$N,MATCH($P26,[3]光真稼働日早見表!$Q:$Q,0),1) -> 46041 | AB26: ・ | AZ26: 000395964 | BA26: OFET | BB26: LBL001(1/5) | BC26: （11/5林ひ様情報） | BD26: =COUNTA(R26:AY26) -> 2 | BE26: =I26 -> 0 | BF26: =K26 -> 46044 | BG26: =A26 -> 0 | BH26: =COUNTA(R26:Z26) -> 0 | BI26: =COUNTA(AB26:AO26) -> 1 | BJ26: LBL001
J27: 46001 | K27: 46044 | M27: MB-08152 | P27: 46044 | Q27: M | AA27: =INDEX([3]光真稼働日早見表!$N:$N,MATCH($P27,[3]光真稼働日早見表!$Q:$Q,0),1) -> 46041 | AB27: ・ | AZ27: 000395964 | BA27: OFET | BB27: LBL001(2/5) | BC27: （11/5林ひ様情報） | BD27: =COUNTA(R27:AY27) -> 2 | BE27: =I27 -> 0 | BF27: =K27 -> 46044 | BG27: =A27 -> 0 | BH27: =COUNTA(R27:Z27) -> 0 | BI27: =COUNTA(AB27:AO27) -> 1 | BJ27: LBL001
J28: 46001 | K28: 46044 | M28: MB-08152 | P28: 46044 | Q28: M | AA28: =INDEX([3]光真稼働日早見表!$N:$N,MATCH($P28,[3]光真稼働日早見表!$Q:$Q,0),1) -> 46041 | AB28: ・ | AZ28: 000395964 | BA28: OFET | BB28: LBL001(3/5) | BC28: （11/5林ひ様情報） | BD28: =COUNTA(R28:AY28) -> 2 | BE28: =I28 -> 0 | BF28: =K28 -> 46044 | BG28: =A28 -> 0 | BH28: =COUNTA(R28:Z28) -> 0 | BI28: =COUNTA(AB28:AO28) -> 1 | BJ28: LBL001
J29: 46001 | K29: 46044 | M29: MB-08152 | P29: 46044 | Q29: M | AA29: =INDEX([3]光真稼働日早見表!$N:$N,MATCH($P29,[3]光真稼働日早見表!$Q:$Q,0),1) -> 46041 | AB29: ・ | AZ29: 000395964 | BA29: OFET | BB29: LBL001(4/5) | BC29: （11/5林ひ様情報） | BD29: =COUNTA(R29:AY29) -> 2 | BE29: =I29 -> 0 | BF29: =K29 -> 46044 | BG29: =A29 -> 0 | BH29: =COUNTA(R29:Z29) -> 0 | BI29: =COUNTA(AB29:AO29) -> 1 | BJ29: LBL001
J30: 46001 | K30: 46044 | M30: MB-08152 | P30: 46044 | Q30: M | AA30: =INDEX([3]光真稼働日早見表!$N:$N,MATCH($P30,[3]光真稼働日早見表!$Q:$Q,0),1) -> 46041 | AB30: ・ | AZ30: 000395964 | BA30: OFET | BB30: LBL001(5/5) | BC30: （11/5林ひ様情報） | BD30: =COUNTA(R30:AY30) -> 2 | BE30: =I30 -> 0 | BF30: =K30 -> 46044 | BG30: =A30 -> 0 | BH30: =COUNTA(R30:Z30) -> 0 | BI30: =COUNTA(AB30:AO30) -> 1 | BJ30: LBL001
J31: 46001 | K31: 46044 | M31: MB-08147 | P31: 46044 | Q31: M | AA31: =INDEX([3]光真稼働日早見表!$N:$N,MATCH($P31,[3]光真稼働日早見表!$Q:$Q,0),1) -> 46041 | AE31: ・ | AZ31: 000395955 | BA31: OFET | BB31: LAN001(1/1) | BC31: （11/5林ひ様情報） | BD31: =COUNTA(R31:AY31) -> 2 | BE31: =I31 -> 0 | BF31: =K31 -> 46044 | BG31: =A31 -> 0 | BH31: =COUNTA(R31:Z31) -> 0 | BI31: =COUNTA(AB31:AO31) -> 1 | BJ31: LAN001
J32: 46001 | K32: 46044 | M32: MB-08145 | P32: 46044 | Q32: M | AA32: =INDEX([3]光真稼働日早見表!$N:$N,MATCH($P32,[3]光真稼働日早見表!$Q:$Q,0),1) -> 46041 | AH32: ・ | AZ32: 000395949 | BA32: OFET | BB32: LAC001(1/1) | BC32: （11/5林ひ様情報） | BD32: =COUNTA(R32:AY32) -> 2 | BE32: =I32 -> 0 | BF32: =K32 -> 46044 | BG32: =A32 -> 0 | BH32: =COUNTA(R32:Z32) -> 0 | BI32: =COUNTA(AB32:AO32) -> 1 | BJ32: LAC001
