Workbook
Name __DAT1: #REF!
Name __DAT10: #REF!
Name __DAT11: #REF!
Name __DAT12: #REF!
Name __DAT2: #REF!
Name __DAT3: #REF!
Name __DAT4: #REF!
Name __DAT5: #REF!
Name __DAT6: #REF!
Name __DAT7: #REF!
Name __DAT8: #REF!
Name __DAT9: #REF!
Name _DAT1: #REF!
Name _DAT1: #REF!
Name _DAT1: #REF!
Name _DAT1: #REF!
Name _DAT1: #REF!
Name _DAT1: #REF!
Name _DAT10: #REF!
Name _DAT10: #REF!
Name _DAT10: #REF!
Name _DAT10: #REF!
Name _DAT10: #REF!
Name _DAT10: #REF!
Name _DAT11: #REF!
Name _DAT11: #REF!
Name _DAT11: #REF!
Name _DAT11: #REF!
Name _DAT11: #REF!
Name _DAT11: #REF!
Name _DAT12: #REF!
Name _DAT12: #REF!
Name _DAT12: #REF!
Name _DAT12: #REF!
Name _DAT12: #REF!
Name _DAT12: #REF!
Name _DAT2: #REF!
Name _DAT2: #REF!
Name _DAT2: #REF!
Name _DAT2: #REF!
Name _DAT2: #REF!
Name _DAT2: #REF!
Name _DAT3: #REF!
Name _DAT3: #REF!
Name _DAT3: #REF!
Name _DAT3: #REF!
Name _DAT3: #REF!
Name _DAT3: #REF!
Name _DAT4: #REF!
Name _DAT4: #REF!
Name _DAT4: #REF!
Name _DAT4: #REF!
Name _DAT4: #REF!
Name _DAT4: #REF!
Name _DAT5: #REF!
Name _DAT5: #REF!
Name _DAT5: #REF!
Name _DAT5: #REF!
Name _DAT5: #REF!
Name _DAT5: #REF!

Sheet Ｖ７星取日程マスター
G1: ・ | H1: ・ | I1: ・ | J1: ・ | K1: ・ | L1: ・ | O1: =VLOOKUP(P1,#REF!,9,FALSE) -> #REF! | P1: =VLOOKUP(Q1,#REF!,11,FALSE) -> #REF! | S1: =VLOOKUP(R1,#REF!,8,FALSE) -> #REF! | U1: =VLOOKUP(C1,Ｖ７structure!$C$5:$V$59,3,FALSE) -> #N/A | V1: =VLOOKUP(C1,Ｖ７structure!$C$5:$V$59,4,FALSE) -> #N/A | W1: =VLOOKUP(C1,Ｖ７structure!$C$5:$V$59,5,FALSE) -> #N/A | X1: =VLOOKUP(C1,Ｖ７structure!$C$5:$V$59,6,FALSE) -> #N/A | Y1: =VLOOKUP(C1,Ｖ７structure!$C$5:$V$59,7,FALSE) -> #N/A | Z1: =VLOOKUP(C1,Ｖ７structure!$C$5:$V$59,8,FALSE) -> #N/A | AA1: =VLOOKUP(C1,Ｖ７structure!$C$5:$V$59,9,FALSE) -> #N/A | AB1: =VLOOKUP(C1,Ｖ７structure!$C$5:$V$59,10,FALSE) -> #N/A | AC1: =VLOOKUP(C1,Ｖ７structure!$C$5:$V$59,11,FALSE) -> #N/A | AD1: =VLOOKUP(C1,Ｖ７structure!$C$5:$V$59,12,FALSE) -> #N/A | AE1: =VLOOKUP(C1,Ｖ７structure!$C$5:$V$59,13,FALSE) -> #N/A | AF1: =VLOOKUP(C1,Ｖ７structure!$C$5:$V$59,14,FALSE) -> #N/A | AG1: =VLOOKUP(C1,Ｖ７structure!$C$5:$V$59,15,FALSE) -> #N/A | AH1: =VLOOKUP(C1,Ｖ７structure!$C$5:$V$59,16,FALSE) -> #N/A | AI1: =VLOOKUP(C1,Ｖ７structure!$C$5:$V$59,17,FALSE) -> #N/A | AJ1: =VLOOKUP(C1,Ｖ７structure!$C$5:$V$59,18,FALSE) -> #N/A | AK1: =VLOOKUP(C1,Ｖ７structure!$C$5:$V$59,19,FALSE) -> #N/A | AL1: =VLOOKUP(C1,Ｖ７structure!$C$5:$V$59,20,FALSE) -> #N/A | AN1: =COUNTA(W1:AK1) -> 15
O2: 着手3日前 | S2: 出荷４日前 | U2: 3 | V2: 4 | W2: 5 | X2: 6 | Y2: 7 | Z2: 8 | AA2: 9 | AB2: 10 | AC2: 11 | AD2: 12 | AE2: 13 | AF2: 14 | AG2: 15 | AH2: 16 | AI2: 17 | AJ2: 18 | AK2: 19 | AL2: 20
A3: T- No | B3: 号機 | C3: BH | D3: 順序 確定日 | E3: 光真 出荷 指示日 | F3: ＬＡＺ 実出荷 | G3: KP-No | H3: LAR101 5948 184-8 | I3: LAJ101 5911 267-2 | J3: LAE100 7961 962-5 | K3: LAG101 5911 295-8 | L3: LAL101 5911 210-9 | M3: 備考 | N3: メンテ | O3: ＫＭＰ ユニット 必要日 | P3: ﾍﾞｰｽ 光真生産 着手日 | Q3: ﾍﾞｰｽ 光真生産 完了日 | R3: 光真 出荷日 | S3: ＫＭＰ カセット 必要日 (出荷4日前） | T3: ﾒﾝﾃ 表示 | U3: LAP101 5911 213-3 | V3: LAP102 1888 889-5 | W3: LAC101 5981 329-8 | X3: LAD101 5964 105-5 | Y3: LAF101 5964 106-3 | Z3: LAF093 1889 107-1 | AA3: LAC092 5992 295-0 | AB3: LAC093 5981 353-0 | AC3: LAC094 1858 395-4 | AD3: LAD001 6911 025-2 | AE3: LAD001 5992 238-0 | AF3: LAC034 6993 321-6 | AG3: LAC071 1870 994-0 | AH3: LAD071 1870 955-9 | AI3: LAC098 1874 748-5 | AJ3: LAC099 1881 236-8 | AK3: LAC081 3734 917-2 | AL3: LAH101 5911 400-4 | AM3: メンテ詳細情報 （空欄はＢＨ搭載用） | AN3: ｶｾｯﾄ 数量 | AO3: 生産計画No | AP3: 客先名 | AQ3: 駅名 | AR3: コーナー | AS3: 機種名
A4: 9478 | B4: 10737 | C4: LA095S | D4: 43413 | E4: 43425 | G4: ・ | H4: ・ | I4: ・ | J4: ・ | K4: ・ | L4: ・ | O4: =VLOOKUP(P4,#REF!,9,FALSE) -> #REF! | P4: =VLOOKUP(Q4,#REF!,11,FALSE) -> #REF! | Q4: 43420 | R4: 43425 | S4: =VLOOKUP(R4,#REF!,8,FALSE) -> #REF! | U4: ・ | Z4: ・ | AB4: ・ | AE4: ・ | AL4: ・ | AN4: =COUNTA(W4:AK4) -> 3 | AO4: 000227595 | AP4: JR西 | AQ4: 南吹田
A5: 9479 | B5: 10738 | C5: LA095S | D5: 43416 | E5: 43426 | G5: ・ | H5: ・ | I5: ・ | J5: ・ | K5: ・ | L5: ・ | O5: =VLOOKUP(P5,#REF!,9,FALSE) -> #REF! | P5: =VLOOKUP(Q5,#REF!,11,FALSE) -> #REF! | Q5: 43420 | R5: 43426 | S5: =VLOOKUP(R5,#REF!,8,FALSE) -> #REF! | U5: ・ | Z5: ・ | AB5: ・ | AE5: ・ | AL5: ・ | AN5: =COUNTA(W5:AK5) -> 3 | AO5: 000240522 | AP5: JR西 | AQ5: JR淡路
A6: 9480 | B6: 10739 | C6: LA095S | D6: 43417 | E6: 43430 | G6: ・ | H6: ・ | I6: ・ | J6: ・ | K6: ・ | L6: ・ | O6: =VLOOKUP(P6,#REF!,9,FALSE) -> #REF! | P6: =VLOOKUP(Q6,#REF!,11,FALSE) -> #REF! | Q6: 43420 | R6: 43430 | S6: =VLOOKUP(R6,#REF!,8,FALSE) -> #REF! | U6: ・ | Z6: ・ | AB6: ・ | AE6: ・ | AL6: ・ | AN6: =COUNTA(W6:AK6) -> 3 | AO6: 000240523 | AP6: JR西 | AQ6: 城北公園通
A7: 9481 | B7: 10740 | C7: LA095S | D7: 43418 | E7: 43431 | G7: ・ | H7: ・ | I7: ・ | J7: ・ | K7: ・ | L7: ・ | O7: =VLOOKUP(P7,#REF!,9,FALSE) -> #REF! | P7: =VLOOKUP(Q7,#REF!,11,FALSE) -> #REF! | Q7: 43420 | R7: 43431 | S7: =VLOOKUP(R7,#REF!,8,FALSE) -> #REF! | U7: ・ | Z7: ・ | AB7: ・ | AE7: ・ | AL7: ・ | AN7: =COUNTA(W7:AK7) -> 3 | AO7: 000240524 | AP7: JR西 | AQ7: JR野江
A8: 9482 | B8: 10741 | C8: LA095S | D8: 43419 | E8: 43432 | G8: ・ | H8: ・ | I8: ・ | J8: ・ | K8: ・ | L8: ・ | O8: =VLOOKUP(P8,#REF!,9,FALSE) -> #REF! | P8: =VLOOKUP(Q8,#REF!,11,FALSE) -> #REF! | Q8: 43420 | R8: 43432 | S8: =VLOOKUP(R8,#REF!,8,FALSE) -> #REF! | U8: ・ | Z8: ・ | AB8: ・ | AE8: ・ | AL8: ・ | AN8: =COUNTA(W8:AK8) -> 3 | AO8: 000240525 | AP8: JR西 | AQ8: 東部市場前
A9: 9483 | B9: 10742 | C9: LA092S | D9: 43423 | E9: 43434 | G9: ・ | H9: ・ | I9: ・ | J9: ・ | K9: ・ | L9: ・ | O9: =VLOOKUP(P9,#REF!,9,FALSE) -> #REF! | P9: =VLOOKUP(Q9,#REF!,11,FALSE) -> #REF! | Q9: 43420 | R9: 43434 | S9: =VLOOKUP(R9,#REF!,8,FALSE) -> #REF! | V9: ・ | Y9: ・ | AA9: ・ | AD9: ・ | AL9: ・ | AN9: =COUNTA(W9:AK9) -> 3 | AO9: 000241971 | AP9: OFET
A10: 9484 | B10: 10743 | C10: LA095S | D10: ? | E10: 43437 | G10: ・ | H10: ・ | I10: ・ | J10: ・ | K10: ・ | L10: ・ | O10: =VLOOKUP(P10,#REF!,9,FALSE) -> #REF! | P10: =VLOOKUP(Q10,#REF!,11,FALSE) -> #REF! | Q10: 43420 | R10: 43437 | S10: =VLOOKUP(R10,#REF!,8,FALSE) -> #REF! | U10: ・ | Z10: ・ | AB10: ・ | AE10: ・ | AL10: ・ | AN10: =COUNTA(W10:AK10) -> 3 | AO10: 000240104 | AP10: JR西 | AQ10: 18短計情報
A11: 9485 | B11: 10744 | C11: LA095S | D11: ? | E11: 43437 | G11: ・ | H11: ・ | I11: ・ | J11: ・ | K11: ・ | L11: ・ | O11: =VLOOKUP(P11,#REF!,9,FALSE) -> #REF! | P11: =VLOOKUP(Q11,#REF!,11,FALSE) -> #REF! | Q11: 43420 | R11: 43437 | S11: =VLOOKUP(R11,#REF!,8,FALSE) -> #REF! | U11: ・ | Z11: ・ | AB11: ・ | AE11: ・ | AL11: ・ | AN11: =COUNTA(W11:AK11) -> 3 | AO11: 000240104 | AP11: JR西 | AQ11: 18短計情報
G12: ・ | H12: ・ | I12: ・ | J12: ・ | K12: ・ | L12: ・ | O12: =VLOOKUP(P12,#REF!,9,FALSE) -> #REF! | P12: =VLOOKUP(Q12,#REF!,11,FALSE) -> #REF! | S12: =VLOOKUP(R12,#REF!,8,FALSE) -> #REF! | U12: =VLOOKUP(C12,Ｖ７structure!$C$5:$V$59,3,FALSE) -> #N/A | V12: =VLOOKUP(C12,Ｖ７structure!$C$5:$V$59,4,FALSE) -> #N/A | W12: =VLOOKUP(C12,Ｖ７structure!$C$5:$V$59,5,FALSE) -> #N/A | X12: =VLOOKUP(C12,Ｖ７structure!$C$5:$V$59,6,FALSE) -> #N/A | Y12: =VLOOKUP(C12,Ｖ７structure!$C$5:$V$59,7,FALSE) -> #N/A | Z12: =VLOOKUP(C12,Ｖ７structure!$C$5:$V$59,8,FALSE) -> #N/A | AA12: =VLOOKUP(C12,Ｖ７structure!$C$5:$V$59,9,FALSE) -> #N/A | AB12: =VLOOKUP(C12,Ｖ７structure!$C$5:$V$59,10,FALSE) -> #N/A | AC12: =VLOOKUP(C12,Ｖ７structure!$C$5:$V$59,11,FALSE) -> #N/A | AD12: =VLOOKUP(C12,Ｖ７structure!$C$5:$V$59,12,FALSE) -> #N/A | AE12: =VLOOKUP(C12,Ｖ７structure!$C$5:$V$59,13,FALSE) -> #N/A | AF12: =VLOOKUP(C12,Ｖ７structure!$C$5:$V$59,14,FALSE) -> #N/A | AG12: =VLOOKUP(C12,Ｖ７structure!$C$5:$V$59,15,FALSE) -> #N/A | AH12: =VLOOKUP(C12,Ｖ７structure!$C$5:$V$59,16,FALSE) -> #N/A | AI12: =VLOOKUP(C12,Ｖ７structure!$C$5:$V$59,17,FALSE) -> #N/A | AJ12: =VLOOKUP(C12,Ｖ７structure!$C$5:$V$59,18,FALSE) -> #N/A | AK12: =VLOOKUP(C12,Ｖ７structure!$C$5:$V$59,19,FALSE) -> #N/A | AL12: =VLOOKUP(C12,Ｖ７structure!$C$5:$V$59,20,FALSE) -> #N/A | AN12: =COUNTA(W12:AK12) -> 15

Sheet Ｖ７structure
A1: Ｖ７－ＢＨ ユニット相対表 | V1: 2014／6／23改訂
C2: 1 | D2: 2 | E2: 3 | F2: 4 | G2: 5 | H2: 6 | I2: 7 | J2: 8 | K2: 9 | L2: 10 | M2: 11 | N2: 12 | O2: 13 | P2: 14 | Q2: 15 | R2: 16 | S2: 17 | T2: 18 | U2: 19 | V2: 20
D3: ｷﾎﾝﾌﾞ | E3: 5000ﾎﾘｭｳ | F3: 5000ﾎﾘｭｳ | G3: ｶｾｯﾄ | H3: ｶｾｯﾄ | I3: ｶｾｯﾄ | J3: ｶｾｯﾄ | K3: ｶｾｯﾄ | L3: ｶｾｯﾄ | M3: ｶｾｯﾄ | N3: ｶｾｯﾄ | O3: ｶｾｯﾄ | P3: ｶｾｯﾄ | Q3: ｶｾｯﾄ | R3: ｶｾｯﾄ | S3: ｶｾｯﾄ | T3: ｶｾｯﾄ | U3: ｶｾｯﾄ | V3: ﾚｰﾙ
A4: No | B4: 品番 | C4: ＢＨ型式 | D4: 7959779-6 ﾍﾞ-ｽ,BH VTS-LAZ100S | E4: 5911213-3 5000ｴﾝﾎﾘﾕｳﾌﾞ VTS-LAP101 | F4: 1888889-5 5000ｴﾝﾎﾘﾕｳﾌﾞ VTS-LAP102 | G4: 5981329-8 10000ｴﾝｱﾂｼ- VTS-LAC101 | H4: 5964105-5 1000ｴﾝｱﾂｼ- VTS-LAD101 | I4: 5964106-3 2000ｴﾝｱﾂｼ- VTS-LAF101 | J4: 1889107-1 2000ｴﾝ ｱﾂｼ- VTS-LAF093 | K4: 5992295-0 10000ｴﾝｱﾂｼ- VTS-LAC092 | L4: 5981353-0 10000ｴﾝｱﾂｼ- VTS-LAC093 | M4: 1858395-4 10000ｴﾝｱﾂｼ- VTS-LAC094 | N4: 6911025-2 1000ｴﾝｱﾂｼ- VTS-LAD001 | O4: 5992238-0 1000ｴﾝｱﾂｼ- VTS-LAD001 | P4: 6993321-6 10000ｴﾝｱﾂｼ- VTS-LAC034 | Q4: 1870994-0 10000ｴﾝｱﾂｼ- VTS-LAC071 | R4: 1870955-9 1000ｴﾝｱﾂｼ- VTS-LAD071 | S4: 1874748-5 10000ｴﾝｱﾂｼ- VTS-LAC098 | T4: 1881236-8 10000ｴﾝｱﾂｼ- VTS-LAC099 | U4: 3734917-2 10000ｴﾝｱﾂｼ- VTS-LAC081 | V4: 5911400-4 ﾚ-ﾙﾌﾞ VTS-LAH101
A5: 1 | B5: 6980132-8 | C5: LA034S | D5: ・ | E5: ・ | I5: ・ | N5: ・ | P5: ・ | V5: ・
A6: 2 | B6: 1870947-8 | C6: LA071S | D6: ・ | E6: ・ | I6: ・ | Q6: ・ | R6: ・ | V6: ・
A7: 3 | B7: 3734909-1 | C7: LA081S | D7: ・ | F7: ・ | I7: ・ | N7: ・ | U7: ・ | V7: ・
A8: 4 | B8: 5992188-0 | C8: LA092S | D8: ・ | F8: ・ | I8: ・ | K8: ・ | N8: ・ | V8: ・
A9: 5 | B9: 5992177-5 | C9: LA093S | D9: ・ | E9: ・ | J9: ・ | L9: ・ | O9: ・ | V9: ・
A10: 6 | B10: 1858373-3 | C10: LA094S | D10: ・ | E10: ・ | I10: ・ | M10: ・ | N10: ・ | V10: ・
A11: 7 | B11: 1860614-8 | C11: LA095S | D11: ・ | E11: ・ | J11: ・ | L11: ・ | O11: ・ | V11: ・
A12: 8 | B12: 6945961-1 | C12: LA096S | D12: ・ | E12: ・ | I12: ・ | K12: ・ | N12: ・ | V12: ・
A13: 9 | B13: 1862821-4 | C13: LA097S | D13: ・ | E13: ・ | J13: ・ | L13: ・ | O13: ・ | V13: ・
A14: 10 | B14: 1874705-1 | C14: LA098S | D14: ・ | E14: ・ | I14: ・ | N14: ・ | S14: ・ | V14: ・
A15: 11 | B15: 1881230-9 | C15: LA099S | D15: ・ | E15: ・ | I15: ・ | N15: ・ | T15: ・ | V15: ・
A16: 12 | B16: 5952735-0 | C16: LA102S | D16: ・ | E16: ・ | G16: ・ | H16: ・ | I16: ・ | V16: ・
A17: 13 | B17: 5992219-4 | C17: LA109S | D17: ・ | E17: ・ | G17: ・ | H17: ・ | I17: ・ | V17: ・
A18: 14 | B18: 6916838-2 | C18: LA111S | D18: ・ | E18: ・ | G18: ・ | H18: ・ | I18: ・ | V18: ・
A19: 15 | B19: 6993314-3 | C19: LA112S | D19: ・ | E19: ・ | G19: ・ | H19: ・ | I19: ・ | V19: ・
A20: 16 | B20: 6995414-0 | C20: LA113S | D20: ・ | E20: ・ | G20: ・ | H20: ・ | I20: ・ | V20: ・
A21: 17 | B21: 7931904-4 | C21: LA114S | D21: ・ | E21: ・ | G21: ・ | H21: ・ | I21: ・ | V21: ・
A22: 18 | B22: 1866538-1 | C22: LA115S | D22: ・ | E22: ・ | G22: ・ | H22: ・ | I22: ・ | V22: ・
A23: 19 | B23: 1869999-5 | C23: LA116S | D23: ・ | E23: ・ | G23: ・ | H23: ・ | I23: ・ | V23: ・
A24: 20 | B24: 1870233-3 | C24: LA117S | D24: ・ | E24: ・ | G24: ・ | H24: ・ | I24: ・ | V24: ・
A25: 21 | B25: 1870917-6 | C25: LA118S | D25: ・ | E25: ・ | G25: ・ | H25: ・ | I25: ・ | V25: ・
A26: 22 | B26: 7940763-6 | C26: LA122S | D26: ・ | E26: ・ | G26: ・ | H26: ・ | I26: ・ | V26: ・
A27: 23 | B27: 6911210-7 | C27: LA131S | D27: ・ | E27: ・ | G27: ・ | H27: ・ | I27: ・ | V27: ・
... A53: 49 | B53: 6965259-4 | C53: LA199S | D53: ・ | E53: ・ | G53: ・ | H53: ・ | I53: ・ | V53: ・
A54: 50 | C54: 仮一般 | D54: ・ | E54: ・ | G54: ・ | H54: ・ | I54: ・ | V54: ・
A55: 51 | B55: 6980133-6 | C55: LB034S | D55: ・ | N55: ・ | V55: ・
A56: 52 | B56: 6901094-0 | C56: LB133S | D56: ・ | H56: ・ | V56: ・
A57: 53 | B57: 6980088-7 | C57: LB134S | D57: ・ | H57: ・ | V57: ・
A58: 54 | B58: 7931201-5 | C58: LB135S | D58: ・ | H58: ・ | V58: ・
A59: 55 | B59: 7975061-6 | C59: LB161S | D59: ・ | H59: ・ | V59: ・

Sheet Ｖ８星取日程マスター
I1: 1 | K1: ａ | N1: b | O1: b-4日 (光真ｶﾚ） | P1: ａ-3日 (光真ｶﾚ） | Q1: ａ (OCｶﾚ） | S1: 2 | T1: 3 | U1: 4 | V1: 5 | W1: 6 | X1: 7 | Y1: 8 | Z1: 9 | AA1: 10 | AB1: 11 | AC1: 12 | AD1: 13 | AE1: 14 | AF1: 15 | AG1: 16 | AH1: 17 | AI1: 18 | AJ1: 19 | AK1: 20 | AL1: 21 | AM1: 22 | AN1: 23 | AO1: 24 | AP1: 25 | AQ1: 26 | AR1: 27 | AS1: 28 | AT1: 29 | AU1: 30 | AV1: 31 | AW1: 32 | AX1: 33 | AY1: 34 | BA1: 客先名 | BB1: 駅名 ﾒﾝﾃﾕﾆｯﾄ型式（個/ﾛｯﾄ） | BC1: コーナー メンテ：情報提供者（情報入手日）
I2: VU-LD091 | N2: 44627 | O2: =INDEX(光真稼働日早見表!M:M,MATCH(N2,光真稼働日早見表!B:B,0),1) -> 44621 | P2: =INDEX(光真稼働日早見表!N:N,MATCH(Q2,光真稼働日早見表!B:B,0),1) -> 44622 | Q2: 44627 | S2: =VLOOKUP(I2,'V8structure '!$C$10:$AJ$49,2,FALSE) -> ・ | T2: =VLOOKUP(I2,'V8structure '!$C$10:$AJ$49,3,FALSE) -> ・ | U2: =VLOOKUP(I2,'V8structure '!$C$10:$AJ$49,4,FALSE) -> 0 | V2: =VLOOKUP(I2,'V8structure '!$C$10:$AJ$49,5,FALSE) -> 0 | W2: =VLOOKUP(I2,'V8structure '!$C$10:$AJ$49,6,FALSE) -> ・ | X2: =VLOOKUP(I2,'V8structure '!$C$10:$AJ$49,7,FALSE) -> 0 | Y2: =VLOOKUP(I2,'V8structure '!$C$10:$AJ$49,8,FALSE) -> 0 | Z2: =VLOOKUP(I2,'V8structure '!$C$10:$AJ$49,9,FALSE) -> 0 | AA2: =VLOOKUP(I2,'V8structure '!$C$10:$AJ$49,10,FALSE) -> ・ | AB2: =VLOOKUP(I2,'V8structure '!$C$10:$AJ$49,11,FALSE) -> 0 | AC2: =VLOOKUP(I2,'V8structure '!$C$10:$AJ$49,12,FALSE) -> ・ | AD2: =VLOOKUP(I2,'V8structure '!$C$10:$AJ$49,13,FALSE) -> 0 | AE2: =VLOOKUP(I2,'V8structure '!$C$10:$AJ$49,14,FALSE) -> 0 | AF2: =VLOOKUP(I2,'V8structure '!$C$10:$AJ$49,15,FALSE) -> 0 | AG2: =VLOOKUP(I2,'V8structure '!$C$10:$AJ$49,16,FALSE) -> ・ | AH2: =VLOOKUP(I2,'V8structure '!$C$10:$AJ$49,17,FALSE) -> 0 | AI2: =VLOOKUP(I2,'V8structure '!$C$10:$AJ$49,18,FALSE) -> 0 | AJ2: =VLOOKUP(I2,'V8structure '!$C$10:$AJ$49,19,FALSE) -> 0 | AK2: =VLOOKUP(I2,'V8structure '!$C$10:$AJ$49,20,FALSE) -> ・ | AL2: =VLOOKUP(I2,'V8structure '!$C$10:$AJ$49,21,FALSE) -> 0 | AM2: =VLOOKUP(I2,'V8structure '!$C$10:$AJ$49,22,FALSE) -> 0 | AN2: =VLOOKUP(I2,'V8structure '!$C$10:$AJ$49,23,FALSE) -> 0 | AO2: =VLOOKUP(I2,'V8structure '!$C$10:$AJ$49,24,FALSE) -> ・ | AP2: =VLOOKUP(I2,'V8structure '!$C$10:$AJ$49,25,FALSE) -> 0 | AQ2: =VLOOKUP(I2,'V8structure '!$C$10:$AJ$49,26,FALSE) -> 0 | AR2: =VLOOKUP(I2,'V8structure '!$C$10:$AJ$49,27,FALSE) -> 0 | AS2: =VLOOKUP(I2,'V8structure '!$C$10:$AJ$49,28,FALSE) -> 0 | AT2: =VLOOKUP(I2,'V8structure '!$C$10:$AJ$49,29,FALSE) -> 0 | AU2: =VLOOKUP(I2,'V8structure '!$C$10:$AJ$49,30,FALSE) -> 0 | AV2: =VLOOKUP(I2,'V8structure '!$C$10:$AJ$49,31,FALSE) -> ・ | AW2: =VLOOKUP(I2,'V8structure '!$C$10:$AJ$49,32,FALSE) -> ・ | AX2: =VLOOKUP(I2,'V8structure '!$C$10:$AJ$49,33,FALSE) -> 0 | AY2: =VLOOKUP(I2,'V8structure '!$C$10:$AJ$49,34,FALSE) -> ・ | BD2: =COUNTIF(S2:AY2,"・") -> 11
A4: T-No | B4: Z002 号機 | C4: Z003 号機 | D4: Z004 号機 | E4: Z101 号機 | F4: Z102 号機 | G4: Z103 号機 | H4: Z201 号機 | I4: ＢＨ型式 | J4: 順序 確定日 | K4: OSS 納入 指示日 | L4: ＬＡＺ 実出荷 | M4: KP-No | N4: LAZ 完了 計画 | O4: KMP ユニット 日本着日 | P4: KMP カセット 日本必要 | Q4: LAZ/ｶｾｯﾄ LAL/LBL J-光真 出荷計画 | R4: メンテ | S4: LAA101 | T4: LAF001 | U4: LAF002 | V4: LAF003 | W4: LAG001 | X4: LAG002 | Y4: LAE101 | Z4: LAE102 | AA4: LAE201 | AB4: LBL001 | AC4: LBL002 | AD4: LAL001 | AE4: LAN001 | AF4: LAN002 | AG4: LCN001 | AH4: LAC001 | AI4: LAC002 | AJ4: LCC001 | AK4: LCC002 | AL4: LAD001 | AM4: LAD002 | AN4: LCD001 | AO4: LCD002 | AP4: LAZ002 | AQ4: LAZ003 | AR4: LAZ004 | AS4: LAZ101 | AT4: LAZ102 | AU4: LAZ103 | AV4: LAZ201 | AW4: LAY001 | AX4: LAY002 | AY4: LAH001 | AZ4: 生産計画№ | BA4: 客先名 | BB4: 駅名 | BC4: コーナー | BD4: ユニット数
A5: 21334 | H5: 3524 | I5: VU-LD091 | J5: 46008 | K5: 46027 | M5: ・ | N5: =IFERROR(INDEX([4]Ｖ８出荷・完了計画!$B$5:$B$2593,MATCH(A5,[4]Ｖ８出荷・完了計画!$M$5:$M$2593,0),1),N6) -> 46029 | O5: =INDEX([5]光真稼働日早見表!$M$3:$M$10000,MATCH($N5,[5]光真稼働日早見表!$Q$3:$Q$10000,0),1) -> 46016 | P5: =INDEX([5]光真稼働日早見表!$N$3:$N$10000,MATCH($Q5,[5]光真稼働日早見表!$Q$3:$Q$10000,0),1) -> 46015 | Q5: 46027 | S5: ・ | T5: ・ | W5: ・ | AA5: ・ | AC5: ・ | AG5: ・ | AK5: ・ | AO5: ・ | AV5: ・ | AW5: ・ | AY5: ・ | AZ5: 000385490 | BA5: 設計設備 | BB5: 下諏訪(本屋)駅設定 | BD5: =COUNTIF(S5:AY5,"・") -> 11
A6: 21335 | H6: 3525 | I6: VU-LD091 | J6: 46009 | K6: 46028 | M6: ・ | N6: =IFERROR(INDEX([4]Ｖ８出荷・完了計画!$B$5:$B$2593,MATCH(A6,[4]Ｖ８出荷・完了計画!$M$5:$M$2593,0),1),N7) -> 46029 | O6: =INDEX([5]光真稼働日早見表!$M$3:$M$10000,MATCH($N6,[5]光真稼働日早見表!$Q$3:$Q$10000,0),1) -> 46016 | P6: =INDEX([5]光真稼働日早見表!$N$3:$N$10000,MATCH($Q6,[5]光真稼働日早見表!$Q$3:$Q$10000,0),1) -> 46016 | Q6: 46028 | S6: ・ | T6: ・ | W6: ・ | AA6: ・ | AC6: ・ | AG6: ・ | AK6: ・ | AO6: ・ | AV6: ・ | AW6: ・ | AY6: ・ | AZ6: 000393963 | BA6: 設計設備 | BB6: 下諏訪(本屋)駅設定 | BD6: =COUNTIF(S6:AY6,"・") -> 11
A7: 21336 | H7: 3526 | I7: VU-LD091 | J7: 46013 | K7: 46030 | M7: ・ | N7: =IFERROR(INDEX([4]Ｖ８出荷・完了計画!$B$5:$B$2593,MATCH(A7,[4]Ｖ８出荷・完了計画!$M$5:$M$2593,0),1),N8) -> 46029 | O7: =INDEX([5]光真稼働日早見表!$M$3:$M$10000,MATCH($N7,[5]光真稼働日早見表!$Q$3:$Q$10000,0),1) -> 46016 | P7: =INDEX([5]光真稼働日早見表!$N$3:$N$10000,MATCH($Q7,[5]光真稼働日早見表!$Q$3:$Q$10000,0),1) -> 46027 | Q7: 46030 | S7: ・ | T7: ・ | W7: ・ | AA7: ・ | AC7: ・ | AG7: ・ | AK7: ・ | AO7: ・ | AV7: ・ | AW7: ・ | AY7: ・ | AZ7: 000393965 | BA7: JREM | BB7: 天王洲アイル | BC7: 南 | BD7: =COUNTIF(S7:AY7,"・") -> 11
A8: 21337 | H8: 3527 | I8: VU-LD091 | J8: 46013 | K8: 46030 | M8: ・ | N8: =IFERROR(INDEX([4]Ｖ８出荷・完了計画!$B$5:$B$2593,MATCH(A8,[4]Ｖ８出荷・完了計画!$M$5:$M$2593,0),1),N9) -> 46029 | O8: =INDEX([5]光真稼働日早見表!$M$3:$M$10000,MATCH($N8,[5]光真稼働日早見表!$Q$3:$Q$10000,0),1) -> 46016 | P8: =INDEX([5]光真稼働日早見表!$N$3:$N$10000,MATCH($Q8,[5]光真稼働日早見表!$Q$3:$Q$10000,0),1) -> 46027 | Q8: 46030 | S8: ・ | T8: ・ | W8: ・ | AA8: ・ | AC8: ・ | AG8: ・ | AK8: ・ | AO8: ・ | AV8: ・ | AW8: ・ | AY8: ・ | AZ8: 000393967 | BA8: JREM | BB8: 天空橋 | BC8: HiCity | BD8: =COUNTIF(S8:AY8,"・") -> 11
A9: 21338 | H9: 3528 | I9: VU-LD091 | J9: 46014 | K9: 46031 | M9: ・ | N9: =IFERROR(INDEX([4]Ｖ８出荷・完了計画!$B$5:$B$2593,MATCH(A9,[4]Ｖ８出荷・完了計画!$M$5:$M$2593,0),1),N10) -> 46030 | O9: =INDEX([5]光真稼働日早見表!$M$3:$M$10000,MATCH($N9,[5]光真稼働日早見表!$Q$3:$Q$10000,0),1) -> 46017 | P9: =INDEX([5]光真稼働日早見表!$N$3:$N$10000,MATCH($Q9,[5]光真稼働日早見表!$Q$3:$Q$10000,0),1) -> 46028 | Q9: 46031 | S9: ・ | T9: ・ | W9: ・ | AA9: ・ | AC9: ・ | AG9: ・ | AK9: ・ | AO9: ・ | AV9: ・ | AW9: ・ | AY9: ・ | AZ9: 000371187 | BA9: JREM | BB9: 天王洲アイル | BC9: 中央 | BD9: =COUNTIF(S9:AY9,"・") -> 11
A10: 21339 | H10: 3529 | I10: VU-LD091 | J10: 46014 | K10: 46031 | M10: ・ | N10: =IFERROR(INDEX([4]Ｖ８出荷・完了計画!$B$5:$B$2593,MATCH(A10,[4]Ｖ８出荷・完了計画!$M$5:$M$2593,0),1),N11) -> 46030 | O10: =INDEX([5]光真稼働日早見表!$M$3:$M$10000,MATCH($N10,[5]光真稼働日早見表!$Q$3:$Q$10000,0),1) -> 46017 | P10: =INDEX([5]光真稼働日早見表!$N$3:$N$10000,MATCH($Q10,[5]光真稼働日早見表!$Q$3:$Q$10000,0),1) -> 46028 | Q10: 46031 | S10: ・ | T10: ・ | W10: ・ | AA10: ・ | AC10: ・ | AG10: ・ | AK10: ・ | AO10: ・ | AV10: ・ | AW10: ・ | AY10: ・ | AZ10: 000393964 | BA10: JREM | BB10: 天空橋 | BC10: 本屋 | BD10: =COUNTIF(S10:AY10,"・") -> 11
A11: 21340 | H11: 3530 | I11: VU-LD091 | J11: 46015 | K11: 46035 | M11: ・ | N11: =IFERROR(INDEX([4]Ｖ８出荷・完了計画!$B$5:$B$2593,MATCH(A11,[4]Ｖ８出荷・完了計画!$M$5:$M$2593,0),1),N12) -> 46030 | O11: =INDEX([5]光真稼働日早見表!$M$3:$M$10000,MATCH($N11,[5]光真稼働日早見表!$Q$3:$Q$10000,0),1) -> 46017 | P11: =INDEX([5]光真稼働日早見表!$N$3:$N$10000,MATCH($Q11,[5]光真稼働日早見表!$Q$3:$Q$10000,0),1) -> 46029 | Q11: 46035 | S11: ・ | T11: ・ | W11: ・ | AA11: ・ | AC11: ・ | AG11: ・ | AK11: ・ | AO11: ・ | AV11: ・ | AW11: ・ | AY11: ・ | AZ11: 000375150 | BA11: JREM | BB11: JREM機械設備技術センター | BD11: =COUNTIF(S11:AY11,"・") -> 11
A12: 21341 | H12: 3531 | I12: VU-LD091 | J12: 46015 | K12: 46035 | M12: ・ | N12: =IFERROR(INDEX([4]Ｖ８出荷・完了計画!$B$5:$B$2593,MATCH(A12,[4]Ｖ８出荷・完了計画!$M$5:$M$2593,0),1),N13) -> 46030 | O12: =INDEX([5]光真稼働日早見表!$M$3:$M$10000,MATCH($N12,[5]光真稼働日早見表!$Q$3:$Q$10000,0),1) -> 46017 | P12: =INDEX([5]光真稼働日早見表!$N$3:$N$10000,MATCH($Q12,[5]光真稼働日早見表!$Q$3:$Q$10000,0),1) -> 46029 | Q12: 46035 | S12: ・ | T12: ・ | W12: ・ | AA12: ・ | AC12: ・ | AG12: ・ | AK12: ・ | AO12: ・ | AV12: ・ | AW12: ・ | AY12: ・ | AZ12: 000393966 | BA12: JREM | BB12: 新整備場 | BD12: =COUNTIF(S12:AY12,"・") -> 11
A13: 21342 | E13: 8206 | I13: VU-LB106 | J13: 46016 | K13: 46036 | M13: ・ | N13: =IFERROR(INDEX([4]Ｖ８出荷・完了計画!$B$5:$B$2593,MATCH(A13,[4]Ｖ８出荷・完了計画!$M$5:$M$2593,0),1),N14) -> 46031 | O13: =INDEX([5]光真稼働日早見表!$M$3:$M$10000,MATCH($N13,[5]光真稼働日早見表!$Q$3:$Q$10000,0),1) -> 46027 | P13: =INDEX([5]光真稼働日早見表!$N$3:$N$10000,MATCH($Q13,[5]光真稼働日早見表!$Q$3:$Q$10000,0),1) -> 46030 | Q13: 46036 | S13: ・ | T13: ・ | W13: ・ | Y13: ・ | AC13: ・ | AE13: ・ | AH13: ・ | AL13: ・ | AS13: ・ | AW13: ・ | AY13: ・ | AZ13: 000381125 | BA13: 南海 | BB13: 七道 | BD13: =COUNTIF(S13:AY13,"・") -> 11
A14: 21343 | E14: 8207 | I14: VU-LA004 | J14: 46017 | K14: 46037 | M14: ・ | N14: =IFERROR(INDEX([4]Ｖ８出荷・完了計画!$B$5:$B$2593,MATCH(A14,[4]Ｖ８出荷・完了計画!$M$5:$M$2593,0),1),N15) -> 46031 | O14: =INDEX([5]光真稼働日早見表!$M$3:$M$10000,MATCH($N14,[5]光真稼働日早見表!$Q$3:$Q$10000,0),1) -> 46027 | P14: =INDEX([5]光真稼働日早見表!$N$3:$N$10000,MATCH($Q14,[5]光真稼働日早見表!$Q$3:$Q$10000,0),1) -> 46031 | Q14: 46037 | S14: ・ | T14: ・ | W14: ・ | Y14: ・ | AD14: ・ | AE14: ・ | AH14: ・ | AL14: ・ | AS14: ・ | AW14: ・ | AY14: ・ | AZ14: 000394016 | BA14: M社（Ｎ） | BC14: VU-LA004 | BD14: =COUNTIF(S14:AY14,"・") -> 11
A15: 21344 | E15: 8208 | I15: VU-LA004 | J15: 46017 | K15: 46037 | M15: ・ | N15: =IFERROR(INDEX([4]Ｖ８出荷・完了計画!$B$5:$B$2593,MATCH(A15,[4]Ｖ８出荷・完了計画!$M$5:$M$2593,0),1),N16) -> 46031 | O15: =INDEX([5]光真稼働日早見表!$M$3:$M$10000,MATCH($N15,[5]光真稼働日早見表!$Q$3:$Q$10000,0),1) -> 46027 | P15: =INDEX([5]光真稼働日早見表!$N$3:$N$10000,MATCH($Q15,[5]光真稼働日早見表!$Q$3:$Q$10000,0),1) -> 46031 | Q15: 46037 | S15: ・ | T15: ・ | W15: ・ | Y15: ・ | AD15: ・ | AE15: ・ | AH15: ・ | AL15: ・ | AS15: ・ | AW15: ・ | AY15: ・ | AZ15: 000371238 | BA15: M社（Ｎ） | BC15: VU-LA004 | BD15: =COUNTIF(S15:AY15,"・") -> 11
A16: 21345 | B16: 3219 | I16: VU-LA007 | J16: 46017 | K16: 46037 | M16: ・ | N16: =IFERROR(INDEX([4]Ｖ８出荷・完了計画!$B$5:$B$2593,MATCH(A16,[4]Ｖ８出荷・完了計画!$M$5:$M$2593,0),1),N17) -> 46031 | O16: =INDEX([5]光真稼働日早見表!$M$3:$M$10000,MATCH($N16,[5]光真稼働日早見表!$Q$3:$Q$10000,0),1) -> 46027 | P16: =INDEX([5]光真稼働日早見表!$N$3:$N$10000,MATCH($Q16,[5]光真稼働日早見表!$Q$3:$Q$10000,0),1) -> 46031 | Q16: 46037 | S16: ・ | T16: ・ | W16: ・ | Y16: ・ | AD16: ・ | AE16: ・ | AH16: ・ | AL16: ・ | AP16: ・ | AX16: ・ | AY16: ・ | AZ16: 000384916 | BA16: N社（Ｎ） | BC16: VU-LA007 | BD16: =COUNTIF(S16:AY16,"・") -> 11
A17: 21346 | E17: 8209 | I17: VU-LB106 | J17: 46017 | K17: 46037 | M17: ・ | N17: =IFERROR(INDEX([4]Ｖ８出荷・完了計画!$B$5:$B$2593,MATCH(A17,[4]Ｖ８出荷・完了計画!$M$5:$M$2593,0),1),N18) -> 46035 | O17: =INDEX([5]光真稼働日早見表!$M$3:$M$10000,MATCH($N17,[5]光真稼働日早見表!$Q$3:$Q$10000,0),1) -> 46028 | P17: =INDEX([5]光真稼働日早見表!$N$3:$N$10000,MATCH($Q17,[5]光真稼働日早見表!$Q$3:$Q$10000,0),1) -> 46031 | Q17: 46037 | S17: ・ | T17: ・ | W17: ・ | Y17: ・ | AC17: ・ | AE17: ・ | AH17: ・ | AL17: ・ | AS17: ・ | AW17: ・ | AY17: ・ | AZ17: 000381128 | BA17: 南海 | BB17: 湊 | BD17: =COUNTIF(S17:AY17,"・") -> 11
A18: 21347 | E18: 8210 | I18: VU-LA004 | J18: 46027 | K18: 46038 | M18: ・ | N18: =IFERROR(INDEX([4]Ｖ８出荷・完了計画!$B$5:$B$2593,MATCH(A18,[4]Ｖ８出荷・完了計画!$M$5:$M$2593,0),1),N19) -> 46035 | O18: =INDEX([5]光真稼働日早見表!$M$3:$M$10000,MATCH($N18,[5]光真稼働日早見表!$Q$3:$Q$10000,0),1) -> 46028 | P18: =INDEX([5]光真稼働日早見表!$N$3:$N$10000,MATCH($Q18,[5]光真稼働日早見表!$Q$3:$Q$10000,0),1) -> 46035 | Q18: 46038 | S18: ・ | T18: ・ | W18: ・ | Y18: ・ | AD18: ・ | AE18: ・ | AH18: ・ | AL18: ・ | AS18: ・ | AW18: ・ | AY18: ・ | AZ18: 000394022 | BA18: M社（Ｎ） | BC18: VU-LA004 | BD18: =COUNTIF(S18:AY18,"・") -> 11
A19: 21348 | E19: 8211 | I19: VU-LA004 | J19: 46027 | K19: 46038 | M19: ・ | N19: =IFERROR(INDEX([4]Ｖ８出荷・完了計画!$B$5:$B$2593,MATCH(A19,[4]Ｖ８出荷・完了計画!$M$5:$M$2593,0),1),N20) -> 46035 | O19: =INDEX([5]光真稼働日早見表!$M$3:$M$10000,MATCH($N19,[5]光真稼働日早見表!$Q$3:$Q$10000,0),1) -> 46028 | P19: =INDEX([5]光真稼働日早見表!$N$3:$N$10000,MATCH($Q19,[5]光真稼働日早見表!$Q$3:$Q$10000,0),1) -> 46035 | Q19: 46038 | S19: ・ | T19: ・ | W19: ・ | Y19: ・ | AD19: ・ | AE19: ・ | AH19: ・ | AL19: ・ | AS19: ・ | AW19: ・ | AY19: ・ | AZ19: 000394020 | BA19: M社（Ｎ） | BC19: VU-LA004 | BD19: =COUNTIF(S19:AY19,"・") -> 11
A20: 21349 | E20: 8212 | I20: VU-LA004 | J20: 46027 | K20: 46038 | M20: ・ | N20: =IFERROR(INDEX([4]Ｖ８出荷・完了計画!$B$5:$B$2593,MATCH(A20,[4]Ｖ８出荷・完了計画!$M$5:$M$2593,0),1),N21) -> 46036 | O20: =INDEX([5]光真稼働日早見表!$M$3:$M$10000,MATCH($N20,[5]光真稼働日早見表!$Q$3:$Q$10000,0),1) -> 46029 | P20: =INDEX([5]光真稼働日早見表!$N$3:$N$10000,MATCH($Q20,[5]光真稼働日早見表!$Q$3:$Q$10000,0),1) -> 46035 | Q20: 46038 | S20: ・ | T20: ・ | W20: ・ | Y20: ・ | AD20: ・ | AE20: ・ | AH20: ・ | AL20: ・ | AS20: ・ | AW20: ・ | AY20: ・ | AZ20: 000394024 | BA20: M社（Ｎ） | BC20: VU-LA004 | BD20: =COUNTIF(S20:AY20,"・") -> 11
A21: 21350 | E21: 8213 | I21: VU-LA004 | J21: 46027 | K21: 46038 | M21: ・ | N21: =IFERROR(INDEX([4]Ｖ８出荷・完了計画!$B$5:$B$2593,MATCH(A21,[4]Ｖ８出荷・完了計画!$M$5:$M$2593,0),1),N22) -> 46036 | O21: =INDEX([5]光真稼働日早見表!$M$3:$M$10000,MATCH($N21,[5]光真稼働日早見表!$Q$3:$Q$10000,0),1) -> 46029 | P21: =INDEX([5]光真稼働日早見表!$N$3:$N$10000,MATCH($Q21,[5]光真稼働日早見表!$Q$3:$Q$10000,0),1) -> 46035 | Q21: 46038 | S21: ・ | T21: ・ | W21: ・ | Y21: ・ | AD21: ・ | AE21: ・ | AH21: ・ | AL21: ・ | AS21: ・ | AW21: ・ | AY21: ・ | AZ21: 000394018 | BA21: M社（Ｎ） | BC21: VU-LA004 | BD21: =COUNTIF(S21:AY21,"・") -> 11
A22: 21351 | F22: 1253 | I22: VU-LB112 | J22: 46027 | K22: 46038 | M22: ・ | N22: =IFERROR(INDEX([4]Ｖ８出荷・完了計画!$B$5:$B$2593,MATCH(A22,[4]Ｖ８出荷・完了計画!$M$5:$M$2593,0),1),N23) -> 46036 | O22: =INDEX([5]光真稼働日早見表!$M$3:$M$10000,MATCH($N22,[5]光真稼働日早見表!$Q$3:$Q$10000,0),1) -> 46029 | P22: =INDEX([5]光真稼働日早見表!$N$3:$N$10000,MATCH($Q22,[5]光真稼働日早見表!$Q$3:$Q$10000,0),1) -> 46035 | Q22: 46038 | S22: ・ | T22: ・ | W22: ・ | Z22: ・ | AC22: ・ | AE22: ・ | AH22: ・ | AL22: ・ | AT22: ・ | AW22: ・ | AY22: ・ | AZ22: 000380740 | BA22: JR西 | BB22: 摩耶 | BD22: =COUNTIF(S22:AY22,"・") -> 11
A23: 21352 | E23: 8214 | I23: VU-LA004 | J23: 46028 | K23: 46041 | M23: ・ | N23: =IFERROR(INDEX([4]Ｖ８出荷・完了計画!$B$5:$B$2593,MATCH(A23,[4]Ｖ８出荷・完了計画!$M$5:$M$2593,0),1),N24) -> 46037 | O23: =INDEX([5]光真稼働日早見表!$M$3:$M$10000,MATCH($N23,[5]光真稼働日早見表!$Q$3:$Q$10000,0),1) -> 46030 | P23: =INDEX([5]光真稼働日早見表!$N$3:$N$10000,MATCH($Q23,[5]光真稼働日早見表!$Q$3:$Q$10000,0),1) -> 46037 | Q23: 46041 | S23: ・ | T23: ・ | W23: ・ | Y23: ・ | AD23: ・ | AE23: ・ | AH23: ・ | AL23: ・ | AS23: ・ | AW23: ・ | AY23: ・ | AZ23: 000394015 | BA23: M社（Ｎ） | BC23: VU-LA004 | BD23: =COUNTIF(S23:AY23,"・") -> 11
A24: 21353 | E24: 8215 | I24: VU-LA004 | J24: 46028 | K24: 46041 | M24: ・ | N24: =IFERROR(INDEX([4]Ｖ８出荷・完了計画!$B$5:$B$2593,MATCH(A24,[4]Ｖ８出荷・完了計画!$M$5:$M$2593,0),1),N25) -> 46037 | O24: =INDEX([5]光真稼働日早見表!$M$3:$M$10000,MATCH($N24,[5]光真稼働日早見表!$Q$3:$Q$10000,0),1) -> 46030 | P24: =INDEX([5]光真稼働日早見表!$N$3:$N$10000,MATCH($Q24,[5]光真稼働日早見表!$Q$3:$Q$10000,0),1) -> 46037 | Q24: 46041 | S24: ・ | T24: ・ | W24: ・ | Y24: ・ | AD24: ・ | AE24: ・ | AH24: ・ | AL24: ・ | AS24: ・ | AW24: ・ | AY24: ・ | AZ24: 000394025 | BA24: M社（Ｎ） | BC24: VU-LA004 | BD24: =COUNTIF(S24:AY24,"・") -> 11
A25: 21354 | E25: 8216 | I25: VU-LA004 | J25: 46028 | K25: 46041 | M25: ・ | N25: =IFERROR(INDEX([4]Ｖ８出荷・完了計画!$B$5:$B$2593,MATCH(A25,[4]Ｖ８出荷・完了計画!$M$5:$M$2593,0),1),N26) -> 46037 | O25: =INDEX([5]光真稼働日早見表!$M$3:$M$10000,MATCH($N25,[5]光真稼働日早見表!$Q$3:$Q$10000,0),1) -> 46030 | P25: =INDEX([5]光真稼働日早見表!$N$3:$N$10000,MATCH($Q25,[5]光真稼働日早見表!$Q$3:$Q$10000,0),1) -> 46037 | Q25: 46041 | S25: ・ | T25: ・ | W25: ・ | Y25: ・ | AD25: ・ | AE25: ・ | AH25: ・ | AL25: ・ | AS25: ・ | AW25: ・ | AY25: ・ | AZ25: 000394013 | BA25: M社（Ｎ） | BC25: VU-LA004 | BD25: =COUNTIF(S25:AY25,"・") -> 11
A26: 21355 | E26: 8217 | I26: VU-LA004 | J26: 46028 | K26: 46041 | M26: ・ | N26: =IFERROR(INDEX([4]Ｖ８出荷・完了計画!$B$5:$B$2593,MATCH(A26,[4]Ｖ８出荷・完了計画!$M$5:$M$2593,0),1),N27) -> 46038 | O26: =INDEX([5]光真稼働日早見表!$M$3:$M$10000,MATCH($N26,[5]光真稼働日早見表!$Q$3:$Q$10000,0),1) -> 46031 | P26: =INDEX([5]光真稼働日早見表!$N$3:$N$10000,MATCH($Q26,[5]光真稼働日早見表!$Q$3:$Q$10000,0),1) -> 46037 | Q26: 46041 | S26: ・ | T26: ・ | W26: ・ | Y26: ・ | AD26: ・ | AE26: ・ | AH26: ・ | AL26: ・ | AS26: ・ | AW26: ・ | AY26: ・ | AZ26: 000394026 | BA26: M社（Ｎ） | BC26: VU-LA004 | BD26: =COUNTIF(S26:AY26,"・") -> 11
A27: 21356 | E27: 8218 | I27: VU-LB106 | J27: 46028 | K27: 46041 | M27: ・ | N27: =IFERROR(INDEX([4]Ｖ８出荷・完了計画!$B$5:$B$2593,MATCH(A27,[4]Ｖ８出荷・完了計画!$M$5:$M$2593,0),1),N28) -> 46038 | O27: =INDEX([5]光真稼働日早見表!$M$3:$M$10000,MATCH($N27,[5]光真稼働日早見表!$Q$3:$Q$10000,0),1) -> 46031 | P27: =INDEX([5]光真稼働日早見表!$N$3:$N$10000,MATCH($Q27,[5]光真稼働日早見表!$Q$3:$Q$10000,0),1) -> 46037 | Q27: 46041 | S27: ・ | T27: ・ | W27: ・ | Y27: ・ | AC27: ・ | AE27: ・ | AH27: ・ | AL27: ・ | AS27: ・ | AW27: ・ | AY27: ・ | AZ27: 000385410 | BA27: 南海 | BB27: 春木 | BC27: 東 | BD27: =COUNTIF(S27:AY27,"・") -> 11
A28: 21357 | E28: 8219 | I28: VU-LA004 | J28: 46029 | K28: 46042 | M28: ・ | N28: =IFERROR(INDEX([4]Ｖ８出荷・完了計画!$B$5:$B$2593,MATCH(A28,[4]Ｖ８出荷・完了計画!$M$5:$M$2593,0),1),N29) -> 46038 | O28: =INDEX([5]光真稼働日早見表!$M$3:$M$10000,MATCH($N28,[5]光真稼働日早見表!$Q$3:$Q$10000,0),1) -> 46031 | P28: =INDEX([5]光真稼働日早見表!$N$3:$N$10000,MATCH($Q28,[5]光真稼働日早見表!$Q$3:$Q$10000,0),1) -> 46038 | Q28: 46042 | S28: ・ | T28: ・ | W28: ・ | Y28: ・ | AD28: ・ | AE28: ・ | AH28: ・ | AL28: ・ | AS28: ・ | AW28: ・ | AY28: ・ | AZ28: 000394023 | BA28: M社（Ｎ） | BC28: VU-LA004 | BD28: =COUNTIF(S28:AY28,"・") -> 11
A29: 21358 | E29: 8220 | I29: VU-LA004 | J29: 46029 | K29: 46042 | M29: ・ | N29: =IFERROR(INDEX([4]Ｖ８出荷・完了計画!$B$5:$B$2593,MATCH(A29,[4]Ｖ８出荷・完了計画!$M$5:$M$2593,0),1),N30) -> 46039 | O29: =INDEX([5]光真稼働日早見表!$M$3:$M$10000,MATCH($N29,[5]光真稼働日早見表!$Q$3:$Q$10000,0),1) -> 46035 | P29: =INDEX([5]光真稼働日早見表!$N$3:$N$10000,MATCH($Q29,[5]光真稼働日早見表!$Q$3:$Q$10000,0),1) -> 46038 | Q29: 46042 | S29: ・ | T29: ・ | W29: ・ | Y29: ・ | AD29: ・ | AE29: ・ | AH29: ・ | AL29: ・ | AS29: ・ | AW29: ・ | AY29: ・ | AZ29: 000394017 | BA29: M社（Ｎ） | BC29: VU-LA004 | BD29: =COUNTIF(S29:AY29,"・") -> 11
A30: 21359 | E30: 8221 | I30: VU-LA004 | J30: 46029 | K30: 46042 | M30: ・ | N30: =IFERROR(INDEX([4]Ｖ８出荷・完了計画!$B$5:$B$2593,MATCH(A30,[4]Ｖ８出荷・完了計画!$M$5:$M$2593,0),1),N31) -> 46039 | O30: =INDEX([5]光真稼働日早見表!$M$3:$M$10000,MATCH($N30,[5]光真稼働日早見表!$Q$3:$Q$10000,0),1) -> 46035 | P30: =INDEX([5]光真稼働日早見表!$N$3:$N$10000,MATCH($Q30,[5]光真稼働日早見表!$Q$3:$Q$10000,0),1) -> 46038 | Q30: 46042 | S30: ・ | T30: ・ | W30: ・ | Y30: ・ | AD30: ・ | AE30: ・ | AH30: ・ | AL30: ・ | AS30: ・ | AW30: ・ | AY30: ・ | AZ30: 000394027 | BA30: M社（Ｎ） | BC30: VU-LA004 | BD30: =COUNTIF(S30:AY30,"・") -> 11
A31: 21360 | E31: 8222 | I31: VU-LA004 | J31: 46029 | K31: 46042 | M31: ・ | N31: =IFERROR(INDEX([4]Ｖ８出荷・完了計画!$B$5:$B$2593,MATCH(A31,[4]Ｖ８出荷・完了計画!$M$5:$M$2593,0),1),N32) -> 46039 | O31: =INDEX([5]光真稼働日早見表!$M$3:$M$10000,MATCH($N31,[5]光真稼働日早見表!$Q$3:$Q$10000,0),1) -> 46035 | P31: =INDEX([5]光真稼働日早見表!$N$3:$N$10000,MATCH($Q31,[5]光真稼働日早見表!$Q$3:$Q$10000,0),1) -> 46038 | Q31: 46042 | S31: ・ | T31: ・ | W31: ・ | Y31: ・ | AD31: ・ | AE31: ・ | AH31: ・ | AL31: ・ | AS31: ・ | AW31: ・ | AY31: ・ | AZ31: 000394014 | BA31: M社（Ｎ） | BC31: VU-LA004 | BD31: =COUNTIF(S31:AY31,"・") -> 11
A32: 21361 | E32: 8223 | I32: VU-LB106 | J32: 46029 | K32: 46042 | M32: ・ | N32: =IFERROR(INDEX([4]Ｖ８出荷・完了計画!$B$5:$B$2593,MATCH(A32,[4]Ｖ８出荷・完了計画!$M$5:$M$2593,0),1),N33) -> 46041 | O32: =INDEX([5]光真稼働日早見表!$M$3:$M$10000,MATCH($N32,[5]光真稼働日早見表!$Q$3:$Q$10000,0),1) -> 46036 | P32: =INDEX([5]光真稼働日早見表!$N$3:$N$10000,MATCH($Q32,[5]光真稼働日早見表!$Q$3:$Q$10000,0),1) -> 46038 | Q32: 46042 | S32: ・ | T32: ・ | W32: ・ | Y32: ・ | AC32: ・ | AE32: ・ | AH32: ・ | AL32: ・ | AS32: ・ | AW32: ・ | AY32: ・ | AZ32: 000385411 | BA32: 南海 | BB32: 貝塚 | BC32: 東 | BD32: =COUNTIF(S32:AY32,"・") -> 11
A33: 21362 | E33: 8224 | I33: VU-LB106 | J33: 46029 | K33: 46042 | M33: ・ | N33: =IFERROR(INDEX([4]Ｖ８出荷・完了計画!$B$5:$B$2593,MATCH(A33,[4]Ｖ８出荷・完了計画!$M$5:$M$2593,0),1),N34) -> 46041 | O33: =INDEX([5]光真稼働日早見表!$M$3:$M$10000,MATCH($N33,[5]光真稼働日早見表!$Q$3:$Q$10000,0),1) -> 46036 | P33: =INDEX([5]光真稼働日早見表!$N$3:$N$10000,MATCH($Q33,[5]光真稼働日早見表!$Q$3:$Q$10000,0),1) -> 46038 | Q33: 46042 | S33: ・ | T33: ・ | W33: ・ | Y33: ・ | AC33: ・ | AE33: ・ | AH33: ・ | AL33: ・ | AS33: ・ | AW33: ・ | AY33: ・ | AZ33: 000385416 | BA33: 南海 | BB33: 初芝 | BD33: =COUNTIF(S33:AY33,"・") -> 11
A34: 21363 | E34: 8225 | I34: VU-LA004 | J34: 46030 | K34: 46043 | M34: ・ | N34: =IFERROR(INDEX([4]Ｖ８出荷・完了計画!$B$5:$B$2593,MATCH(A34,[4]Ｖ８出荷・完了計画!$M$5:$M$2593,0),1),N35) -> 46041 | O34: =INDEX([5]光真稼働日早見表!$M$3:$M$10000,MATCH($N34,[5]光真稼働日早見表!$Q$3:$Q$10000,0),1) -> 46036 | P34: =INDEX([5]光真稼働日早見表!$N$3:$N$10000,MATCH($Q34,[5]光真稼働日早見表!$Q$3:$Q$10000,0),1) -> 46039 | Q34: 46043 | S34: ・ | T34: ・ | W34: ・ | Y34: ・ | AD34: ・ | AE34: ・ | AH34: ・ | AL34: ・ | AS34: ・ | AW34: ・ | AY34: ・ | AZ34: 000394019 | BA34: M社（Ｎ） | BC34: VU-LA004 | BD34: =COUNTIF(S34:AY34,"・") -> 11
A35: 21364 | E35: 8226 | I35: VU-LA004 | J35: 46030 | K35: 46043 | M35: ・ | N35: =IFERROR(INDEX([4]Ｖ８出荷・完了計画!$B$5:$B$2593,MATCH(A35,[4]Ｖ８出荷・完了計画!$M$5:$M$2593,0),1),N36) -> 46042 | O35: =INDEX([5]光真稼働日早見表!$M$3:$M$10000,MATCH($N35,[5]光真稼働日早見表!$Q$3:$Q$10000,0),1) -> 46037 | P35: =INDEX([5]光真稼働日早見表!$N$3:$N$10000,MATCH($Q35,[5]光真稼働日早見表!$Q$3:$Q$10000,0),1) -> 46039 | Q35: 46043 | S35: ・ | T35: ・ | W35: ・ | Y35: ・ | AD35: ・ | AE35: ・ | AH35: ・ | AL35: ・ | AS35: ・ | AW35: ・ | AY35: ・ | AZ35: 000394021 | BA35: M社（Ｎ） | BC35: VU-LA004 | BD35: =COUNTIF(S35:AY35,"・") -> 11
A36: 21365 | E36: 8227 | I36: VU-LB106 | J36: 46030 | K36: 46043 | M36: ・ | N36: =IFERROR(INDEX([4]Ｖ８出荷・完了計画!$B$5:$B$2593,MATCH(A36,[4]Ｖ８出荷・完了計画!$M$5:$M$2593,0),1),N37) -> 46042 | O36: =INDEX([5]光真稼働日早見表!$M$3:$M$10000,MATCH($N36,[5]光真稼働日早見表!$Q$3:$Q$10000,0),1) -> 46037 | P36: =INDEX([5]光真稼働日早見表!$N$3:$N$10000,MATCH($Q36,[5]光真稼働日早見表!$Q$3:$Q$10000,0),1) -> 46039 | Q36: 46043 | S36: ・ | T36: ・ | W36: ・ | Y36: ・ | AC36: ・ | AE36: ・ | AH36: ・ | AL36: ・ | AS36: ・ | AW36: ・ | AY36: ・ | AZ36: 000385413 | BA36: 南海 | BB36: 沢ノ町 | BC36: 西 | BD36: =COUNTIF(S36:AY36,"・") -> 11
A37: 21366 | E37: 8228 | I37: VU-LB106 | J37: 46030 | K37: 46043 | M37: ・ | N37: =IFERROR(INDEX([4]Ｖ８出荷・完了計画!$B$5:$B$2593,MATCH(A37,[4]Ｖ８出荷・完了計画!$M$5:$M$2593,0),1),N38) -> 46042 | O37: =INDEX([5]光真稼働日早見表!$M$3:$M$10000,MATCH($N37,[5]光真稼働日早見表!$Q$3:$Q$10000,0),1) -> 46037 | P37: =INDEX([5]光真稼働日早見表!$N$3:$N$10000,MATCH($Q37,[5]光真稼働日早見表!$Q$3:$Q$10000,0),1) -> 46039 | Q37: 46043 | S37: ・ | T37: ・ | W37: ・ | Y37: ・ | AC37: ・ | AE37: ・ | AH37: ・ | AL37: ・ | AS37: ・ | AW37: ・ | AY37: ・ | AZ37: 000385414 | BA37: 南海 | BB37: 百舌鳥八幡 | BC37: 西 | BD37: =COUNTIF(S37:AY37,"・") -> 11
A38: 21367 | E38: 8229 | I38: VU-LB106 | J38: 46031 | K38: 46044 | M38: ・ | N38: =IFERROR(INDEX([4]Ｖ８出荷・完了計画!$B$5:$B$2593,MATCH(A38,[4]Ｖ８出荷・完了計画!$M$5:$M$2593,0),1),N39) -> 46043 | O38: =INDEX([5]光真稼働日早見表!$M$3:$M$10000,MATCH($N38,[5]光真稼働日早見表!$Q$3:$Q$10000,0),1) -> 46038 | P38: =INDEX([5]光真稼働日早見表!$N$3:$N$10000,MATCH($Q38,[5]光真稼働日早見表!$Q$3:$Q$10000,0),1) -> 46041 | Q38: 46044 | S38: ・ | T38: ・ | W38: ・ | Y38: ・ | AC38: ・ | AE38: ・ | AH38: ・ | AL38: ・ | AS38: ・ | AW38: ・ | AY38: ・ | AZ38: 000385412 | BA38: 南海 | BB38: 羽倉崎 | BC38: 東 | BD38: =COUNTIF(S38:AY38,"・") -> 11
A39: 21368 | E39: 8230 | I39: VU-LB106 | J39: 46035 | K39: 46045 | M39: ・ | N39: =IFERROR(INDEX([4]Ｖ８出荷・完了計画!$B$5:$B$2593,MATCH(A39,[4]Ｖ８出荷・完了計画!$M$5:$M$2593,0),1),N40) -> 46044 | O39: =INDEX([5]光真稼働日早見表!$M$3:$M$10000,MATCH($N39,[5]光真稼働日早見表!$Q$3:$Q$10000,0),1) -> 46039 | P39: =INDEX([5]光真稼働日早見表!$N$3:$N$10000,MATCH($Q39,[5]光真稼働日早見表!$Q$3:$Q$10000,0),1) -> 46042 | Q39: 46045 | S39: ・ | T39: ・ | W39: ・ | Y39: ・ | AC39: ・ | AE39: ・ | AH39: ・ | AL39: ・ | AS39: ・ | AW39: ・ | AY39: ・ | AZ39: 000385415 | BA39: 南海 | BB39: 関西空港 | BD39: =COUNTIF(S39:AY39,"・") -> 11
A40: 21369 | F40: 1254 | I40: VU-LB112 | J40: 46036 | K40: 46048 | M40: ・ | N40: =IFERROR(INDEX([4]Ｖ８出荷・完了計画!$B$5:$B$2593,MATCH(A40,[4]Ｖ８出荷・完了計画!$M$5:$M$2593,0),1),N41) -> 46045 | O40: =INDEX([5]光真稼働日早見表!$M$3:$M$10000,MATCH($N40,[5]光真稼働日早見表!$Q$3:$Q$10000,0),1) -> 46041 | P40: =INDEX([5]光真稼働日早見表!$N$3:$N$10000,MATCH($Q40,[5]光真稼働日早見表!$Q$3:$Q$10000,0),1) -> 46043 | Q40: 46048 | S40: ・ | T40: ・ | W40: ・ | Z40: ・ | AC40: ・ | AE40: ・ | AH40: ・ | AL40: ・ | AT40: ・ | AW40: ・ | AY40: ・ | AZ40: 000380741 | BA40: JR西 | BB40: 鷹取 | BD40: =COUNTIF(S40:AY40,"・") -> 11
A41: 21370 | E41: 8231 | I41: VU-LA004 | J41: 46043 | K41: 46055 | M41: ・ | N41: =IFERROR(INDEX([4]Ｖ８出荷・完了計画!$B$5:$B$2593,MATCH(A41,[4]Ｖ８出荷・完了計画!$M$5:$M$2593,0),1),N42) -> 46051 | O41: =INDEX([5]光真稼働日早見表!$M$3:$M$10000,MATCH($N41,[5]光真稼働日早見表!$Q$3:$Q$10000,0),1) -> 46045 | P41: =INDEX([5]光真稼働日早見表!$N$3:$N$10000,MATCH($Q41,[5]光真稼働日早見表!$Q$3:$Q$10000,0),1) -> 46050 | Q41: 46055 | S41: ・ | T41: ・ | W41: ・ | Y41: ・ | AD41: ・ | AE41: ・ | AH41: ・ | AL41: ・ | AS41: ・ | AW41: ・ | AY41: ・ | AZ41: 000384260 | BA41: M社（Ｎ） | BC41: VU-LA004 | BD41: =COUNTIF(S41:AY41,"・") -> 11
...

Sheet V8structure 
A1: Ｖ８－ＢＨ UNIT STRUCTURE （2019/12/6）
A2: . | C2: 1 | D2: 2 | E2: 3 | F2: 4 | G2: 5 | H2: 6 | I2: 7 | J2: 8 | K2: 9 | L2: 10 | M2: 11 | N2: 12 | O2: 13 | P2: 14 | Q2: 15 | R2: 16 | S2: 17 | T2: 18 | U2: 19 | V2: 20 | W2: 21 | X2: 22 | Y2: 23 | Z2: 24 | AA2: 25 | AB2: 26 | AC2: 27 | AD2: 28 | AE2: 29 | AF2: 30 | AG2: 31 | AH2: 32 | AI2: 33 | AJ2: 34 | AK2: 35 | AL2: 36 | AM2: 37 | AN2: 38 | AO2: 39 | AP2: 40 | AQ2: 41 | AR2: 42 | AS2: 43 | AT2: 44 | AU2: 45 | AV2: 46 | AW2: 47 | AX2: 48 | AY2: 49 | AZ2: 50
C3: production | D3: KMP | E3: KMP | F3: KMP | G3: KMP | H3: KMP | I3: KMP | J3: KMP | K3: KMP | L3: KMP | M3: KMP | N3: KMP | O3: KMP | P3: KMP | Q3: KMP | R3: KMP | S3: KMP | T3: KMP | U3: KMP | V3: KMP | W3: KMP | X3: KMP | Y3: KMP | Z3: KMP | AA3: J-KOSS | AB3: J-KOSS | AC3: J-KOSS | AD3: J-KOSS | AE3: J-KOSS | AF3: J-KOSS | AG3: J-KOSS | AH3: J-KOSS | AI3: J-KOSS | AJ3: J-KOSS | AL3: OSS | AM3: OSS
C4: UNIT No | D4: 0184429-0 | E4: 1876212-3 | F4: 3249850-1 | G4: 3139386-2 | H4: 1876278-6 | I4: 3729591-9 | J4: 0184763-0 | K4: 9064355-4 | L4: 9912506-8 | M4: 1876267-0 | N4: 3729668-0 | O4: 1876265-4 | P4: 1876242-5 | Q4: 3139392-7 | R4: 1876244-1 | S4: 1868741-5 | T4: 3139382-0 | U4: 1868739-3 | V4: 5343350-7 | W4: 1868742-3 | X4: 3139404-4 | Y4: 1868740-7 | Z4: 5343349-3 | AA4: 1892440-9 | AB4: 3729514-5 | AC4: 3247289-8 | AD4: 0184427-4 | AE4: 9066030-0 | AF4: 3139406-0 | AG4: 9912561-0 | AH4: 1876275-1 | AI4: 1892439-5 | AJ4: 1876277-8 | AL4: 0184762-1 | AM4: 1878529-8
C5: UNIT No | D5: 184 | E5: 1876 | F5: 3249 | G5: 3139 | H5: 1876 | I5: 3729 | J5: 184 | K5: 9064 | L5: 9912 | M5: 1876 | N5: 3729 | O5: 1876 | P5: 1876 | Q5: 3139 | R5: 1876 | S5: 1868 | T5: 3139 | U5: 1868 | V5: 5343 | W5: 1868 | X5: 3139 | Y5: 1868 | Z5: 5343 | AA5: 1892 | AB5: 3729 | AC5: 3247 | AD5: 184 | AE5: 9066 | AF5: 3139 | AG5: 9912 | AH5: 1876 | AI5: 1892 | AJ5: 1876 | AL5: 184 | AM5: 1878
D6: 429-0 | E6: 212-3 | F6: 850-1 | G6: 386-2 | H6: 278-6 | I6: 591-9 | J6: 763-0 | K6: 355-4 | L6: 506-8 | M6: 267-0 | N6: 668-0 | O6: 265-4 | P6: 242-5 | Q6: 392-7 | R6: 244-1 | S6: 741-5 | T6: 382-0 | U6: 739-3 | V6: 350-7 | W6: 742-3 | X6: 404-4 | Y6: 740-7 | Z6: 349-3 | AA6: 440-9 | AB6: 514-5 | AC6: 289-8 | AD6: 427-4 | AE6: 030-0 | AF6: 406-0 | AG6: 561-0 | AH6: 275-1 | AI6: 439-5 | AJ6: 277-8 | AL6: 762-1 | AM6: 529-8
C7: unit name | D7: TRANCEPOTER | E7: 5000YEN | H7: CHENGE BILL STOCK | J7: ＩＮＬＥＴ | M7: REAR REPLENISHMENT | O7: SHELTER | P7: RECOVERY | S7: 10000YEN | W7: 1000YEN | AA7: ｷﾎﾝﾌﾞ | AH7: ﾌﾚｰﾑﾌﾞ | AJ7: ﾚ-ﾙﾌﾞ | AL7: ｼﾍｲｼｷﾍﾞﾂﾌﾞ
C8: ユニット名 | D8: ﾊﾝｿｳﾌﾞ | E8: 5000ｴﾝﾌﾞ | H8: ﾂﾘｼﾍｲﾎﾘﾕｳﾌﾞ | J8: ｿｳﾆｭｳｺｳﾌﾞ | M8: ﾎｷﾕｳﾌﾞｺｳﾎｳ | O8: ﾀｲﾋﾌﾞ | P8: ｶｲｼﾕｳﾌﾞ | S8: 10000ｴﾝﾌﾞ | W8: 1000ｴﾝﾌﾞ | AL8: ＢＩＤ
A9: No | B9: ＢＨ No | C9: type | D9: LAA101 | E9: LAF001 | F9: LAF002 | G9: LAF003 | H9: LAG001 | I9: LAG002 | J9: LAE101 | K9: LAE102 | L9: LAE201 | M9: LBL001 | N9: LBL002 | O9: LAL001 | P9: LAN001 | Q9: LAN002 | R9: LCN001 | S9: LAC001 | T9: LAC002 | U9: LCC001 | V9: LCC002 | W9: LAD001 | X9: LAD002 | Y9: LCD001 | Z9: LCD002 | AA9: LAZ002 | AB9: LAZ003 | AC9: LAZ004 | AD9: LAZ101 | AE9: LAZ102 | AF9: LAZ103 | AG9: LAZ201 | AH9: LAY001 | AI9: LAY002 | AJ9: LAH001 | AK9: 主要 客先 | AL9: LAB101 | AM9: LAB001 | AN9: 基本部 | AO9: ﾌﾚｰﾑ部 | AP9: ﾕﾆｯﾄ数 | AQ9: 搬送部 | AR9: 5000円 | AS9: 釣紙幣 | AT9: 挿入口 | AU9: 補給後方 | AV9: 退避部 | AW9: 回収 | AX9: 10000円 | AY9: 1000円 | AZ9: LAZ色分け
A10: 1 | B10: 1876280-8 | C10: VU-LA001 | D10: ・ | E10: ・ | H10: ・ | J10: ・ | O10: ・ | P10: ・ | S10: ・ | W10: ・ | AD10: ・ | AH10: ・ | AJ10: ・ | AK10: 東京ﾒﾄﾛ | AL10: ・ | AN10: LAZ101 | AO10: LAY001 | AP10: =COUNTA(AM10,AL10,D10:AJ10) -> 12 | AQ10: LAA101 | AR10: LAF001 | AS10: LAG001 | AT10: LAE101 | AU10: - | AV10: LAL001 | AW10: LAN001 | AX10: LAC001 | AY10: LAD001 | AZ10: オレンジ
A11: 2 | B11: 1889220-5 | C11: VU-LA002 | D11: ・ | E11: ・ | H11: ・ | J11: ・ | O11: ・ | P11: ・ | S11: ・ | W11: ・ | AD11: ・ | AH11: ・ | AJ11: ・ | AK11: M社O 大市交 | AL11: ・ | AN11: LAZ101 | AO11: LAY001 | AP11: =COUNTA(AM11,AL11,D11:AJ11) -> 12 | AQ11: LAA101 | AR11: LAF001 | AS11: LAG001 | AT11: LAE101 | AU11: - | AV11: LAL001 | AW11: LAN001 | AX11: LAC001 | AY11: LAD001 | AZ11: オレンジ
A12: 3 | B12: 1889683-9 | C12: VU-LA003 | D12: ・ | E12: ・ | H12: ・ | J12: ・ | O12: ・ | P12: ・ | S12: ・ | W12: ・ | AD12: ・ | AH12: ・ | AJ12: ・ | AK12: M社（Ｆ）・京阪・京市交・近鉄・神市交・静鉄・大市交 | AL12: ・ | AN12: LAZ101 | AO12: LAY001 | AP12: =COUNTA(AM12,AL12,D12:AJ12) -> 12 | AQ12: LAA101 | AR12: LAF001 | AS12: LAG001 | AT12: LAE101 | AU12: - | AV12: LAL001 | AW12: LAN001 | AX12: LAC001 | AY12: LAD001 | AZ12: オレンジ
A13: 4 | B13: 1892581-2 | C13: VU-LA004 | D13: ・ | E13: ・ | H13: ・ | J13: ・ | O13: ・ | P13: ・ | S13: ・ | W13: ・ | AD13: ・ | AH13: ・ | AJ13: ・ | AK13: M社（Ｎ）・（Ｏ）・（Ｔ） | AL13: ・ | AN13: LAZ101 | AO13: LAY001 | AP13: =COUNTA(AM13,AL13,D13:AJ13) -> 12 | AQ13: LAA101 | AR13: LAF001 | AS13: LAG001 | AT13: LAE101 | AU13: - | AV13: LAL001 | AW13: LAN001 | AX13: LAC001 | AY13: LAD001 | AZ13: オレンジ
A14: 5 | B14: 2205957-7 | C14: VU-LA005 | D14: ・ | E14: ・ | H14: ・ | J14: ・ | O14: ・ | P14: ・ | S14: ・ | W14: ・ | AD14: ・ | AH14: ・ | AJ14: ・ | AK14: OFE北 | AM14: ・ | AN14: LAZ101 | AO14: LAY001 | AP14: =COUNTA(AM14,AL14,D14:AJ14) -> 12 | AQ14: LAA101 | AR14: LAF001 | AS14: LAG001 | AT14: LAE101 | AU14: - | AV14: LAL001 | AW14: LAN001 | AX14: LAC001 | AY14: LAD001 | AZ14: オレンジ
A15: 6 | B15: 3249797-1 | C15: VU-LA006 | D15: ・ | E15: ・ | H15: ・ | J15: ・ | O15: ・ | P15: ・ | S15: ・ | W15: ・ | AD15: ・ | AH15: ・ | AJ15: ・ | AK15: 多摩ﾓﾉ | AL15: ・ | AN15: LAZ101 | AO15: LAY001 | AP15: =COUNTA(AM15,AL15,D15:AJ15) -> 12 | AQ15: LAA101 | AR15: LAF001 | AS15: LAG001 | AT15: LAE101 | AU15: - | AV15: LAL001 | AW15: LAN001 | AX15: LAC001 | AY15: LAD001 | AZ15: オレンジ
A16: 7 | B16: 3251849-9 | C16: VU-LA007 | D16: ・ | E16: ・ | H16: ・ | J16: ・ | O16: ・ | P16: ・ | S16: ・ | W16: ・ | AA16: ・ | AI16: ・ | AJ16: ・ | AK16: N社（Ｔ） | AL16: ・ | AN16: LAZ002 | AO16: LAY002 | AP16: =COUNTA(AM16,AL16,D16:AJ16) -> 12 | AQ16: LAA101 | AR16: LAF001 | AS16: LAG001 | AT16: LAE101 | AU16: - | AV16: LAL001 | AW16: LAN001 | AX16: LAC001 | AY16: LAD001 | AZ16: 青
A17: 8 | B17: 3253280-7 | C17: VU-LA008 | D17: ・ | E17: ・ | H17: ・ | J17: ・ | O17: ・ | P17: ・ | S17: ・ | W17: ・ | AD17: ・ | AH17: ・ | AJ17: ・ | AK17: 京市交 南海 | AL17: ・ | AN17: LAZ101 | AO17: LAY001 | AP17: =COUNTA(AM17,AL17,D17:AJ17) -> 12 | AQ17: LAA101 | AR17: LAF001 | AS17: LAG001 | AT17: LAE101 | AU17: - | AV17: LAL001 | AW17: LAN001 | AX17: LAC001 | AY17: LAD001 | AZ17: オレンジ
A18: 9 | B18: 9708375-9 | C18: VU-LA009 | D18: ・ | E18: ・ | H18: ・ | J18: ・ | O18: ・ | P18: ・ | S18: ・ | W18: ・ | AA18: ・ | AI18: ・ | AJ18: ・ | AK18: N社（N） | AL18: ・ | AN18: LAZ002 | AO18: LAY002 | AP18: =COUNTA(AM18,AL18,D18:AJ18) -> 12 | AQ18: LAA101 | AR18: LAF001 | AS18: LAG001 | AT18: LAE101 | AU18: - | AV18: LAL001 | AW18: LAN001 | AX18: LAC001 | AY18: LAD001 | AZ18: 青
A19: 10 | B19: 3137804-9 | C19: VU-LA010 | D19: ・ | E19: ・ | H19: ・ | J19: ・ | O19: ・ | P19: ・ | S19: ・ | W19: ・ | AA19: ・ | AI19: ・ | AJ19: ・ | AK19: N社（Ｔ） | AL19: ・ | AN19: LAZ002 | AO19: LAY002 | AP19: =COUNTA(AM19,AL19,D19:AJ19) -> 12 | AQ19: LAA101 | AR19: LAF001 | AS19: LAG001 | AT19: LAE101 | AU19: - | AV19: LAL001 | AW19: LAN001 | AX19: LAC001 | AY19: LAD001 | AZ19: 青
A20: 11 | B20: 3139136-3 | C20: VU-LA011 | D20: ・ | E20: ・ | H20: ・ | J20: ・ | O20: ・ | P20: ・ | S20: ・ | W20: ・ | AD20: ・ | AH20: ・ | AJ20: ・ | AK20: 大市交 | AL20: ・ | AN20: LAZ101 | AO20: LAY001 | AP20: =COUNTA(AM20,AL20,D20:AJ20) -> 12 | AQ20: LAA101 | AR20: LAF001 | AS20: LAG001 | AT20: LAE101 | AU20: - | AV20: LAL001 | AW20: LAN001 | AX20: LAC001 | AY20: LAD001 | AZ20: オレンジ
A21: 12 | B21: 2872812-8 | C21: VU-LA012 | D21: ・ | E21: ・ | H21: ・ | J21: ・ | O21: ・ | P21: ・ | S21: ・ | W21: ・ | AD21: ・ | AH21: ・ | AJ21: ・ | AK21: 小田急 | AL21: ・ | AN21: LAZ101 | AO21: LAY001 | AP21: =COUNTA(AM21,AL21,D21:AJ21) -> 12 | AQ21: LAA101 | AR21: LAF001 | AS21: LAG001 | AT21: LAE101 | AU21: - | AV21: LAL001 | AW21: LAN001 | AX21: LAC001 | AY21: LAD001 | AZ21: オレンジ
A22: 13 | B22: 1876262-0 | C22: VU-LB001 | D22: ・ | E22: ・ | H22: ・ | J22: ・ | M22: ・ | P22: ・ | S22: ・ | W22: ・ | AD22: ・ | AH22: ・ | AJ22: ・ | AK22: つくば・横浜高速・西武・都交 | AL22: ・ | AN22: LAZ101 | AO22: LAY001 | AP22: =COUNTA(AM22,AL22,D22:AJ22) -> 12 | AQ22: LAA101 | AR22: LAF001 | AS22: LAG001 | AT22: LAE101 | AU22: LBL001 | AV22: - | AW22: LAN001 | AX22: LAC001 | AY22: LAD001 | AZ22: オレンジ
A23: 14 | B23: 1889259-0 | C23: VU-LB002 | D23: ・ | E23: ・ | H23: ・ | J23: ・ | N23: ・ | P23: ・ | S23: ・ | W23: ・ | AA23: ・ | AI23: ・ | AJ23: ・ | AK23: N社ｔ | AL23: ・ | AN23: LAZ002 | AO23: LAY002 | AP23: =COUNTA(AM23,AL23,D23:AJ23) -> 12 | AQ23: LAA101 | AR23: LAF001 | AS23: LAG001 | AT23: LAE101 | AU23: LBL002 | AV23: - | AW23: LAN001 | AX23: LAC001 | AY23: LAD001 | AZ23: 青
A24: 15 | B24: 1889761-4 | C24: VU-LB003 | D24: ・ | E24: ・ | H24: ・ | J24: ・ | N24: ・ | P24: ・ | S24: ・ | W24: ・ | AD24: ・ | AH24: ・ | AJ24: ・ | AK24: 小田急 | AL24: ・ | AN24: LAZ101 | AO24: LAY001 | AP24: =COUNTA(AM24,AL24,D24:AJ24) -> 12 | AQ24: LAA101 | AR24: LAF001 | AS24: LAG001 | AT24: LAE101 | AU24: LBL002 | AV24: - | AW24: LAN001 | AX24: LAC001 | AY24: LAD001 | AZ24: オレンジ
A25: 16 | B25: 1889958-7 | C25: VU-LB004 | D25: ・ | E25: ・ | H25: ・ | J25: ・ | N25: ・ | P25: ・ | S25: ・ | W25: ・ | AD25: ・ | AH25: ・ | AJ25: ・ | AK25: JR海 | AL25: ・ | AN25: LAZ101 | AO25: LAY001 | AP25: =COUNTA(AM25,AL25,D25:AJ25) -> 12 | AQ25: LAA101 | AR25: LAF001 | AS25: LAG001 | AT25: LAE101 | AU25: LBL002 | AV25: - | AW25: LAN001 | AX25: LAC001 | AY25: LAD001 | AZ25: オレンジ
A26: 17 | B26: 1891760-7 | C26: VU-LB005 | D26: ・ | E26: ・ | H26: ・ | J26: ・ | M26: ・ | P26: ・ | S26: ・ | W26: ・ | AD26: ・ | AH26: ・ | AJ26: ・ | AK26: 東武 | AL26: ・ | AN26: LAZ101 | AO26: LAY001 | AP26: =COUNTA(AM26,AL26,D26:AJ26) -> 12 | AQ26: LAA101 | AR26: LAF001 | AS26: LAG001 | AT26: LAE101 | AU26: LBL001 | AV26: - | AW26: LAN001 | AX26: LAC001 | AY26: LAD001 | AZ26: オレンジ
A27: 18 | B27: 2206082-6 | C27: VU-LB006 | D27: ・ | E27: ・ | H27: ・ | J27: ・ | M27: ・ | P27: ・ | S27: ・ | W27: ・ | AA27: ・ | AI27: ・ | AJ27: ・ | AK27: N社（Ｔ） | AL27: ・ | AN27: LAZ002 | AO27: LAY002 | AP27: =COUNTA(AM27,AL27,D27:AJ27) -> 12 | AQ27: LAA101 | AR27: LAF001 | AS27: LAG001 | AT27: LAE101 | AU27: LBL001 | AV27: - | AW27: LAN001 | AX27: LAC001 | AY27: LAD001 | AZ27: 青
A28: 19 | B28: 0184425-8 | C28: VU-LB101 | D28: ・ | E28: ・ | H28: ・ | J28: ・ | N28: ・ | P28: ・ | S28: ・ | W28: ・ | AD28: ・ | AH28: ・ | AJ28: ・ | AK28: M社（Ｔ）・OFET・つくば・京王・神市交・西武・東急・東武 | AL28: ・ | AN28: LAZ101 | AO28: LAY001 | AP28: =COUNTA(AM28,AL28,D28:AJ28) -> 12 | AQ28: LAA101 | AR28: LAF001 | AS28: LAG001 | AT28: LAE101 | AU28: LBL002 | AV28: - | AW28: LAN001 | AX28: LAC001 | AY28: LAD001 | AZ28: オレンジ
A29: 20 | B29: 9909170-8 | C29: VU-LB102 | D29: ・ | E29: ・ | H29: ・ | K29: ・ | N29: ・ | P29: ・ | S29: ・ | W29: ・ | AE29: ・ | AH29: ・ | AJ29: ・ | AK29: JR西 | AL29: ・ | AN29: LAZ102 | AO29: LAY001 | AP29: =COUNTA(AM29,AL29,D29:AJ29) -> 12 | AQ29: LAA101 | AR29: LAF001 | AS29: LAG001 | AT29: LAE102 | AU29: LBL002 | AV29: - | AW29: LAN001 | AX29: LAC001 | AY29: LAD001 | AZ29: 黄
A30: 21 | B30: 5353079-0 | C30: VU-LB103 | D30: ・ | E30: ・ | H30: ・ | J30: ・ | N30: ・ | P30: ・ | S30: ・ | W30: ・ | AD30: ・ | AH30: ・ | AJ30: ・ | AK30: 京阪 N社（Ｎ） | AL30: ・ | AN30: LAZ101 | AO30: LAY001 | AP30: =COUNTA(AM30,AL30,D30:AJ30) -> 12 | AQ30: LAA101 | AR30: LAF001 | AS30: LAG001 | AT30: LAE101 | AU30: LBL002 | AV30: - | AW30: LAN001 | AX30: LAC001 | AY30: LAD001 | AZ30: オレンジ
A31: 22 | B31: 3245432-6 | C31: VU-LB104 | D31: ・ | E31: ・ | H31: ・ | J31: ・ | N31: ・ | P31: ・ | S31: ・ | W31: ・ | AD31: ・ | AH31: ・ | AJ31: ・ | AK31: 横浜高速 | AL31: ・ | AN31: LAZ101 | AO31: LAY001 | AP31: =COUNTA(AM31,AL31,D31:AJ31) -> 12 | AQ31: LAA101 | AR31: LAF001 | AS31: LAG001 | AT31: LAE101 | AU31: LBL002 | AV31: - | AW31: LAN001 | AX31: LAC001 | AY31: LAD001 | AZ31: オレンジ
A32: 23 | B32: 3245481-4 | C32: VU-LB105 | D32: ・ | E32: ・ | H32: ・ | J32: ・ | N32: ・ | P32: ・ | S32: ・ | W32: ・ | AA32: ・ | AI32: ・ | AJ32: ・ | AL32: ・ | AN32: LAZ002 | AO32: LAY002 | AP32: =COUNTA(AM32,AL32,D32:AJ32) -> 12 | AQ32: LAA101 | AR32: LAF001 | AS32: LAG001 | AT32: LAE101 | AU32: LBL002 | AV32: - | AW32: LAN001 | AX32: LAC001 | AY32: LAD001 | AZ32: 青
A33: 24 | B33: 9707599-3 | C33: VU-LB106 | D33: ・ | E33: ・ | H33: ・ | J33: ・ | N33: ・ | P33: ・ | S33: ・ | W33: ・ | AD33: ・ | AH33: ・ | AJ33: ・ | AK33: 南海 | AL33: ・ | AN33: LAZ101 | AO33: LAY001 | AP33: =COUNTA(AM33,AL33,D33:AJ33) -> 12 | AQ33: LAA101 | AR33: LAF001 | AS33: LAG001 | AT33: LAE101 | AU33: LBL002 | AV33: - | AW33: LAN001 | AX33: LAC001 | AY33: LAD001 | AZ33: オレンジ
A34: 25 | B34: 2802778-2 | C34: VU-LB107 | D34: ・ | E34: ・ | H34: ・ | J34: ・ | N34: ・ | P34: ・ | S34: ・ | W34: ・ | AD34: ・ | AH34: ・ | AJ34: ・ | AK34: 東急 | AL34: ・ | AN34: LAZ101 | AO34: LAY001 | AP34: =COUNTA(AM34,AL34,D34:AJ34) -> 12 | AQ34: LAA101 | AR34: LAF001 | AS34: LAG001 | AT34: LAE101 | AU34: LBL002 | AV34: - | AW34: LAN001 | AX34: LAC001 | AY34: LAD001 | AZ34: オレンジ
A35: 26 | B35: 3137714-0 | C35: VU-LB108 | D35: ・ | E35: ・ | H35: ・ | J35: ・ | N35: ・ | P35: ・ | S35: ・ | W35: ・ | AD35: ・ | AH35: ・ | AJ35: ・ | AK35: つくばV8ﾁｬｰｼﾞ | AL35: ・ | AN35: LAZ101 | AO35: LAY001 | AP35: =COUNTA(AM35,AL35,D35:AJ35) -> 12 | AQ35: LAA101 | AR35: LAF001 | AS35: LAG001 | AT35: LAE101 | AU35: LBL002 | AV35: - | AW35: LAN001 | AX35: LAC001 | AY35: LAD001 | AZ35: オレンジ
A36: 27 | B36: 3138506-1 | C36: VU-LB109 | D36: ・ | E36: ・ | H36: ・ | J36: ・ | N36: ・ | P36: ・ | S36: ・ | W36: ・ | AD36: ・ | AH36: ・ | AJ36: ・ | AK36: 東武 V8ﾏﾙﾁ | AL36: ・ | AN36: LAZ101 | AO36: LAY001 | AP36: =COUNTA(AM36,AL36,D36:AJ36) -> 12 | AQ36: LAA101 | AR36: LAF001 | AS36: LAG001 | AT36: LAE101 | AU36: LBL002 | AV36: - | AW36: LAN001 | AX36: LAC001 | AY36: LAD001 | AZ36: オレンジ
A37: 28 | B37: 3139405-2 | C37: VU-LB110 | D37: ・ | G37: ・ | H37: ・ | J37: ・ | N37: ・ | Q37: ・ | T37: ・ | X37: ・ | AF37: ・ | AH37: ・ | AJ37: ・ | AK37: M社Ｔ （東京ﾒﾄﾛ） | AL37: ・ | AN37: LAZ103 | AO37: LAY001 | AP37: =COUNTA(AM37,AL37,D37:AJ37) -> 12 | AQ37: LAA101 | AR37: LAF003 | AS37: LAG001 | AT37: LAE101 | AU37: LBL002 | AV37: - | AW37: LAN002 | AX37: LAC002 | AY37: LAD002 | AZ37: 紺（白字）
A38: 29 | B38: 3283267-3 | C38: VU-LB111 | D38: ・ | G38: ・ | H38: ・ | J38: ・ | N38: ・ | Q38: ・ | T38: ・ | X38: ・ | AF38: ・ | AH38: ・ | AJ38: ・ | AK38: 東京 ﾒﾄﾛ | AL38: ・ | AN38: LAZ103 | AO38: LAY001 | AP38: =COUNTA(AM38,AL38,D38:AJ38) -> 12 | AQ38: LAA101 | AR38: LAF003 | AS38: LAG001 | AT38: LAE101 | AU38: LBL002 | AV38: - | AW38: LAN002 | AX38: LAC002 | AY38: LAD002 | AZ38: 紺（白字）
A39: 30 | B39: 2875841-8 | C39: VU-LB112 | D39: ・ | E39: ・ | H39: ・ | K39: ・ | N39: ・ | P39: ・ | S39: ・ | W39: ・ | AE39: ・ | AH39: ・ | AJ39: ・ | AK39: JR西 | AL39: ・ | AN39: LAZ102 | AO39: LAY001 | AP39: =COUNTA(AM39,AL39,D39:AJ39) -> 12 | AQ39: LAA101 | AR39: LAF001 | AS39: LAG001 | AT39: LAE102 | AU39: LBL002 | AV39: - | AW39: LAN001 | AX39: LAC001 | AY39: LAD001 | AZ39: 黄
A40: 31 | B40: 1876274-3 | C40: VU-LC001 | D40: ・ | E40: ・ | H40: ・ | J40: ・ | O40: ・ | R40: ・ | U40: ・ | Y40: ・ | AD40: ・ | AH40: ・ | AJ40: ・ | AK40: 試作 | AL40: ・ | AN40: LAZ101 | AO40: LAY001 | AP40: =COUNTA(AM40,AL40,D40:AJ40) -> 12 | AQ40: LAA101 | AR40: LAF001 | AS40: LAG001 | AT40: LAE101 | AU40: - | AV40: LAL001 | AW40: LCN001 | AX40: LCC001 | AY40: LCD001 | AZ40: オレンジ
...

Sheet V9星取表日程マスター
A1: Ｖ９-BH（星取表） | H1: ａ | K1: b | L1: b-任意 (光真ｶﾚ） | M1: ａ (OCｶﾚ） | O1: （計算式）
F2: YB-LA001 | K2: 45077 | L2: =INDEX(光真稼働日早見表!M:M,MATCH(K2,光真稼働日早見表!B:B,0),1) -> 45071 | M2: =I2 -> 0 | O2: =VLOOKUP($F2,Ｖ９structure!$C$8:$P$9,2,FALSE) -> ・ | P2: =VLOOKUP($F2,Ｖ９structure!$C$8:$P$9,3,FALSE) -> ・ | Q2: =VLOOKUP($F2,Ｖ９structure!$C$8:$P$9,4,FALSE) -> ・ | R2: =VLOOKUP($F2,Ｖ９structure!$C$8:$P$9,5,FALSE) -> ・ | S2: =VLOOKUP($F2,Ｖ９structure!$C$8:$P$9,6,FALSE) -> ・ | T2: =VLOOKUP($F2,Ｖ９structure!$C$8:$P$9,7,FALSE) -> ・ | U2: =VLOOKUP($F2,Ｖ９structure!$C$8:$P$9,8,FALSE) -> ・ | V2: =VLOOKUP($F2,Ｖ９structure!$C$8:$P$9,9,FALSE) -> ・ | W2: =VLOOKUP($F2,Ｖ９structure!$C$8:$P$9,10,FALSE) -> ・ | X2: =VLOOKUP($F2,Ｖ９structure!$C$8:$P$9,11,FALSE) -> ・ | Y2: =VLOOKUP($F2,Ｖ９structure!$C$8:$P$9,12,FALSE) -> 0 | Z2: =VLOOKUP($F2,Ｖ９structure!$C$8:$P$9,13,FALSE) -> ・
A4: T-No | B4: Z001 号機 | C4: Z002 号機 | D4: Y001 号機 | E4: Y002 号機 | F4: ＢＨ型式 | G4: 順序 確定日 | H4: 光真 順序 出荷日 | I4: 実出荷 | J4: KP-No | K4: LAZ 完了 計画 | L4: KMP ユニット 日本着日 | M4: 光真 出荷計画 | N4: メンテ | O4: YBS-LAA001 | P4: YBS-LAF001 | Q4: YBS-LAG001 | R4: YBS-LAE001 | S4: YBS-LAL001 | T4: YBS-LAN001 | U4: YBS-LAC001 | V4: YBS-LAD001 | W4: YBS-LAH001 | X4: YBS-LAY001 | Y4: YBS-LAY002 | Z4: YBS-LAZ001 | AA4: 生産 計画 No | AB4: 客先名 | AC4: 駅名 ﾒﾝﾃﾕﾆｯﾄ型式（個/ﾛｯﾄ） | AD4: コーナー メンテ：情報提供者 （情報入手日） | AE4: ﾕﾆｯﾄ 種類数
A5: 1442 | C5: 583 | E5: 530 | F5: YB-LA002 | G5: 46008 | H5: 46027 | J5: ・ | K5: =IFERROR(INDEX('[6]Ｖ９－BH出荷・完了計画'!$B:$B,MATCH(A5,'[6]Ｖ９－BH出荷・完了計画'!$M:$M,0),1),K6) -> 46009 | L5: =INDEX([5]光真稼働日早見表!$M$3:$M$10000,MATCH($K5,[5]光真稼働日早見表!$Q$3:$Q$10000,0),1) -> 46003 | M5: 46027 | O5: ・ | P5: ・ | Q5: ・ | R5: ・ | S5: ・ | T5: ・ | U5: ・ | V5: ・ | Y5: ・ | Z5: ・ | AA5: 000391786 | AB5: JRS | AD5: YB-LA002 | AE5: =COUNTIFS(O5:Z5,"・") -> 10
A6: 1443 | C6: 584 | E6: 531 | F6: YB-LA002 | G6: 46008 | H6: 46027 | J6: ・ | K6: =IFERROR(INDEX('[6]Ｖ９－BH出荷・完了計画'!$B:$B,MATCH(A6,'[6]Ｖ９－BH出荷・完了計画'!$M:$M,0),1),K7) -> 46010 | L6: =INDEX([5]光真稼働日早見表!$M$3:$M$10000,MATCH($K6,[5]光真稼働日早見表!$Q$3:$Q$10000,0),1) -> 46006 | M6: 46027 | O6: ・ | P6: ・ | Q6: ・ | R6: ・ | S6: ・ | T6: ・ | U6: ・ | V6: ・ | Y6: ・ | Z6: ・ | AA6: 000391788 | AB6: JRS | AD6: YB-LA002 | AE6: =COUNTIFS(O6:Z6,"・") -> 10
A7: 1444 | C7: 585 | E7: 532 | F7: YB-LA002 | G7: 46008 | H7: 46027 | J7: ・ | K7: =IFERROR(INDEX('[6]Ｖ９－BH出荷・完了計画'!$B:$B,MATCH(A7,'[6]Ｖ９－BH出荷・完了計画'!$M:$M,0),1),K8) -> 46010 | L7: =INDEX([5]光真稼働日早見表!$M$3:$M$10000,MATCH($K7,[5]光真稼働日早見表!$Q$3:$Q$10000,0),1) -> 46006 | M7: 46027 | O7: ・ | P7: ・ | Q7: ・ | R7: ・ | S7: ・ | T7: ・ | U7: ・ | V7: ・ | Y7: ・ | Z7: ・ | AA7: 000391787 | AB7: JRS | AD7: YB-LA002 | AE7: =COUNTIFS(O7:Z7,"・") -> 10
A8: 1445 | B8: 863 | D8: 916 | F8: YB-LA001 | G8: 46008 | H8: 46027 | J8: ・ | K8: =IFERROR(INDEX('[6]Ｖ９－BH出荷・完了計画'!$B:$B,MATCH(A8,'[6]Ｖ９－BH出荷・完了計画'!$M:$M,0),1),K9) -> 46010 | L8: =INDEX([5]光真稼働日早見表!$M$3:$M$10000,MATCH($K8,[5]光真稼働日早見表!$Q$3:$Q$10000,0),1) -> 46006 | M8: 46027 | O8: ・ | P8: ・ | Q8: ・ | R8: ・ | S8: ・ | T8: ・ | U8: ・ | V8: ・ | W8: ・ | X8: ・ | Z8: ・ | AA8: 000382813 | AB8: つくば | AC8: 台東試験場 | AD8: 秋葉原(本屋) | AE8: =COUNTIFS(O8:Z8,"・") -> 11
A9: 1446 | C9: 586 | E9: 533 | F9: YB-LA002 | G9: 46009 | H9: 46028 | J9: ・ | K9: =IFERROR(INDEX('[6]Ｖ９－BH出荷・完了計画'!$B:$B,MATCH(A9,'[6]Ｖ９－BH出荷・完了計画'!$M:$M,0),1),K10) -> 46010 | L9: =INDEX([5]光真稼働日早見表!$M$3:$M$10000,MATCH($K9,[5]光真稼働日早見表!$Q$3:$Q$10000,0),1) -> 46006 | M9: 46028 | O9: ・ | P9: ・ | Q9: ・ | R9: ・ | S9: ・ | T9: ・ | U9: ・ | V9: ・ | Y9: ・ | Z9: ・ | AA9: 000393970 | AB9: JRS | AD9: YB-LA002 | AE9: =COUNTIFS(O9:Z9,"・") -> 10
A10: 1447 | C10: 587 | E10: 534 | F10: YB-LA002 | G10: 46009 | H10: 46028 | J10: ・ | K10: =IFERROR(INDEX('[6]Ｖ９－BH出荷・完了計画'!$B:$B,MATCH(A10,'[6]Ｖ９－BH出荷・完了計画'!$M:$M,0),1),K11) -> 46027 | L10: =INDEX([5]光真稼働日早見表!$M$3:$M$10000,MATCH($K10,[5]光真稼働日早見表!$Q$3:$Q$10000,0),1) -> 46014 | M10: 46028 | O10: ・ | P10: ・ | Q10: ・ | R10: ・ | S10: ・ | T10: ・ | U10: ・ | V10: ・ | Y10: ・ | Z10: ・ | AA10: 000393978 | AB10: JRS | AD10: YB-LA002 | AE10: =COUNTIFS(O10:Z10,"・") -> 10
A11: 1448 | C11: 588 | E11: 535 | F11: YB-LA002 | G11: 46009 | H11: 46028 | J11: ・ | K11: =IFERROR(INDEX('[6]Ｖ９－BH出荷・完了計画'!$B:$B,MATCH(A11,'[6]Ｖ９－BH出荷・完了計画'!$M:$M,0),1),K12) -> 46027 | L11: =INDEX([5]光真稼働日早見表!$M$3:$M$10000,MATCH($K11,[5]光真稼働日早見表!$Q$3:$Q$10000,0),1) -> 46014 | M11: 46028 | O11: ・ | P11: ・ | Q11: ・ | R11: ・ | S11: ・ | T11: ・ | U11: ・ | V11: ・ | Y11: ・ | Z11: ・ | AA11: 000393968 | AB11: JRS | AD11: YB-LA002 | AE11: =COUNTIFS(O11:Z11,"・") -> 10
A12: 1449 | C12: 589 | E12: 536 | F12: YB-LA002 | G12: 46009 | H12: 46028 | J12: ・ | K12: =IFERROR(INDEX('[6]Ｖ９－BH出荷・完了計画'!$B:$B,MATCH(A12,'[6]Ｖ９－BH出荷・完了計画'!$M:$M,0),1),K13) -> 46027 | L12: =INDEX([5]光真稼働日早見表!$M$3:$M$10000,MATCH($K12,[5]光真稼働日早見表!$Q$3:$Q$10000,0),1) -> 46014 | M12: 46028 | O12: ・ | P12: ・ | Q12: ・ | R12: ・ | S12: ・ | T12: ・ | U12: ・ | V12: ・ | Y12: ・ | Z12: ・ | AA12: 000371222 | AB12: JRS | AD12: YB-LA002 | AE12: =COUNTIFS(O12:Z12,"・") -> 10
A13: 1450 | C13: 590 | E13: 537 | F13: YB-LA002 | G13: 46010 | H13: 46029 | J13: ・ | K13: =IFERROR(INDEX('[6]Ｖ９－BH出荷・完了計画'!$B:$B,MATCH(A13,'[6]Ｖ９－BH出荷・完了計画'!$M:$M,0),1),K14) -> 46027 | L13: =INDEX([5]光真稼働日早見表!$M$3:$M$10000,MATCH($K13,[5]光真稼働日早見表!$Q$3:$Q$10000,0),1) -> 46014 | M13: 46029 | O13: ・ | P13: ・ | Q13: ・ | R13: ・ | S13: ・ | T13: ・ | U13: ・ | V13: ・ | Y13: ・ | Z13: ・ | AA13: 000393973 | AB13: JRS | AD13: YB-LA002 | AE13: =COUNTIFS(O13:Z13,"・") -> 10
A14: 1451 | C14: 591 | E14: 538 | F14: YB-LA002 | G14: 46010 | H14: 46029 | J14: ・ | K14: =IFERROR(INDEX('[6]Ｖ９－BH出荷・完了計画'!$B:$B,MATCH(A14,'[6]Ｖ９－BH出荷・完了計画'!$M:$M,0),1),K15) -> 46028 | L14: =INDEX([5]光真稼働日早見表!$M$3:$M$10000,MATCH($K14,[5]光真稼働日早見表!$Q$3:$Q$10000,0),1) -> 46015 | M14: 46029 | O14: ・ | P14: ・ | Q14: ・ | R14: ・ | S14: ・ | T14: ・ | U14: ・ | V14: ・ | Y14: ・ | Z14: ・ | AA14: 000393969 | AB14: JRS | AD14: YB-LA002 | AE14: =COUNTIFS(O14:Z14,"・") -> 10
A15: 1452 | C15: 592 | E15: 539 | F15: YB-LA002 | G15: 46010 | H15: 46029 | J15: ・ | K15: =IFERROR(INDEX('[6]Ｖ９－BH出荷・完了計画'!$B:$B,MATCH(A15,'[6]Ｖ９－BH出荷・完了計画'!$M:$M,0),1),K16) -> 46028 | L15: =INDEX([5]光真稼働日早見表!$M$3:$M$10000,MATCH($K15,[5]光真稼働日早見表!$Q$3:$Q$10000,0),1) -> 46015 | M15: 46029 | O15: ・ | P15: ・ | Q15: ・ | R15: ・ | S15: ・ | T15: ・ | U15: ・ | V15: ・ | Y15: ・ | Z15: ・ | AA15: 000393977 | AB15: JRS | AD15: YB-LA002 | AE15: =COUNTIFS(O15:Z15,"・") -> 10
A16: 1453 | C16: 593 | E16: 540 | F16: YB-LA002 | G16: 46010 | H16: 46029 | J16: ・ | K16: =IFERROR(INDEX('[6]Ｖ９－BH出荷・完了計画'!$B:$B,MATCH(A16,'[6]Ｖ９－BH出荷・完了計画'!$M:$M,0),1),K17) -> 46028 | L16: =INDEX([5]光真稼働日早見表!$M$3:$M$10000,MATCH($K16,[5]光真稼働日早見表!$Q$3:$Q$10000,0),1) -> 46015 | M16: 46029 | O16: ・ | P16: ・ | Q16: ・ | R16: ・ | S16: ・ | T16: ・ | U16: ・ | V16: ・ | Y16: ・ | Z16: ・ | AA16: 000393975 | AB16: JRS | AD16: YB-LA002 | AE16: =COUNTIFS(O16:Z16,"・") -> 10
A17: 1454 | B17: 864 | D17: 917 | F17: YB-LA001 | G17: 46010 | H17: 46029 | J17: ・ | K17: =IFERROR(INDEX('[6]Ｖ９－BH出荷・完了計画'!$B:$B,MATCH(A17,'[6]Ｖ９－BH出荷・完了計画'!$M:$M,0),1),K18) -> 46028 | L17: =INDEX([5]光真稼働日早見表!$M$3:$M$10000,MATCH($K17,[5]光真稼働日早見表!$Q$3:$Q$10000,0),1) -> 46015 | M17: 46029 | O17: ・ | P17: ・ | Q17: ・ | R17: ・ | S17: ・ | T17: ・ | U17: ・ | V17: ・ | W17: ・ | X17: ・ | Z17: ・ | AA17: 000371421 | AB17: 小田急 | AC17: 海老名 | AE17: =COUNTIFS(O17:Z17,"・") -> 11
A18: 1455 | B18: 865 | D18: 918 | F18: YB-LA001 | G18: 46010 | H18: 46029 | J18: ・ | K18: =IFERROR(INDEX('[6]Ｖ９－BH出荷・完了計画'!$B:$B,MATCH(A18,'[6]Ｖ９－BH出荷・完了計画'!$M:$M,0),1),K19) -> 46028 | L18: =INDEX([5]光真稼働日早見表!$M$3:$M$10000,MATCH($K18,[5]光真稼働日早見表!$Q$3:$Q$10000,0),1) -> 46015 | M18: 46029 | O18: ・ | P18: ・ | Q18: ・ | R18: ・ | S18: ・ | T18: ・ | U18: ・ | V18: ・ | W18: ・ | X18: ・ | Z18: ・ | AA18: 000386085 | AB18: 小田急 | AC18: 喜多見研修センター | AE18: =COUNTIFS(O18:Z18,"・") -> 11
A19: 1456 | C19: 594 | E19: 541 | F19: YB-LA002 | G19: 46013 | H19: 46030 | J19: ・ | K19: =IFERROR(INDEX('[6]Ｖ９－BH出荷・完了計画'!$B:$B,MATCH(A19,'[6]Ｖ９－BH出荷・完了計画'!$M:$M,0),1),K20) -> 46029 | L19: =INDEX([5]光真稼働日早見表!$M$3:$M$10000,MATCH($K19,[5]光真稼働日早見表!$Q$3:$Q$10000,0),1) -> 46016 | M19: 46030 | O19: ・ | P19: ・ | Q19: ・ | R19: ・ | S19: ・ | T19: ・ | U19: ・ | V19: ・ | Y19: ・ | Z19: ・ | AA19: 000393979 | AB19: JRS | AD19: YB-LA002 | AE19: =COUNTIFS(O19:Z19,"・") -> 10
A20: 1457 | C20: 595 | E20: 542 | F20: YB-LA002 | G20: 46013 | H20: 46030 | J20: ・ | K20: =IFERROR(INDEX('[6]Ｖ９－BH出荷・完了計画'!$B:$B,MATCH(A20,'[6]Ｖ９－BH出荷・完了計画'!$M:$M,0),1),K21) -> 46029 | L20: =INDEX([5]光真稼働日早見表!$M$3:$M$10000,MATCH($K20,[5]光真稼働日早見表!$Q$3:$Q$10000,0),1) -> 46016 | M20: 46030 | O20: ・ | P20: ・ | Q20: ・ | R20: ・ | S20: ・ | T20: ・ | U20: ・ | V20: ・ | Y20: ・ | Z20: ・ | AA20: 000393974 | AB20: JRS | AD20: YB-LA002 | AE20: =COUNTIFS(O20:Z20,"・") -> 10
