Workbook
Name __DAT1: #REF!
Name __DAT1: #REF!
Name __DAT1: #REF!
Name __DAT10: #REF!
Name __DAT10: #REF!
Name __DAT10: #REF!
Name __DAT11: #REF!
Name __DAT11: #REF!
Name __DAT11: #REF!
Name __DAT12: #REF!
Name __DAT12: #REF!
Name __DAT12: #REF!
Name __DAT2: #REF!
Name __DAT2: #REF!
Name __DAT2: #REF!
Name __DAT3: #REF!
Name __DAT3: #REF!
Name __DAT3: #REF!
Name __DAT4: #REF!
Name __DAT4: #REF!
Name __DAT4: #REF!
Name __DAT5: #REF!
Name __DAT5: #REF!
Name __DAT5: #REF!
Name __DAT6: #REF!
Name __DAT6: #REF!
Name __DAT6: #REF!
Name __DAT7: #REF!
Name __DAT7: #REF!
Name __DAT7: #REF!
Name __DAT8: #REF!
Name __DAT8: #REF!
Name __DAT8: #REF!
Name __DAT9: #REF!
Name __DAT9: #REF!
Name __DAT9: #REF!
Name _DAT1: #REF!
Name _DAT1: #REF!
Name _DAT1: #REF!
Name _DAT10: #REF!
Name _DAT10: #REF!
Name _DAT10: #REF!
Name _DAT11: #REF!
Name _DAT11: #REF!
Name _DAT11: #REF!
Name _DAT12: #REF!
Name _DAT12: #REF!
Name _DAT12: #REF!
Name _DAT2: #REF!
Name _DAT2: #REF!
Name _DAT2: #REF!
Name _DAT3: #REF!
Name _DAT3: #REF!
Name _DAT3: #REF!
Name _DAT4: #REF!
Name _DAT4: #REF!
Name _DAT4: #REF!
Name _DAT5: #REF!
Name _DAT5: #REF!
Name _DAT5: #REF!

Sheet 0110集計
A1: 1/10集計 ＯＳＳ様 ＢＨ出荷計画情報（25年度ボギー集計） | N1: 注：T-No＝V8累計台数+ 13台（破損機）
H2: Ｖ８(VUS-) | P2: V９（ | Q2: YBS-）
B3: 光真ss 出荷月 | C3: LAZ901 LA001～4 LC001 | D3: LAZ001 LB001 LB003～5 LD001 | E3: LAZ002 LA007,9,10 LB002,6 LB105 LC002 LD003 | F3: LAZ003 LD002 LD002(H) | G3: LAZ004 LD004 | H3: LAZ101 LA001～6､8 LA011,012 LB001,3～5 LB101,3,4,6～9 LB112 LC001,LD001 | I3: LAZ102 LB102 LB112 | J3: LAZ103 ＬＢ110 ＬＢ111 | K3: LAZ201 LC091 LD091 LD092 | L3: Ｖ８ 合計 | M3: Ｖ８ 累計 | N3: LAY 001 | O3: LAY 002 | P3: LAZ001 LAZ002 | Q3: Ｖ９ 累計 | R3: ＢＨ合計 | S3: VU-LA004 | T3: VU-LA007 | U3: VU-LA012 | V3: VU-LB002 | W3: VU-LB006 | X3: VU-LB101 | Y3: VU-LB102 | Z3: VU-LB106 | AA3: VU-LB112 | AB3: VU-LC002 | AC3: VU-LD091 | AD3: YB-LA001 | AE3: YB-LA002
A4: 10年度 | B4: ５月 | C4: 3 | D4: 3 | L4: 6 | M4: 6 | N4: 6 | O4: 0 | R4: =L4+P4 -> 6
B5: ６月 | C5: 0 | D5: 51 | L5: 51 | M5: 57 | N5: 51 | O5: 0 | R5: =L5+P5 -> 51
B6: ７月 | C6: 7 | D6: 65 | L6: 72 | M6: 129 | N6: 72 | O6: 0 | R6: =L6+P6 -> 72
B7: ８月 | C7: 2 | D7: 69 | L7: 71 | M7: 200 | N7: 71 | O7: 0 | R7: =L7+P7 -> 71
A8: 【Ｖ８】 | B8: ９月 | C8: 76 | D8: 18 | L8: 94 | M8: 294 | N8: 94 | O8: 0 | R8: =L8+P8 -> 94
A9: =SUM(L4:L15) -> 838 | B9: １０月 | C9: 86 | D9: 40 | L9: 126 | M9: 420 | N9: 126 | O9: 0 | R9: =L9+P9 -> 126
B10: １１月 | C10: 101 | D10: 29 | L10: 130 | M10: 550 | N10: 130 | O10: 0 | R10: =L10+P10 -> 130
A11: 【合計】 | B11: １２月 | C11: 106 | D11: 6 | L11: 112 | M11: 662 | N11: 112 | O11: 0 | R11: =L11+P11 -> 112
A12: =A6+A9 -> 838 | B12: 11/１月 | C12: 45 | D12: 42 | L12: 87 | M12: 749 | N12: 87 | O12: 0 | R12: =L12+P12 -> 87
B13: ２月 | C13: 3 | D13: 73 | L13: 76 | M13: 825 | N13: 76 | O13: 0 | R13: =L13+P13 -> 76
B14: ３月 | C14: 0 | D14: 3 | L14: 3 | M14: 828 | N14: 3 | O14: 0 | R14: =L14+P14 -> 3
B15: ４月 | C15: 10 | D15: 0 | L15: 10 | M15: 838 | N15: 10 | O15: 0 | R15: =L15+P15 -> 10
A16: 11年度 | B16: ５月 | C16: 5 | D16: 1 | E16: 0 | L16: 6 | M16: 844 | N16: 6 | O16: 0 | R16: =L16+P16 -> 6
B17: ６月 | C17: 12 | D17: 0 | E17: 0 | L17: 12 | M17: 856 | N17: 12 | O17: 0 | R17: =L17+P17 -> 12
B18: ７月 | C18: 25 | D18: 0 | E18: 0 | L18: 25 | M18: 881 | N18: 25 | O18: 0 | R18: =L18+P18 -> 25
B19: ８月 | C19: 16 | D19: 0 | E19: 0 | L19: 16 | M19: 897 | N19: 16 | O19: 0 | R19: =L19+P19 -> 16
A20: 【Ｖ８】 | B20: ９月 | C20: 31 | D20: 0 | E20: 1 | L20: 32 | M20: 929 | N20: 31 | O20: 1 | R20: =L20+P20 -> 32
A21: =SUM(L16:L27) -> 422 | B21: １０月 | C21: 28 | D21: 8 | E21: 0 | L21: 36 | M21: 965 | N21: 36 | O21: 0 | R21: =L21+P21 -> 36
B22: １１月 | C22: 19 | D22: 46 | E22: 9 | L22: 74 | M22: 1039 | N22: 65 | O22: 9 | R22: =L22+P22 -> 74
A23: 【合計】 | B23: １２月 | C23: 17 | D23: 25 | E23: 15 | L23: 57 | M23: 1096 | N23: 42 | O23: 15 | R23: =L23+P23 -> 57
A24: =A18+A21 -> 422 | B24: 12/１月 | C24: 23 | D24: 40 | E24: 0 | L24: 63 | M24: 1159 | N24: 63 | O24: 0 | R24: =L24+P24 -> 63
B25: ２月 | C25: 7 | D25: 22 | E25: 0 | L25: 29 | M25: 1188 | N25: 29 | O25: 0 | R25: =L25+P25 -> 29
B26: ３月 | C26: 14 | D26: 7 | E26: 0 | L26: 21 | M26: 1209 | N26: 21 | O26: 0 | R26: =L26+P26 -> 21
B27: ４月 | C27: 39 | D27: 12 | E27: 0 | L27: 51 | M27: 1260 | N27: 51 | O27: 0 | R27: =L27+P27 -> 51
A28: １２年度 | B28: ５月 | C28: 23 | D28: 11 | E28: 0 | F28: 0 | H28: 0 | L28: 34 | M28: 1294 | N28: 34 | O28: 0 | R28: =L28+P28 -> 34
B29: ６月 | C29: 46 | D29: 28 | E29: 3 | F29: 0 | H29: 0 | L29: 77 | M29: 1371 | N29: 74 | O29: 3 | R29: =L29+P29 -> 77
B30: ７月 | C30: 15 | D30: 24 | E30: 14 | F30: 0 | H30: 0 | L30: 53 | M30: 1424 | N30: 39 | O30: 14 | R30: =L30+P30 -> 53
B31: ８月 | C31: 0 | D31: 5 | E31: 2 | F31: 0 | H31: 0 | L31: 7 | M31: 1431 | N31: 5 | O31: 2 | R31: =L31+P31 -> 7
A32: 【Ｖ８】 | B32: ９月 | C32: 0 | D32: 4 | E32: 0 | F32: 0 | H32: 0 | L32: 4 | M32: 1435 | N32: 4 | O32: 0 | R32: =L32+P32 -> 4
A33: =SUM(L28:L39) -> 362 | B33: １０月 | C33: 0 | D33: 41 | E33: 3 | F33: 0 | H33: 0 | L33: 44 | M33: 1479 | N33: 41 | O33: 3 | R33: =L33+P33 -> 44
B34: １１月 | C34: 19 | D34: 17 | E34: 4 | F34: 13 | H34: 0 | L34: 53 | M34: 1532 | N34: 49 | O34: 4 | R34: =L34+P34 -> 53
A35: 【合計】 | B35: １２月 | C35: 10 | D35: 20 | E35: 0 | F35: 0 | H35: 27 | L35: 57 | M35: 1589 | N35: 57 | O35: 0 | R35: =L35+P35 -> 57
A36: =A30+A33 -> 362 | B36: 13/1月 | C36: 5 | D36: 22 | E36: 0 | F36: 0 | H36: 0 | L36: 27 | M36: 1616 | N36: 27 | O36: 0 | R36: =L36+P36 -> 27
B37: ２月 | C37: 0 | D37: 0 | E37: 0 | F37: 0 | H37: 0 | L37: 0 | M37: 1616 | N37: 0 | O37: 0 | R37: =L37+P37 -> 0
B38: ３月 | C38: 1 | D38: 4 | E38: 0 | F38: 0 | H38: 1 | L38: 6 | M38: 1622 | N38: 6 | O38: 0 | R38: =L38+P38 -> 6
B39: ４月 | C39: 0 | D39: 0 | E39: 0 | F39: 0 | H39: 0 | I39: 0 | L39: 0 | M39: 1622 | N39: 0 | O39: 0 | R39: =L39+P39 -> 0
A40: １３年度 | B40: ５月 | C40: 0 | D40: 0 | E40: 0 | F40: 34 | H40: 39 | I40: 0 | L40: 73 | M40: 1695 | N40: 73 | O40: 0 | R40: =L40+P40 -> 73
...

Sheet Ｖ８星取表
M1: 1 | N1: 2 | O1: 3 | P1: 4 | Q1: 5 | R1: 6 | S1: 7 | T1: 8 | U1: 9 | V1: 10 | W1: 11 | X1: 12 | Y1: 13 | Z1: 14 | AA1: 15 | AB1: 16 | AC1: 17 | AD1: 18 | AE1: 19 | AF1: 20 | AG1: 21 | AH1: 22 | AI1: 23 | AJ1: 24 | AK1: 25 | AL1: 26 | AM1: 27 | AN1: 28 | AO1: 29 | AP1: 30 | AQ1: 31 | AR1: 32 | AS1: 33 | AT1: 34 | AU1: 35 | AV1: 36 | AW1: 37 | AX1: 38 | AY1: 39 | AZ1: 40 | BA1: 41 | BB1: 42 | BC1: 43 | BD1: 44 | BE1: 45 | BF1: 46 | BG1: 47 | BH1: 48 | BI1: 49 | BJ1: 50
S2: KMP UNITS | AP2: KOUSHIN JAPAN UNITS
P3: =COUNTIF(#REF!,"・") -> #REF! | R3: ・→ | S3: =COUNTIF(S7:S241,"・") -> 31 | T3: =COUNTIF(T7:T241,"・") -> 29 | U3: =COUNTIF(U7:U241,"・") -> 0 | V3: =COUNTIF(V7:V241,"・") -> 0 | W3: =COUNTIF(W7:W241,"・") -> 35 | X3: =COUNTIF(X7:X241,"・") -> 0 | Y3: =COUNTIF(Y7:Y241,"・") -> 8 | Z3: =COUNTIF(Z7:Z241,"・") -> 12 | ... AY3: =COUNTIF(AY7:AY241,"・") -> 79
P4: =COUNTIF(#REF!,"1/13") -> #REF! | S4: 0184429-0 | T4: 1876212-3 | U4: 3249850-1 | V4: 3139386-2 | W4: 1876278-6 | X4: 3729591-9 | Y4: 0184763-0 | Z4: 9064355-4 | AA4: 9912506-8 | AB4: 1876267-0 | AC4: 3729668-0 | AD4: 1876265-4 | AE4: 1876242-5 | AF4: 3139392-7 | AG4: 1876244-1 | AH4: 1868741-5 | AI4: 3139382-0 | AJ4: 1868739-3 | AK4: 5343350-7 | AL4: 1868742-3 | AM4: 3139404-4 | AN4: 1868740-7 | AO4: 5343349-3 | AP4: 1892440-9 | AQ4: 3729514-5 | AR4: 3247289-8 | AS4: 0184427-4 | AT4: 9066030-0 | AU4: 3139406-0 | AV4: 9912561-0 | AW4: 1876275-1 | AX4: 1892439-5 | AY4: 1876277-8
A5: ＊1/10生産計画 | K5: ａ (OCｶﾚ） | N5: b (光真ｶﾚ） | O5: b-4日 (光真ｶﾚ） | P5: ａ-3日 (光真ｶﾚ） | Q5: ａ (OCｶﾚ） | S5: ﾊﾝｿｳﾌﾞ | T5: 5000ｴﾝﾌﾞ | U5: 5000ｴﾝﾌﾞ | V5: 5000ｴﾝﾌﾞ | W5: ﾂﾘｼﾍｲ ﾎﾘﾕｳﾌﾞ | X5: ﾂﾘｼﾍｲ ﾎﾘﾕｳﾌﾞ | Y5: ｿｳﾆﾕｳｳﾌﾞ | Z5: ｿｳﾆﾕｳｳﾌﾞ | AA5: ｿｳﾆﾕｳｳﾌﾞ | AB5: ﾎｷﾕｳﾌﾞ ｺｳﾎｳ | AC5: ﾎｷﾕｳﾌﾞ ｺｳﾎｳ | AD5: ﾀｲﾋﾌﾞ | AE5: ｶｲｼﾕｳﾌﾞ （固定式） | AF5: ｶｲｼﾕｳﾌﾞ （固定式） | AG5: ｶｲｼﾕｳﾌﾞ （可搬式） | AH5: 10000ｴﾝﾌﾞ （固定式） | AI5: 10000ｴﾝﾌﾞ （固定式） | AJ5: 10000ｴﾝﾌﾞ （可搬式） | AK5: 10000ｴﾝﾌﾞ （可搬式） | AL5: 1000ｴﾝ ｶｾﾂﾄﾌﾞ （固定式） | AM5: 1000ｴﾝ ｶｾﾂﾄﾌﾞ （固定式） | AN5: 1000ｴﾝ ｶｾﾂﾄﾌﾞ （可搬式） | AO5: 1000ｴﾝ ｶｾﾂﾄﾌﾞ （可搬式） | AP5: ｷﾎﾝﾌﾞ BH | AQ5: ｷﾎﾝﾌﾞ BH | AR5: ｷﾎﾝﾌﾞ BH | AS5: ｷﾎﾝﾌﾞ BH | AT5: ｷﾎﾝﾌﾞ BH | AU5: ｷﾎﾝﾌﾞ BH | AV5: ｷﾎﾝﾌﾞ BH | AW5: ﾌﾚ-ﾑﾌﾞ | AX5: ﾌﾚ-ﾑﾌﾞ | AY5: ﾚ-ﾙﾌﾞ
A6: T-No （LAY） | B6: Z002 号機 | C6: Z003 号機 | D6: Z004 号機 | E6: Z101 号機 | F6: Z102 号機 | G6: Z103 号機 | H6: Z201 号機 | I6: ＢＨ型式 | J6: 順序 確定日 | K6: 光真 順序 出荷日 | L6: 実出荷 | M6: KP-No | N6: LAZ 完了 計画 | O6: KMP ユニット 日本着日 | P6: KMP ユニット 日本着日 | Q6: LAZ/ｶｾｯﾄ LAL/LBL J-光真 出荷計画 | R6: メンテ | S6: LAA101 | T6: LAF001 | U6: LAF002 | V6: LAF003 | W6: LAG001 | X6: LAG002 | Y6: LAE101 | Z6: LAE102 | AA6: LAE201 | AB6: LBL001 | AC6: LBL002 | AD6: LAL001 | AE6: LAN001 | AF6: LAN002 | AG6: LCN001 | AH6: LAC001 | AI6: LAC002 | AJ6: LCC001 | AK6: LCC002 | AL6: LAD001 | AM6: LAD002 | AN6: LCD001 | AO6: LCD002 | AP6: LAZ002 | AQ6: LAZ003 | AR6: LAZ004 | AS6: LAZ101 | AT6: LAZ102 | AU6: LAZ103 | AV6: LAZ201 | AW6: LAY001 | AX6: LAY002 | AY6: LAH001 | AZ6: 生産 計画 No | BA6: 客先名 | BB6: 駅名 ﾒﾝﾃﾕﾆｯﾄ型式（個/ﾛｯﾄ） | BC6: コーナー メンテ：情報提供者 （情報入手日） | BD6: ﾕﾆｯﾄ 種類数 | BE6: BH型式 | BF6: 出荷日 | BG6: T-No （LAY） | BH6: LAZ ﾕﾆｯﾄ | BI6: 1F 出荷 | BJ6: ﾒﾝﾃﾕﾆｯﾄ 型式 | BK6: 5311189-5 | BL6: 5311167-4
J7: 46001 | K7: 46051 | L7: 46027 | M7: MB-08144 | O7: =INDEX([5]光真稼働日早見表!$M:$M,MATCH($Q7,[5]光真稼働日早見表!$Q:$Q,0),1) -> 46014 | Q7: 46027 | R7: M | W7: 46013 | AZ7: 000396263 | BA7: OFET | BB7: LAG001(6/39) | BC7: （11/5林ひ様情報） | BD7: =COUNTA(S7:AY7) -> 1 | BE7: =I7 -> 0 | BF7: =K7 -> 46051 | BG7: =A7 -> 0 | BH7: =COUNTA(S7:AA7) -> 1 | BI7: =COUNTA(AB7:AO7) -> 0 | BJ7: LAG001
J8: 46001 | K8: 46051 | L8: 46027 | M8: MB-08144 | O8: =INDEX([5]光真稼働日早見表!$M:$M,MATCH($Q8,[5]光真稼働日早見表!$Q:$Q,0),1) -> 46014 | Q8: 46027 | R8: M | W8: 46013 | AZ8: 000396263 | BA8: OFET | BB8: LAG001(7/39) | BC8: （11/5林ひ様情報） | BD8: =COUNTA(S8:AY8) -> 1 | BE8: =I8 -> 0 | BF8: =K8 -> 46051 | BG8: =A8 -> 0 | BH8: =COUNTA(S8:AA8) -> 1 | BI8: =COUNTA(AB8:AO8) -> 0 | BJ8: LAG001
J9: 46001 | K9: 46051 | L9: 46027 | M9: MB-08144 | O9: =INDEX([5]光真稼働日早見表!$M:$M,MATCH($Q9,[5]光真稼働日早見表!$Q:$Q,0),1) -> 46014 | Q9: 46027 | R9: M | W9: 46013 | AZ9: 000396263 | BA9: OFET | BB9: LAG001(8/39) | BC9: （11/5林ひ様情報） | BD9: =COUNTA(S9:AY9) -> 1 | BE9: =I9 -> 0 | BF9: =K9 -> 46051 | BG9: =A9 -> 0 | BH9: =COUNTA(S9:AA9) -> 1 | BI9: =COUNTA(AB9:AO9) -> 0 | BJ9: LAG001
J10: 46001 | K10: 46051 | L10: 46027 | M10: MB-08144 | O10: =INDEX([5]光真稼働日早見表!$M:$M,MATCH($Q10,[5]光真稼働日早見表!$Q:$Q,0),1) -> 46014 | Q10: 46027 | R10: M | W10: 46013 | AZ10: 000396263 | BA10: OFET | BB10: LAG001(9/39) | BC10: （11/5林ひ様情報） | BD10: =COUNTA(S10:AY10) -> 1 | BE10: =I10 -> 0 | BF10: =K10 -> 46051 | BG10: =A10 -> 0 | BH10: =COUNTA(S10:AA10) -> 1 | BI10: =COUNTA(AB10:AO10) -> 0 | BJ10: LAG001
J11: 46001 | K11: 46051 | L11: 46027 | M11: MB-08144 | O11: =INDEX([5]光真稼働日早見表!$M:$M,MATCH($Q11,[5]光真稼働日早見表!$Q:$Q,0),1) -> 46014 | Q11: 46027 | R11: M | W11: 46013 | AZ11: 000396263 | BA11: OFET | BB11: LAG001(10/39) | BC11: （11/5林ひ様情報） | BD11: =COUNTA(S11:AY11) -> 1 | BE11: =I11 -> 0 | BF11: =K11 -> 46051 | BG11: =A11 -> 0 | BH11: =COUNTA(S11:AA11) -> 1 | BI11: =COUNTA(AB11:AO11) -> 0 | BJ11: LAG001
A12: 21326 | E12: 8201 | I12: VU-LB106 | J12: 45995 | K12: 46007 | L12: 46028 | M12: VV-26749 | N12: 46027 | O12: 46000 | P12: 46002 | Q12: 46028 | S12: 45999 | T12: 45999 | W12: 45999 | Y12: 45999 | AC12: 45999 | AE12: 45999 | AH12: 45999 | AL12: 45999 | AS12: ・ | AW12: ・ | AY12: ・ | AZ12: 000377924 | BA12: 南海 | BB12: 新今宮 | BC12: ４F | BD12: 11 | BE12: =I12 -> VU-LB106 | BF12: =K12 -> 46007 | BG12: =A12 -> 21326 | BH12: =COUNTA(S12:AA12) -> 4 | BI12: =COUNTA(AB12:AO12) -> 4
A13: 21327 | B13: 3216 | I13: VU-LA007 | J13: 45996 | K13: 46008 | L13: 46028 | M13: MC-51684 | N13: 46027 | O13: 46000 | P13: 46003 | Q13: 46028 | S13: 45999 | T13: 45999 | W13: 45999 | Y13: 45999 | AD13: 45999 | AE13: 45999 | AH13: 45999 | AL13: 45999 | AP13: ・ | AX13: ・ | AY13: ・ | AZ13: 000391722 | BA13: N社（Ｎ） | BC13: VU-LA007 | BD13: 11 | BE13: =I13 -> VU-LA007 | BF13: =K13 -> 46008 | BG13: =A13 -> 21327 | BH13: =COUNTA(S13:AA13) -> 4 | BI13: =COUNTA(AB13:AO13) -> 4
A14: 21328 | B14: 3217 | I14: VU-LA007 | J14: 45999 | K14: 46009 | L14: 46028 | M14: MC-51692 | N14: 46027 | O14: 46001 | P14: 46006 | Q14: 46028 | S14: 45999 | T14: 45999 | W14: 45999 | Y14: 45999 | AD14: 45999 | AE14: 45999 | AH14: 45999 | AL14: 45999 | AP14: ・ | AX14: ・ | AY14: ・ | AZ14: 000391729 | BA14: N社（Ｎ） | BC14: VU-LA007 | BD14: 11 | BE14: =I14 -> VU-LA007 | BF14: =K14 -> 46009 | BG14: =A14 -> 21328 | BH14: =COUNTA(S14:AA14) -> 4 | BI14: =COUNTA(AB14:AO14) -> 4
A15: 21329 | B15: 3218 | I15: VU-LA007 | J15: 46000 | K15: 46010 | L15: 46028 | M15: MC-51700 | N15: 46027 | O15: 46001 | P15: 46007 | Q15: 46028 | S15: 45999 | T15: 45999 | W15: 45999 | Y15: 45999 | AD15: 45999 | AE15: 45999 | AH15: 45999 | AL15: 45999 | AP15: ・ | AX15: ・ | AY15: ・ | AZ15: 000391724 | BA15: N社（Ｎ） | BC15: VU-LA007 | BD15: 11 | BE15: =I15 -> VU-LA007 | BF15: =K15 -> 46010 | BG15: =A15 -> 21329 | BH15: =COUNTA(S15:AA15) -> 4 | BI15: =COUNTA(AB15:AO15) -> 4
J16: 46001 | K16: 46052 | L16: 46028 | M16: MB-08170 | O16: =INDEX([5]光真稼働日早見表!$M:$M,MATCH($Q16,[5]光真稼働日早見表!$Q:$Q,0),1) -> 46015 | Q16: 46028 | R16: M | W16: 46013 | AZ16: 000396262 | BA16: OFET | BB16: LAG001(11/39) | BC16: （11/5林ひ様情報） | BD16: =COUNTA(S16:AY16) -> 1 | BE16: =I16 -> 0 | BF16: =K16 -> 46052 | BG16: =A16 -> 0 | BH16: =COUNTA(S16:AA16) -> 1 | BI16: =COUNTA(AB16:AO16) -> 0 | BJ16: LAG001
J17: 46001 | K17: 46052 | L17: 46028 | M17: MB-08170 | O17: =INDEX([5]光真稼働日早見表!$M:$M,MATCH($Q17,[5]光真稼働日早見表!$Q:$Q,0),1) -> 46015 | Q17: 46028 | R17: M | W17: 46013 | AZ17: 000396262 | BA17: OFET | BB17: LAG001(12/39) | BC17: （11/5林ひ様情報） | BD17: =COUNTA(S17:AY17) -> 1 | BE17: =I17 -> 0 | BF17: =K17 -> 46052 | BG17: =A17 -> 0 | BH17: =COUNTA(S17:AA17) -> 1 | BI17: =COUNTA(AB17:AO17) -> 0 | BJ17: LAG001
J18: 46001 | K18: 46052 | L18: 46028 | M18: MB-08170 | O18: =INDEX([5]光真稼働日早見表!$M:$M,MATCH($Q18,[5]光真稼働日早見表!$Q:$Q,0),1) -> 46015 | Q18: 46028 | R18: M | W18: 46013 | AZ18: 000396262 | BA18: OFET | BB18: LAG001(13/39) | BC18: （11/5林ひ様情報） | BD18: =COUNTA(S18:AY18) -> 1 | BE18: =I18 -> 0 | BF18: =K18 -> 46052 | BG18: =A18 -> 0 | BH18: =COUNTA(S18:AA18) -> 1 | BI18: =COUNTA(AB18:AO18) -> 0 | BJ18: LAG001
J19: 46001 | K19: 46052 | L19: 46028 | M19: MB-08170 | O19: =INDEX([5]光真稼働日早見表!$M:$M,MATCH($Q19,[5]光真稼働日早見表!$Q:$Q,0),1) -> 46015 | Q19: 46028 | R19: M | W19: 46013 | AZ19: 000396262 | BA19: OFET | BB19: LAG001(14/39) | BC19: （11/5林ひ様情報） | BD19: =COUNTA(S19:AY19) -> 1 | BE19: =I19 -> 0 | BF19: =K19 -> 46052 | BG19: =A19 -> 0 | BH19: =COUNTA(S19:AA19) -> 1 | BI19: =COUNTA(AB19:AO19) -> 0 | BJ19: LAG001
J20: 46001 | K20: 46052 | L20: 46028 | M20: MB-08170 | O20: =INDEX([5]光真稼働日早見表!$M:$M,MATCH($Q20,[5]光真稼働日早見表!$Q:$Q,0),1) -> 46015 | Q20: 46028 | R20: M | W20: 46013 | AZ20: 000396262 | BA20: OFET | BB20: LAG001(15/39) | BC20: （11/5林ひ様情報） | BD20: =COUNTA(S20:AY20) -> 1 | BE20: =I20 -> 0 | BF20: =K20 -> 46052 | BG20: =A20 -> 0 | BH20: =COUNTA(S20:AA20) -> 1 | BI20: =COUNTA(AB20:AO20) -> 0 | BJ20: LAG001
A21: 21330 | E21: 8202 | I21: VU-LA012 | J21: 46000 | K21: 46010 | L21: 46029 | M21: VV-26755 | N21: 46028 | O21: 46002 | P21: 46007 | Q21: 46029 | S21: 45999 | T21: 45999 | W21: 45999 | Y21: 45999 | AD21: 45999 | AE21: 45999 | AH21: 45999 | AL21: 45999 | AS21: ・ | AW21: ・ | AY21: ・ | AZ21: 000378623 | BA21: 小田急 | BB21: 本鵠沼 | BC21: 西口 | BD21: 11 | BE21: =I21 -> VU-LA012 | BF21: =K21 -> 46010 | BG21: =A21 -> 21330 | BH21: =COUNTA(S21:AA21) -> 4 | BI21: =COUNTA(AB21:AO21) -> 4
A22: 21331 | E22: 8203 | I22: VU-LB106 | J22: 46002 | K22: 46014 | L22: 46029 | M22: VV-26760 | N22: 46028 | O22: 46002 | P22: 46009 | Q22: 46029 | S22: 45999 | T22: 45999 | W22: 45999 | Y22: 45999 | AC22: 45999 | AE22: 45999 | AH22: 45999 | AL22: 45999 | AS22: ・ | AW22: ・ | AY22: ・ | AZ22: 000377925 | BA22: 南海 | BB22: 天下茶屋 | BD22: 11 | BE22: =I22 -> VU-LB106 | BF22: =K22 -> 46014 | BG22: =A22 -> 21331 | BH22: =COUNTA(S22:AA22) -> 4 | BI22: =COUNTA(AB22:AO22) -> 4
A23: 21332 | E23: 8204 | I23: VU-LB106 | J23: 46003 | K23: 46015 | L23: 46029 | M23: VV-26763 | N23: 46028 | O23: 46003 | P23: 46010 | Q23: 46029 | S23: 45999 | T23: 45999 | W23: 45999 | Y23: 45999 | AC23: 45999 | AE23: 45999 | AH23: 45999 | AL23: 45999 | AS23: ・ | AW23: ・ | AY23: ・ | AZ23: 000381123 | BA23: 南海 | BB23: 萩ノ茶屋 | BD23: 11 | BE23: =I23 -> VU-LB106 | BF23: =K23 -> 46015 | BG23: =A23 -> 21332 | BH23: =COUNTA(S23:AA23) -> 4 | BI23: =COUNTA(AB23:AO23) -> 4
A24: 21333 | E24: 8205 | I24: VU-LB106 | J24: 46003 | K24: 46015 | L24: 46029 | M24: VV-26764 | N24: 46028 | O24: 46003 | P24: 46010 | Q24: 46029 | S24: 45999 | T24: 45999 | W24: 45999 | Y24: 45999 | AC24: 45999 | AE24: 45999 | AH24: 45999 | AL24: 45999 | AS24: ・ | AW24: ・ | AY24: ・ | AZ24: 000381124 | BA24: 南海 | BB24: 粉浜 | BD24: 11 | BE24: =I24 -> VU-LB106 | BF24: =K24 -> 46015 | BG24: =A24 -> 21333 | BH24: =COUNTA(S24:AA24) -> 4 | BI24: =COUNTA(AB24:AO24) -> 4
A25: 21334 | H25: 3524 | I25: VU-LD091 | J25: 46008 | K25: 46027 | L25: 46030 | M25: VV-26775 | N25: 46029 | O25: 46006 | P25: 46015 | Q25: 46030 | S25: 45999 | T25: 45999 | W25: 45999 | AA25: 45999 | AC25: 45999 | AG25: 45999 | AK25: 45999 | AO25: 45999 | AV25: ・ | AW25: ・ | AY25: ・ | AZ25: 000385490 | BA25: 設計設備 | BD25: 11 | BE25: =I25 -> VU-LD091 | BF25: =K25 -> 46027 | BG25: =A25 -> 21334 | BH25: =COUNTA(S25:AA25) -> 4 | BI25: =COUNTA(AB25:AO25) -> 4
A26: 21335 | H26: 3525 | I26: VU-LD091 | J26: 46009 | K26: 46028 | L26: 46030 | M26: VV-26777 | N26: 46029 | O26: 46014 | P26: 46016 | Q26: 46030 | S26: 45999 | T26: 45999 | W26: 45999 | AA26: 45999 | AC26: 45999 | AG26: 45999 | AK26: 45999 | AO26: 45999 | AV26: ・ | AW26: ・ | AY26: ・ | AZ26: 000393963 | BA26: 設計設備 | BD26: 11 | BE26: =I26 -> VU-LD091 | BF26: =K26 -> 46028 | BG26: =A26 -> 21335 | BH26: =COUNTA(S26:AA26) -> 4 | BI26: =COUNTA(AB26:AO26) -> 4
A27: 21336 | H27: 3526 | I27: VU-LD091 | J27: 46013 | K27: 46030 | L27: 46030 | M27: VV-26782 | N27: 46029 | O27: 46014 | P27: 46027 | Q27: 46030 | S27: 45999 | T27: 45999 | W27: 45999 | AA27: 45999 | AC27: 45999 | AG27: 45999 | AK27: 45999 | AO27: 45999 | AV27: ・ | AW27: ・ | AY27: ・ | AZ27: 000393965 | BA27: JREM | BD27: 11 | BE27: =I27 -> VU-LD091 | BF27: =K27 -> 46030 | BG27: =A27 -> 21336 | BH27: =COUNTA(S27:AA27) -> 4 | BI27: =COUNTA(AB27:AO27) -> 4
A28: 21337 | H28: 3527 | I28: VU-LD091 | J28: 46013 | K28: 46030 | L28: 46030 | M28: VV-26783 | N28: 46029 | O28: 46015 | P28: 46027 | Q28: 46030 | S28: 45999 | T28: 45999 | W28: 45999 | AA28: 45999 | AC28: 46013 | AG28: 46013 | AK28: 46013 | AO28: 46013 | AV28: ・ | AW28: ・ | AY28: ・ | AZ28: 000393967 | BA28: JREM | BD28: 11 | BE28: =I28 -> VU-LD091 | BF28: =K28 -> 46030 | BG28: =A28 -> 21337 | BH28: =COUNTA(S28:AA28) -> 4 | BI28: =COUNTA(AB28:AO28) -> 4
A29: 21338 | H29: 3528 | I29: VU-LD091 | J29: 46014 | K29: 46031 | L29: 46031 | M29: VV-26786 | N29: 46030 | O29: 46015 | P29: 46028 | Q29: 46031 | S29: 45999 | T29: 45999 | W29: 45999 | AA29: 45999 | AC29: 46013 | AG29: 46013 | AK29: 46013 | AO29: 46013 | AV29: ・ | AW29: ・ | AY29: ・ | AZ29: 000371187 | BA29: JREM | BD29: 11 | BE29: =I29 -> VU-LD091 | BF29: =K29 -> 46031 | BG29: =A29 -> 21338 | BH29: =COUNTA(S29:AA29) -> 4 | BI29: =COUNTA(AB29:AO29) -> 4
A30: 21339 | H30: 3529 | I30: VU-LD091 | J30: 46014 | K30: 46031 | L30: 46031 | M30: VV-26787 | N30: 46030 | O30: 46016 | P30: 46028 | Q30: 46031 | S30: 45999 | T30: 45999 | W30: 45999 | AA30: 45999 | AC30: 46013 | AG30: 46013 | AK30: 46013 | AO30: 46013 | AV30: ・ | AW30: ・ | AY30: ・ | AZ30: 000393964 | BA30: JREM | BD30: 11 | BE30: =I30 -> VU-LD091 | BF30: =K30 -> 46031 | BG30: =A30 -> 21339 | BH30: =COUNTA(S30:AA30) -> 4 | BI30: =COUNTA(AB30:AO30) -> 4
A31: 21340 | H31: 3530 | I31: VU-LD091 | J31: 46015 | K31: 46035 | L31: 46035 | M31: VV-26790 | N31: 46030 | O31: 46016 | P31: 46029 | Q31: 46035 | S31: 45999 | T31: 45999 | W31: 45999 | AA31: 45999 | AC31: 46013 | AG31: 46013 | AK31: 46013 | AO31: 46013 | AV31: ・ | AW31: ・ | AY31: ・ | AZ31: 000375150 | BA31: JREM | BC31: 仮品番 | BD31: 11 | BE31: =I31 -> VU-LD091 | BF31: =K31 -> 46035 | BG31: =A31 -> 21340 | BH31: =COUNTA(S31:AA31) -> 4 | BI31: =COUNTA(AB31:AO31) -> 4
A32: 21341 | H32: 3531 | I32: VU-LD091 | J32: 46015 | K32: 46035 | L32: 46035 | M32: VV-26791 | N32: 46030 | O32: 46017 | P32: 46029 | Q32: 46035 | S32: 46013 | T32: 46013 | W32: 46013 | AA32: 46013 | AC32: 46013 | AG32: 46013 | AK32: 46013 | AO32: 46013 | AV32: ・ | AW32: ・ | AY32: ・ | AZ32: 000393966 | BA32: JREM | BD32: 11 | BE32: =I32 -> VU-LD091 | BF32: =K32 -> 46035 | BG32: =A32 -> 21341 | BH32: =COUNTA(S32:AA32) -> 4 | BI32: =COUNTA(AB32:AO32) -> 4
A33: 21342 | E33: 8206 | I33: VU-LB106 | J33: 46016 | K33: 46036 | L33: 46036 | M33: VV-26794 | N33: 46031 | O33: 46017 | P33: 46030 | Q33: 46036 | S33: 46013 | T33: 46013 | W33: 46013 | Y33: 46013 | AC33: 46013 | AE33: 46013 | AH33: 46013 | AL33: 46013 | AS33: ・ | AW33: ・ | AY33: ・ | AZ33: 000381125 | BA33: 南海 | BB33: 七道 | BD33: 11 | BE33: =I33 -> VU-LB106 | BF33: =K33 -> 46036 | BG33: =A33 -> 21342 | BH33: =COUNTA(S33:AA33) -> 4 | BI33: =COUNTA(AB33:AO33) -> 4
A34: 21343 | E34: 8207 | I34: VU-LA004 | J34: 46017 | K34: 46037 | L34: 46037 | M34: MC-51868 | N34: 46031 | O34: 46027 | P34: 46031 | Q34: 46037 | S34: 46013 | T34: 46013 | W34: 46013 | Y34: 46013 | AD34: 46013 | AE34: 46013 | AH34: 46013 | AL34: 46013 | AS34: ・ | AW34: ・ | AY34: ・ | AZ34: 000371238 | BA34: M社（Ｎ） | BC34: VU-LA004 | BD34: 11 | BE34: =I34 -> VU-LA004 | BF34: =K34 -> 46037 | BG34: =A34 -> 21343 | BH34: =COUNTA(S34:AA34) -> 4 | BI34: =COUNTA(AB34:AO34) -> 4
A35: 21344 | E35: 8208 | I35: VU-LA004 | J35: 46017 | K35: 46037 | L35: 46037 | M35: MC-51869 | N35: 46031 | O35: 46027 | P35: 46031 | Q35: 46037 | S35: 46013 | T35: 46013 | W35: 46013 | Y35: 46013 | AD35: 46013 | AE35: 46013 | AH35: 46013 | AL35: 46013 | AS35: ・ | AW35: ・ | AY35: ・ | AZ35: 000394016 | BA35: M社（Ｎ） | BC35: VU-LA004 | BD35: 11 | BE35: =I35 -> VU-LA004 | BF35: =K35 -> 46037 | BG35: =A35 -> 21344 | BH35: =COUNTA(S35:AA35) -> 4 | BI35: =COUNTA(AB35:AO35) -> 4
A36: 21345 | B36: 3219 | I36: VU-LA007 | J36: 46017 | K36: 46037 | L36: 46037 | M36: MC-51870 | N36: 46031 | O36: 46027 | P36: 46031 | Q36: 46037 | S36: 46013 | T36: 46013 | W36: 46013 | Y36: 46013 | AD36: 46013 | AE36: 46013 | AH36: 46013 | AL36: 46013 | AP36: ・ | AX36: ・ | AY36: ・ | AZ36: 000384916 | BA36: N社（Ｎ） | BC36: VU-LA007 | BD36: 11 | BE36: =I36 -> VU-LA007 | BF36: =K36 -> 46037 | BG36: =A36 -> 21345 | BH36: =COUNTA(S36:AA36) -> 4 | BI36: =COUNTA(AB36:AO36) -> 4
A37: 21346 | E37: 8209 | I37: VU-LB106 | J37: 46017 | K37: 46037 | L37: 46037 | M37: VV-26797 | N37: 46035 | O37: 46028 | P37: 46031 | Q37: 46037 | S37: 46013 | T37: 46013 | W37: 46013 | Y37: 46013 | AC37: 46013 | AE37: 46013 | AH37: 46013 | AL37: 46013 | AS37: ・ | AW37: ・ | AY37: ・ | AZ37: 000381128 | BA37: 南海 | BB37: 湊 | BD37: 11 | BE37: =I37 -> VU-LB106 | BF37: =K37 -> 46037 | BG37: =A37 -> 21346 | BH37: =COUNTA(S37:AA37) -> 4 | BI37: =COUNTA(AB37:AO37) -> 4
A38: 21347 | E38: 8210 | I38: VU-LA004 | J38: 46027 | K38: 46038 | L38: 46038 | M38: MC-51875 | N38: 46035 | O38: 46028 | P38: 46035 | Q38: 46038 | S38: 46013 | T38: 46013 | W38: 46013 | Y38: 46013 | AD38: 46013 | AE38: 46013 | AH38: 46013 | AL38: 46013 | AS38: ・ | AW38: ・ | AY38: ・ | AZ38: 000394018 | BA38: M社（Ｎ） | BC38: VU-LA004 | BD38: 11 | BE38: =I38 -> VU-LA004 | BF38: =K38 -> 46038 | BG38: =A38 -> 21347 | BH38: =COUNTA(S38:AA38) -> 4 | BI38: =COUNTA(AB38:AO38) -> 4
A39: 21348 | E39: 8211 | I39: VU-LA004 | J39: 46027 | K39: 46038 | L39: 46038 | M39: MC-51876 | N39: 46035 | O39: 46028 | P39: 46035 | Q39: 46038 | S39: 46013 | T39: 46013 | W39: 46013 | Y39: 46013 | AD39: 46013 | AE39: 46013 | AH39: 46013 | AL39: 46013 | AS39: ・ | AW39: ・ | AY39: ・ | AZ39: 000394020 | BA39: M社（Ｎ） | BC39: VU-LA004 | BD39: 11 | BE39: =I39 -> VU-LA004 | BF39: =K39 -> 46038 | BG39: =A39 -> 21348 | BH39: =COUNTA(S39:AA39) -> 4 | BI39: =COUNTA(AB39:AO39) -> 4
A40: 21349 | E40: 8212 | I40: VU-LA004 | J40: 46027 | K40: 46038 | L40: 46038 | M40: MC-51877 | N40: 46036 | O40: 46029 | P40: 46035 | Q40: 46038 | S40: 46013 | T40: 46013 | W40: 46013 | Y40: 46013 | AD40: 46013 | AE40: 46013 | AH40: 46013 | AL40: 46013 | AS40: ・ | AW40: ・ | AY40: ・ | AZ40: 000394022 | BA40: M社（Ｎ） | BC40: VU-LA004 | BD40: 11 | BE40: =I40 -> VU-LA004 | BF40: =K40 -> 46038 | BG40: =A40 -> 21349 | BH40: =COUNTA(S40:AA40) -> 4 | BI40: =COUNTA(AB40:AO40) -> 4
...

Sheet Ｖ８出荷・完了計画
B1: Ｖ８－ＢＨ 生産投入／出荷計画表 | H1: 1/10光真ＳＳ完了/出荷計画
E2: =E2594 -> 21404 | F2: =F2594 -> 21404 | G2: =G2594 -> 21404 | H2: =IF(F2=G2,"ＯＫ","ＮＧ") -> ＯＫ | M2: 1 | N2: 皮膚科 | O2: 26
E3: 基本部
A5: 年度 | B5: 日付 | C5: 曜 | D5: 光真 稼働 | E5: 順序指示 出荷台数 | F5: 光真完了 台数 | G5: 出荷台数 ＬＡＺ計 | H5: 光真 ストア数 | I5: 遅れ 台数 | J5: 当日完了 当日出荷 台数 | K5: 備考 | L5: ストア | M5: 完了最終 T-No | N5: 出荷 累計 | O5: 日付
A6: =TEXT(B6,"YY") -> 19 | B6: 43555 | C6: 日 | D6: × | E6: 12555 | F6: 12611 | G6: 12555 | H6: =#REF!+F6-G6 -> #REF! | I6: =#REF!+G6-E6 -> #REF! | J6: =(G6-#REF!)*-1 -> #REF! | M6: 12555 | N6: 12555 | O6: =B6 -> 43555
A7: 19 | B7: 43556 | C7: 月 | D7: ○ | E7: 26 | F7: 15 | G7: 26 | H7: 45 | I7: 0 | J7: 30 | M7: 12626 | N7: =N6+G7 -> 12581 | O7: =B7 -> 43556
A8: =TEXT(B8,"YY") -> 19 | B8: 43557 | C8: 火 | D8: ○ | E8: 18 | F8: 15 | G8: 18 | H8: =H7+F8-G8 -> 42 | I8: =I7+G8-E8 -> 0 | J8: =(G8-H7)*-1 -> 27 | M8: =M7+F8 -> 12641 | N8: =N7+G8 -> 12599 | O8: =B8 -> 43557
A9: =TEXT(B9,"YY") -> 19 | B9: 43558 | C9: 水 | D9: ○ | E9: 18 | F9: 15 | G9: 18 | H9: =H8+F9-G9 -> 39 | I9: =I8+G9-E9 -> 0 | J9: =(G9-H8)*-1 -> 24 | M9: =M8+F9 -> 12656 | N9: =N8+G9 -> 12617 | O9: =B9 -> 43558
A10: =TEXT(B10,"YY") -> 19 | B10: 43559 | C10: 木 | D10: ○ | E10: 19 | F10: 15 | G10: 19 | H10: =H9+F10-G10 -> 35 | I10: =I9+G10-E10 -> 0 | J10: =(G10-H9)*-1 -> 20 | M10: =M9+F10 -> 12671 | N10: =N9+G10 -> 12636 | O10: =B10 -> 43559
A11: =TEXT(B11,"YY") -> 19 | B11: 43560 | C11: 金 | D11: ○ | E11: 18 | F11: 15 | G11: 18 | H11: =H10+F11-G11 -> 32 | I11: =I10+G11-E11 -> 0 | J11: =(G11-H10)*-1 -> 17 | M11: =M10+F11 -> 12686 | N11: =N10+G11 -> 12654 | O11: =B11 -> 43560
A12: =TEXT(B12,"YY") -> 19 | B12: 43561 | C12: 土 | D12: × | H12: =H11+F12-G12 -> 32 | I12: =I11+G12-E12 -> 0 | J12: =(G12-H11)*-1 -> 32 | M12: =M11+F12 -> 12686 | N12: =N11+G12 -> 12654 | O12: =B12 -> 43561
A13: =TEXT(B13,"YY") -> 19 | B13: 43562 | C13: 日 | D13: × | H13: =H12+F13-G13 -> 32 | I13: =I12+G13-E13 -> 0 | J13: =(G13-H12)*-1 -> 32 | M13: =M12+F13 -> 12686 | N13: =N12+G13 -> 12654 | O13: =B13 -> 43562
A14: =TEXT(B14,"YY") -> 19 | B14: 43563 | C14: 月 | D14: ○ | E14: 18 | F14: 17 | G14: 18 | H14: =H13+F14-G14 -> 31 | I14: =I13+G14-E14 -> 0 | J14: =(G14-H13)*-1 -> 14 | K14: 完了台数+1 | M14: =M13+F14 -> 12703 | N14: =N13+G14 -> 12672 | O14: =B14 -> 43563
A15: =TEXT(B15,"YY") -> 19 | B15: 43564 | C15: 火 | D15: ○ | E15: 18 | F15: 17 | G15: 18 | H15: =H14+F15-G15 -> 30 | I15: =I14+G15-E15 -> 0 | J15: =(G15-H14)*-1 -> 13 | K15: 完了台数+1 | M15: =M14+F15 -> 12720 | N15: =N14+G15 -> 12690 | O15: =B15 -> 43564
A16: =TEXT(B16,"YY") -> 19 | B16: 43565 | C16: 水 | D16: ○ | E16: 18 | F16: 17 | G16: 18 | H16: =H15+F16-G16 -> 29 | I16: =I15+G16-E16 -> 0 | J16: =(G16-H15)*-1 -> 12 | K16: 完了台数+1 | M16: =M15+F16 -> 12737 | N16: =N15+G16 -> 12708 | O16: =B16 -> 43565
A17: =TEXT(B17,"YY") -> 19 | B17: 43566 | C17: 木 | D17: ○ | E17: 19 | F17: 17 | G17: 19 | H17: =H16+F17-G17 -> 27 | I17: =I16+G17-E17 -> 0 | J17: =(G17-H16)*-1 -> 10 | K17: 完了台数+1 | M17: =M16+F17 -> 12754 | N17: =N16+G17 -> 12727 | O17: =B17 -> 43566
A18: =TEXT(B18,"YY") -> 19 | B18: 43567 | C18: 金 | D18: ○ | E18: 19 | F18: 17 | G18: 19 | H18: =H17+F18-G18 -> 25 | I18: =I17+G18-E18 -> 0 | J18: =(G18-H17)*-1 -> 8 | K18: 完了台数+1 | M18: =M17+F18 -> 12771 | N18: =N17+G18 -> 12746 | O18: =B18 -> 43567
A19: =TEXT(B19,"YY") -> 19 | B19: 43568 | C19: 土 | D19: × | H19: =H18+F19-G19 -> 25 | I19: =I18+G19-E19 -> 0 | J19: =(G19-H18)*-1 -> 25 | M19: =M18+F19 -> 12771 | N19: =N18+G19 -> 12746 | O19: =B19 -> 43568
A20: =TEXT(B20,"YY") -> 19 | B20: 43569 | C20: 日 | D20: × | H20: =H19+F20-G20 -> 25 | I20: =I19+G20-E20 -> 0 | J20: =(G20-H19)*-1 -> 25 | M20: =M19+F20 -> 12771 | N20: =N19+G20 -> 12746 | O20: =B20 -> 43569
A21: =TEXT(B21,"YY") -> 19 | B21: 43570 | C21: 月 | D21: ○ | E21: 18 | F21: 17 | G21: 18 | H21: =H20+F21-G21 -> 24 | I21: =I20+G21-E21 -> 0 | J21: =(G21-H20)*-1 -> 7 | K21: 完了台数+1 | M21: =M20+F21 -> 12788 | N21: =N20+G21 -> 12764 | O21: =B21 -> 43570
A22: =TEXT(B22,"YY") -> 19 | B22: 43571 | C22: 火 | D22: ○ | E22: 18 | F22: 18 | G22: 18 | H22: =H21+F22-G22 -> 24 | I22: =I21+G22-E22 -> 0 | J22: =(G22-H21)*-1 -> 6 | K22: 完了台数+1 | M22: =M21+F22 -> 12806 | N22: =N21+G22 -> 12782 | O22: =B22 -> 43571
A23: =TEXT(B23,"YY") -> 19 | B23: 43572 | C23: 水 | D23: ○ | E23: 19 | F23: 18 | G23: 19 | H23: =H22+F23-G23 -> 23 | I23: =I22+G23-E23 -> 0 | J23: =(G23-H22)*-1 -> 5 | K23: 完了台数+1 | M23: =M22+F23 -> 12824 | N23: =N22+G23 -> 12801 | O23: =B23 -> 43572
A24: =TEXT(B24,"YY") -> 19 | B24: 43573 | C24: 木 | D24: ○ | E24: 19 | F24: 18 | G24: 19 | H24: =H23+F24-G24 -> 22 | I24: =I23+G24-E24 -> 0 | J24: =(G24-H23)*-1 -> 4 | K24: 完了台数+1 | M24: =M23+F24 -> 12842 | N24: =N23+G24 -> 12820 | O24: =B24 -> 43573
A25: =TEXT(B25,"YY") -> 19 | B25: 43574 | C25: 金 | D25: ○ | E25: 18 | F25: 18 | G25: 18 | H25: =H24+F25-G25 -> 22 | I25: =I24+G25-E25 -> 0 | J25: =(G25-H24)*-1 -> 4 | K25: 完了台数+1 | M25: =M24+F25 -> 12860 | N25: =N24+G25 -> 12838 | O25: =B25 -> 43574
A26: =TEXT(B26,"YY") -> 19 | B26: 43575 | C26: 土 | D26: × | H26: =H25+F26-G26 -> 22 | I26: =I25+G26-E26 -> 0 | J26: =(G26-H25)*-1 -> 22 | M26: =M25+F26 -> 12860 | N26: =N25+G26 -> 12838 | O26: =B26 -> 43575
A27: =TEXT(B27,"YY") -> 19 | B27: 43576 | C27: 日 | D27: × | H27: =H26+F27-G27 -> 22 | I27: =I26+G27-E27 -> 0 | J27: =(G27-H26)*-1 -> 22 | M27: =M26+F27 -> 12860 | N27: =N26+G27 -> 12838 | O27: =B27 -> 43576
A28: =TEXT(B28,"YY") -> 19 | B28: 43577 | C28: 月 | D28: ○ | E28: 19 | F28: 18 | G28: 19 | H28: =H27+F28-G28 -> 21 | I28: =I27+G28-E28 -> 0 | J28: =(G28-H27)*-1 -> 3 | K28: 完了台数+1 | M28: =M27+F28 -> 12878 | N28: =N27+G28 -> 12857 | O28: =B28 -> 43577
A29: =TEXT(B29,"YY") -> 19 | B29: 43578 | C29: 火 | D29: ○ | E29: 19 | F29: 18 | G29: 19 | H29: =H28+F29-G29 -> 20 | I29: =I28+G29-E29 -> 0 | J29: =(G29-H28)*-1 -> 2 | K29: 完了台数+1 | M29: =M28+F29 -> 12896 | N29: =N28+G29 -> 12876 | O29: =B29 -> 43578
A30: =TEXT(B30,"YY") -> 19 | B30: 43579 | C30: 水 | D30: ○ | E30: 18 | F30: 18 | G30: 18 | H30: =H29+F30-G30 -> 20 | I30: =I29+G30-E30 -> 0 | J30: =(G30-H29)*-1 -> 2 | K30: 完了台数+1 | M30: =M29+F30 -> 12914 | N30: =N29+G30 -> 12894 | O30: =B30 -> 43579
A31: =TEXT(B31,"YY") -> 19 | B31: 43580 | C31: 木 | D31: ○ | E31: 20 | F31: 17 | G31: 20 | H31: =H30+F31-G31 -> 17 | I31: =I30+G31-E31 -> 0 | J31: =(G31-H30)*-1 -> 0 | M31: =M30+F31 -> 12931 | N31: =N30+G31 -> 12914 | O31: =B31 -> 43580
A32: =TEXT(B32,"YY") -> 19 | B32: 43581 | C32: 金 | D32: ○ | E32: 0 | F32: 8 | G32: 0 | H32: =H31+F32-G32 -> 25 | I32: =I31+G32-E32 -> 0 | J32: =(G32-H31)*-1 -> 17 | K32: ＯＳＳ非稼働設定日/光真ss棚卸 | M32: =M31+F32 -> 12939 | N32: =N31+G32 -> 12914 | O32: =B32 -> 43581
A33: =TEXT(B33,"YY") -> 19 | B33: 43582 | C33: 土 | D33: × | H33: =H32+F33-G33 -> 25 | I33: =I32+G33-E33 -> 0 | J33: =(G33-H32)*-1 -> 25 | M33: =M32+F33 -> 12939 | N33: =N32+G33 -> 12914 | O33: =B33 -> 43582
A34: =TEXT(B34,"YY") -> 19 | B34: 43583 | C34: 日 | D34: × | H34: =H33+F34-G34 -> 25 | I34: =I33+G34-E34 -> 0 | J34: =(G34-H33)*-1 -> 25 | M34: =M33+F34 -> 12939 | N34: =N33+G34 -> 12914 | O34: =B34 -> 43583
A35: =TEXT(B35,"YY") -> 19 | B35: 43584 | C35: 月 | D35: × | H35: =H34+F35-G35 -> 25 | I35: =I34+G35-E35 -> 0 | J35: =(G35-H34)*-1 -> 25 | K35: 昭和の日 | M35: =M34+F35 -> 12939 | N35: =N34+G35 -> 12914 | O35: =B35 -> 43584
A36: =TEXT(B36,"YY") -> 19 | B36: 43585 | C36: 火 | D36: × | H36: =H35+F36-G36 -> 25 | I36: =I35+G36-E36 -> 0 | J36: =(G36-H35)*-1 -> 25 | K36: 休日 | M36: =M35+F36 -> 12939 | N36: =N35+G36 -> 12914 | O36: =B36 -> 43585
A37: =TEXT(B37,"YY") -> 19 | B37: 43586 | C37: 水 | D37: × | H37: =H36+F37-G37 -> 25 | I37: =I36+G37-E37 -> 0 | J37: =(G37-H36)*-1 -> 25 | K37: 新天皇即位 | M37: =M36+F37 -> 12939 | N37: =N36+G37 -> 12914 | O37: =B37 -> 43586
A38: =TEXT(B38,"YY") -> 19 | B38: 43587 | C38: 木 | D38: × | H38: =H37+F38-G38 -> 25 | I38: =I37+G38-E38 -> 0 | J38: =(G38-H37)*-1 -> 25 | K38: 休日 | M38: =M37+F38 -> 12939 | N38: =N37+G38 -> 12914 | O38: =B38 -> 43587
A39: =TEXT(B39,"YY") -> 19 | B39: 43588 | C39: 金 | D39: × | H39: =H38+F39-G39 -> 25 | I39: =I38+G39-E39 -> 0 | J39: =(G39-H38)*-1 -> 25 | K39: 憲法記念日 | M39: =M38+F39 -> 12939 | N39: =N38+G39 -> 12914 | O39: =B39 -> 43588
A40: =TEXT(B40,"YY") -> 19 | B40: 43589 | C40: 土 | D40: × | H40: =H39+F40-G40 -> 25 | I40: =I39+G40-E40 -> 0 | J40: =(G40-H39)*-1 -> 25 | K40: みどりの日 | M40: =M39+F40 -> 12939 | N40: =N39+G40 -> 12914 | O40: =B40 -> 43589
A41: =TEXT(B41,"YY") -> 19 | B41: 43590 | C41: 日 | D41: × | H41: =H40+F41-G41 -> 25 | I41: =I40+G41-E41 -> 0 | J41: =(G41-H40)*-1 -> 25 | K41: こどもの日 | M41: =M40+F41 -> 12939 | N41: =N40+G41 -> 12914 | O41: =B41 -> 43590
...

Sheet Ｖ８ KMP  SHIPMENT PLAN 
E1: 2 | F1: 3 | G1: 4 | H1: 5 | J1: 6 | K1: 7 | L1: 9 | M1: 10 | N1: 11 | O1: 12 | P1: 13 | Q1: 14 | R1: 15 | T1: 16 | U1: 17 | W1: 18 | X1: 19 | Y1: 20 | AA1: 21 | AB1: 22
A2: A shipment schedule of KMP （It is based on production schedule of J-Koushin which referred to Omron data as of 1/10）
C4: ＠ | E4: 29856.4 | G4: 21069.9 | J4: 14724.3 | O4: 15607.8 | R4: 26329.3 | T4: 26329.3 | U4: 24384.6 | W4: 24384.6 | Y4: 24622.2 | AA4: 24622.2
E5: TRANCEPOTER | G5: 5000YEN unit | J5: OUTLET unit | L5: INLET unit | O5: SUPPLY unit | Q5: SHELTER unit | R5: RECOVERY unit | U5: 10000YEN unit | Y5: 1000YEN unit
A6: ＫＭＰ Shipment | B6: Day | C6: J-Koushin Arrival | D6: Day | E6: LAA001 | F6: LAA101 | G6: LAF001 | H6: LAF002 | I6: LAF003 | J6: LAG001 | K6: LAG002 | L6: LAE101 | M6: LAE102 | N6: LAE201 | O6: LBL001 | P6: LBL002 | Q6: LAL001 | R6: LAN001 | S6: LAN002 | T6: LCN001 | U6: LAC001 | V6: LAC002 | W6: LCC001 | X6: LCC002 | Y6: LAD001 | Z6: LAD002 | AA6: LCD001 | AB6: LCD002 | AC6: ＴＯＴＡＬ | AD6: Remarks | AE6: 前
A7: 40292 | B7: =TEXT(A7,"ｄｄｄ") -> Sat | C7: 40295 | D7: =TEXT(C7,"ｄｄｄ") -> Tue | E7: 3 | G7: 3 | H7: 0 | J7: 0 | O7: 0 | R7: 3 | T7: 0 | U7: 3 | W7: 0 | Y7: 3 | AA7: 0 | AC7: =SUM(E7:AB7) -> 15
A8: 40311 | B8: =TEXT(A8,"ｄｄｄ") -> Thu | C8: 40312 | D8: =TEXT(C8,"ｄｄｄ") -> Fri | E8: 18 | G8: 18 | H8: 0 | J8: 0 | O8: 0 | R8: 0 | T8: 0 | U8: 0 | W8: 0 | Y8: 0 | AA8: 0 | AC8: =SUM(E8:AB8) -> 36 | AD8: FEDEX866447055230
A9: 40316 | B9: =TEXT(A9,"ｄｄｄ") -> Tue | C9: 40317 | D9: =TEXT(C9,"ｄｄｄ") -> Wed | E9: 15 | G9: 19 | H9: 0 | J9: 0 | O9: 0 | R9: 12 | T9: 0 | U9: 9 | W9: 0 | Y9: 9 | AA9: 0 | AC9: =SUM(E9:AB9) -> 64 | AD9: FEDEX866447055240
A10: 40320 | B10: =TEXT(A10,"ｄｄｄ") -> Sat | C10: 40322 | D10: =TEXT(C10,"ｄｄｄ") -> Mon | E10: 12 | G10: 12 | H10: 0 | J10: 0 | O10: 0 | R10: 13 | T10: 0 | U10: 13 | W10: 0 | Y10: 13 | AA10: 0 | AC10: =SUM(E10:AB10) -> 63 | AD10: FEDEX866447055251
A11: 40327 | B11: =TEXT(A11,"ｄｄｄ") -> Sat | C11: 40329 | D11: =TEXT(C11,"ｄｄｄ") -> Mon | E11: 8 | G11: 8 | H11: 0 | J11: 0 | O11: 0 | R11: 9 | T11: 0 | U11: 12 | W11: 0 | Y11: 12 | AA11: 0 | AC11: =SUM(E11:AB11) -> 49 | AD11: FEDEX866447055284
A12: 40334 | B12: =TEXT(A12,"ｄｄｄ") -> Sat | C12: 40336 | D12: =TEXT(C12,"ｄｄｄ") -> Mon | E12: 19 | G12: 15 | H12: 0 | J12: 0 | O12: 0 | R12: 16 | T12: 0 | U12: 16 | W12: 0 | Y12: 16 | AA12: 0 | AC12: =SUM(E12:AB12) -> 82 | AD12: FEDEX866447055300
A13: 40341 | B13: =TEXT(A13,"ｄｄｄ") -> Sat | C13: 40343 | D13: =TEXT(C13,"ｄｄｄ") -> Mon | E13: 21 | G13: 21 | H13: 0 | J13: 0 | O13: 0 | R13: 8 | T13: 0 | U13: 19 | W13: 0 | Y13: 19 | AA13: 0 | AC13: =SUM(E13:AB13) -> 88 | AD13: FEDEX866447055310
A14: 40352 | B14: =TEXT(A14,"ｄｄｄ") -> Wed | C14: 40354 | D14: =TEXT(C14,"ｄｄｄ") -> Fri | E14: 19 | G14: 19 | H14: 0 | J14: 0 | O14: 0 | R14: 28 | T14: 0 | U14: 19 | W14: 0 | Y14: 19 | AA14: 0 | AC14: =SUM(E14:AB14) -> 104 | AD14: FEDEX866447055321
A15: 40358 | B15: =TEXT(A15,"ｄｄｄ") -> Tue | C15: 40359 | D15: =TEXT(C15,"ｄｄｄ") -> Wed | E15: 27 | G15: 14 | H15: 0 | J15: 0 | O15: 0 | R15: 12 | T15: 0 | U15: 19 | W15: 0 | Y15: 19 | AA15: 0 | AC15: =SUM(E15:AB15) -> 91 | AD15: 866447055332
A16: 40362 | B16: =TEXT(A16,"ｄｄｄ") -> Sat | C16: 40364 | D16: =TEXT(C16,"ｄｄｄ") -> Mon | E16: 5 | G16: 13 | H16: 0 | J16: 0 | O16: 0 | R16: 22 | T16: 0 | U16: 13 | W16: 0 | Y16: 13 | AA16: 0 | AC16: =SUM(E16:AB16) -> 66 | AD16: 866447055343
A17: 40372 | B17: =TEXT(A17,"ｄｄｄ") -> Tue | C17: 40374 | D17: =TEXT(C17,"ｄｄｄ") -> Thu | E17: 19 | G17: 24 | H17: 0 | J17: 0 | O17: 0 | R17: 18 | T17: 0 | U17: 18 | W17: 0 | Y17: 18 | AA17: 0 | AC17: =SUM(E17:AB17) -> 97 | AD17: 866447055376
A18: 40379 | B18: =TEXT(A18,"ｄｄｄ") -> Tue | C18: 40380 | D18: =TEXT(C18,"ｄｄｄ") -> Wed | E18: 19 | G18: 19 | H18: 0 | J18: 0 | O18: 0 | R18: 25 | T18: 0 | U18: 25 | W18: 0 | Y18: 25 | AA18: 0 | AC18: =SUM(E18:AB18) -> 113 | AD18: 866447055398
A19: 40388 | B19: =TEXT(A19,"ｄｄｄ") -> Thu | C19: 40389 | D19: =TEXT(C19,"ｄｄｄ") -> Fri | E19: 26 | G19: 5 | H19: 0 | J19: 0 | O19: 0 | R19: 32 | T19: 0 | U19: 19 | W19: 0 | Y19: 13 | AA19: 0 | AC19: =SUM(E19:AB19) -> 95 | AD19: 866447055413
A20: 40394 | B20: =TEXT(A20,"ｄｄｄ") -> Wed | C20: 40395 | D20: =TEXT(C20,"ｄｄｄ") -> Thu | E20: 0 | G20: 16 | H20: 0 | J20: 0 | O20: 0 | R20: 0 | T20: 0 | U20: 0 | W20: 0 | Y20: 4 | AA20: 0 | AC20: =SUM(E20:AB20) -> 20 | AD20: 866447055435
A21: 40404 | B21: =TEXT(A21,"ｄｄｄ") -> Sat | C21: 40406 | D21: =TEXT(C21,"ｄｄｄ") -> Mon | E21: 22 | G21: 21 | H21: 0 | J21: 0 | O21: 0 | R21: 9 | T21: 0 | U21: 15 | W21: 0 | Y21: 17 | AA21: 0 | AC21: =SUM(E21:AB21) -> 84 | AD21: 866447055457
A22: 40410 | B22: =TEXT(A22,"ｄｄｄ") -> Fri | C22: 40413 | D22: =TEXT(C22,"ｄｄｄ") -> Mon | E22: 23 | G22: 11 | H22: 0 | J22: 0 | O22: 0 | R22: 26 | T22: 0 | U22: 13 | W22: 0 | Y22: 13 | AA22: 0 | AC22: =SUM(E22:AB22) -> 86 | AD22: 866447055468
A23: 40416 | B23: =TEXT(A23,"ｄｄｄ") -> Thu | C23: 40417 | D23: =TEXT(C23,"ｄｄｄ") -> Fri | E23: 13 | G23: 20 | H23: 0 | J23: 0 | O23: 0 | R23: 17 | T23: 0 | U23: 25 | W23: 0 | Y23: 25 | AA23: 0 | AC23: =SUM(E23:AB23) -> 100 | AD23: 866447055479
A24: 40421 | B24: =TEXT(A24,"ｄｄｄ") -> Tue | C24: 40422 | D24: =TEXT(C24,"ｄｄｄ") -> Wed | E24: 8 | G24: 11 | H24: 0 | J24: 0 | O24: 0 | R24: 11 | T24: 0 | U24: 14 | W24: 0 | Y24: 14 | AA24: 0 | AC24: =SUM(E24:AB24) -> 58 | AD24: 866447055505
A25: 40425 | B25: =TEXT(A25,"ｄｄｄ") -> Sat | C25: 40428 | D25: =TEXT(C25,"ｄｄｄ") -> Tue | E25: 0 | G25: 18 | H25: 0 | J25: 0 | O25: 0 | R25: 12 | T25: 0 | U25: 17 | W25: 0 | Y25: 17 | AA25: 0 | AC25: =SUM(E25:AB25) -> 64 | AD25: 866447055516
A26: 40432 | B26: =TEXT(A26,"ｄｄｄ") -> Sat | C26: 40434 | D26: =TEXT(C26,"ｄｄｄ") -> Mon | E26: 16 | G26: 8 | H26: 0 | J26: 0 | O26: 0 | R26: 20 | T26: 0 | U26: 12 | W26: 0 | Y26: 12 | AA26: 0 | AC26: =SUM(E26:AB26) -> 68 | AD26: 866447055538
... A32: 40472 | B32: =TEXT(A32,"ｄｄｄ") -> Thu | C32: 40473 | D32: =TEXT(C32,"ｄｄｄ") -> Fri | E32: 37 | G32: 19 | H32: 0 | J32: 0 | O32: 0 | R32: 28 | T32: 0 | U32: 13 | W32: 0 | Y32: 13 | AA32: 0 | AC32: =SUM(E32:AB32) -> 110 | AD32: 866447055560
A33: 40478 | B33: =TEXT(A33,"ｄｄｄ") -> Wed | C33: 40479 | D33: =TEXT(C33,"ｄｄｄ") -> Thu | E33: 36 | G33: 28 | H33: 0 | J33: 0 | O33: 0 | R33: 22 | T33: 0 | U33: 28 | W33: 0 | Y33: 28 | AA33: 0 | AC33: =SUM(E33:AB33) -> 142 | AD33: DHL5678882381
A34: 40483 | B34: =TEXT(A34,"ｄｄｄ") -> Mon | C34: 40486 | D34: =TEXT(C34,"ｄｄｄ") -> Thu | E34: 10 | G34: 31 | H34: 0 | J34: 0 | O34: 0 | R34: 24 | T34: 0 | U34: 33 | W34: 0 | Y34: 33 | AA34: 0 | AC34: =SUM(E34:AB34) -> 131 | AD34: DHL5678882392
A35: 40488 | B35: =TEXT(A35,"ｄｄｄ") -> Sat | C35: 40490 | D35: =TEXT(C35,"ｄｄｄ") -> Mon | E35: 31 | G35: 27 | H35: 0 | J35: 0 | O35: 0 | R35: 35 | T35: 0 | U35: 28 | W35: 0 | Y35: 29 | AA35: 0 | AC35: =SUM(E35:AB35) -> 150 | AD35: 866447055571
A36: 40495 | B36: =TEXT(A36,"ｄｄｄ") -> Sat | C36: 40497 | D36: =TEXT(C36,"ｄｄｄ") -> Mon | E36: 40 | G36: 39 | H36: 0 | J36: 0 | O36: 0 | R36: 40 | T36: 0 | U36: 34 | W36: 0 | Y36: 34 | AA36: 0 | AC36: =SUM(E36:AB36) -> 187 | AD36: DHL5678882403
A37: 40502 | B37: =TEXT(A37,"ｄｄｄ") -> Sat | C37: 40506 | D37: =TEXT(C37,"ｄｄｄ") -> Wed | E37: 22 | G37: 28 | H37: 0 | J37: 0 | O37: 0 | R37: 23 | T37: 0 | U37: 22 | W37: 0 | Y37: 22 | AA37: 0 | AC37: =SUM(E37:AB37) -> 117 | AD37: DHL5678882436
A38: 40506 | B38: =TEXT(A38,"ｄｄｄ") -> Wed | C38: 40507 | D38: =TEXT(C38,"ｄｄｄ") -> Thu | E38: 15 | G38: 17 | H38: 0 | J38: 0 | O38: 0 | R38: 17 | T38: 0 | U38: 22 | W38: 0 | Y38: 19 | AA38: 0 | AC38: =SUM(E38:AB38) -> 90 | AD38: 866447055582
A39: 40509 | B39: =TEXT(A39,"ｄｄｄ") -> Sat | C39: 40512 | D39: =TEXT(C39,"ｄｄｄ") -> Tue | E39: 24 | G39: 18 | H39: 0 | J39: 0 | O39: 0 | R39: 12 | T39: 0 | U39: 18 | W39: 0 | Y39: 18 | AA39: 0 | AC39: =SUM(E39:AB39) -> 90 | AD39: 866447055593
A40: 40516 | B40: =TEXT(A40,"ｄｄｄ") -> Sat | C40: 40518 | D40: =TEXT(C40,"ｄｄｄ") -> Mon | E40: 18 | G40: 24 | H40: 0 | J40: 0 | O40: 0 | R40: 26 | T40: 0 | U40: 29 | W40: 0 | Y40: 30 | AA40: 0 | AC40: =SUM(E40:AB40) -> 127 | AD40: DHL5678882554
A41: 40520 | B41: =TEXT(A41,"ｄｄｄ") -> Wed | C41: 40521 | D41: =TEXT(C41,"ｄｄｄ") -> Thu | E41: 10 | G41: 14 | H41: 0 | J41: 0 | O41: 0 | R41: 22 | T41: 0 | U41: 25 | W41: 0 | Y41: 24 | AA41: 0 | AC41: =SUM(E41:AB41) -> 95 | AD41: 866447055608
A42: 40523 | B42: =TEXT(A42,"ｄｄｄ") -> Sat | C42: 40527 | D42: =TEXT(C42,"ｄｄｄ") -> Wed | E42: 22 | G42: 13 | H42: 0 | J42: 0 | O42: 0 | R42: 19 | T42: 0 | U42: 22 | W42: 0 | Y42: 22 | AA42: 0 | AC42: =SUM(E42:AB42) -> 98 | AD42: 866447055619
A43: 40530 | B43: =TEXT(A43,"ｄｄｄ") -> Sat | C43: 40534 | D43: =TEXT(C43,"ｄｄｄ") -> Wed | E43: 18 | G43: 35 | H43: 0 | J43: 0 | O43: 0 | R43: 20 | T43: 0 | U43: 22 | W43: 0 | Y43: 22 | AA43: 0 | AC43: =SUM(E43:AB43) -> 117 | AD43: DHL5678882543
A44: 40535 | B44: =TEXT(A44,"ｄｄｄ") -> Thu | C44: 40536 | D44: =TEXT(C44,"ｄｄｄ") -> Fri | E44: 42 | G44: 29 | H44: 0 | J44: 0 | O44: 0 | R44: 27 | T44: 0 | U44: 24 | W44: 0 | Y44: 24 | AA44: 0 | AC44: =SUM(E44:AB44) -> 146 | AD44: 866447055620
A45: 40555 | B45: =TEXT(A45,"ｄｄｄ") -> Wed | C45: 40556 | D45: =TEXT(C45,"ｄｄｄ") -> Thu | E45: 23 | G45: 24 | H45: 0 | J45: 0 | O45: 0 | R45: 27 | T45: 0 | U45: 27 | W45: 0 | Y45: 27 | AA45: 0 | AC45: =SUM(E45:AB45) -> 128 | AD45: 866447055652
A46: 40562 | B46: =TEXT(A46,"ｄｄｄ") -> Wed | C46: 40563 | D46: =TEXT(C46,"ｄｄｄ") -> Thu | E46: 3 | G46: 27 | H46: 0 | J46: 0 | O46: 0 | R46: 35 | T46: 0 | U46: 36 | W46: 0 | Y46: 36 | AA46: 0 | AC46: =SUM(E46:AB46) -> 137 | AD46: 866447055674
...

Sheet BH出荷・完了グラフ 
A1: 出荷月 | B1: V8-BH | C1: V9-BH | D1: BH合計
A2: 25/4月 | B2: 12 | C2: 16 | D2: 28
A3: 5月 | B3: 16 | C3: 18 | D3: 34
A4: 6月 | B4: 13 | C4: 19 | D4: 32
A5: 7月 | B5: 12 | C5: 37 | D5: 49
A6: 8月 | B6: 25 | C6: 50 | D6: 75
A7: 9月 | B7: 24 | C7: 54 | D7: 78
A8: 10月 | B8: 45 | C8: 72 | D8: 117
A9: 11月 | B9: 53 | C9: 71 | D9: 124
A10: 12月 | B10: 31 | C10: 64 | D10: 95
A11: 26/1月 | B11: 36 | C11: 61 | D11: 97
A12: 2月 | B12: 6 | C12: 25 | D12: 31
A13: 3月 | B13: 16 | C13: 14 | D13: 30
... A26: 4月 | B26: 25 | C26: 0 | D26: 25
A28: 日 | B28: V8出荷 | C28: V8完了 | D28: V9出荷 | E28: V9完了 | F28: BH出荷台数 | G28: BH完了台数
A29: 45992 | B29: 5 | C29: 2 | D29: 2 | E29: 4 | F29: =B29+D29 -> 7 | G29: =C29+E29 -> 6
A30: 45993 | B30: 3 | C30: 2 | D30: 2 | E30: 4 | F30: =B30+D30 -> 5 | G30: =C30+E30 -> 6
A31: 45994 | B31: 2 | C31: 2 | D31: 2 | E31: 4 | F31: =B31+D31 -> 4 | G31: =C31+E31 -> 6
A32: 45995 | B32: 3 | C32: 1 | D32: 2 | E32: 5 | F32: =B32+D32 -> 5 | G32: =C32+E32 -> 6
A33: 45996 | B33: 1 | C33: 1 | D33: 4 | E33: 5 | F33: =B33+D33 -> 5 | G33: =C33+E33 -> 6
A34: 45999 | B34: 1 | C34: 1 | D34: 3 | E34: 5 | F34: =B34+D34 -> 4 | G34: =C34+E34 -> 6
A35: 46000 | B35: 1 | C35: 1 | D35: 3 | E35: 5 | F35: =B35+D35 -> 4 | G35: =C35+E35 -> 6
A36: 46001 | B36: 1 | C36: 1 | D36: 3 | E36: 5 | F36: =B36+D36 -> 4 | G36: =C36+E36 -> 6
A37: 46002 | B37: 2 | C37: 2 | D37: 2 | E37: 4 | F37: =B37+D37 -> 4 | G37: =C37+E37 -> 6
A38: 46003 | B38: 1 | C38: 2 | D38: 3 | E38: 4 | F38: =B38+D38 -> 4 | G38: =C38+E38 -> 6
A39: 46006 | B39: 2 | C39: 2 | D39: 3 | E39: 4 | F39: =B39+D39 -> 5 | G39: =C39+E39 -> 6
A40: 46007 | B40: 2 | C40: 2 | D40: 3 | E40: 4 | F40: =B40+D40 -> 5 | G40: =C40+E40 -> 6
... A126: 46139 | B126: 0 | C126: 0 | D126: 5 | E126: 5 | F126: =B126+D126 -> 5 | G126: =C126+E126 -> 5
A127: 46140 | B127: 0 | C127: 0 | D127: 6 | F127: =B127+D127 -> 6 | G127: =C127+E127 -> 0
A128: 46142 | B128: 0 | C128: 0 | F128: =B128+D128 -> 0 | G128: =C128+E128 -> 0

Sheet 山元用
A1: 日付 ShipDate | B1: ﾊﾝｿｳﾌﾞ | C1: 5000ｴﾝﾌﾞ | D1: 5000ｴﾝﾌﾞ | E1: 5000ｴﾝﾌﾞ | F1: ﾂﾘｼﾍｲ ﾎﾘﾕｳﾌﾞ | G1: ﾂﾘｼﾍｲ ﾎﾘﾕｳﾌﾞ | H1: ｿｳﾆﾕｳｳﾌﾞ | I1: ｿｳﾆﾕｳｳﾌﾞ | J1: ｿｳﾆﾕｳｳﾌﾞ | K1: ﾎｷﾕｳﾌﾞ ｺｳﾎｳ | L1: ﾎｷﾕｳﾌﾞ ｺｳﾎｳ | M1: ﾀｲﾋﾌﾞ | N1: ｶｲｼﾕｳﾌﾞ （固定式） | O1: ｶｲｼﾕｳﾌﾞ （固定式） | P1: ｶｲｼﾕｳﾌﾞ （可搬式） | Q1: 10000ｴﾝﾌﾞ （固定式） | R1: 10000ｴﾝﾌﾞ （固定式） | S1: 10000ｴﾝﾌﾞ （可搬式） | T1: 10000ｴﾝﾌﾞ （可搬式） | U1: 1000ｴﾝ ｶｾﾂﾄﾌﾞ （固定式） | V1: 1000ｴﾝ ｶｾﾂﾄﾌﾞ （固定式） | W1: 1000ｴﾝ ｶｾﾂﾄﾌﾞ （可搬式） | X1: 1000ｴﾝ ｶｾﾂﾄﾌﾞ （可搬式） | Y1: ｷﾎﾝﾌﾞ BH | Z1: ｷﾎﾝﾌﾞ BH | AA1: ｷﾎﾝﾌﾞ BH | AB1: ｷﾎﾝﾌﾞ BH | AC1: ｷﾎﾝﾌﾞ BH | AD1: ｷﾎﾝﾌﾞ BH | AE1: ｷﾎﾝﾌﾞ BH | AF1: ﾚ-ﾙﾌﾞ
A2: 46066 | B2: LAA101 | C2: LAF001 | D2: LAF002 | E2: LAF003 | F2: LAG001 | G2: LAG002 | H2: LAE101 | I2: LAE102 | J2: LAE201 | K2: LBL001 | L2: LBL002 | M2: LAL001 | N2: LAN001 | O2: LAN002 | P2: LCN001 | Q2: LAC001 | R2: LAC002 | S2: LCC001 | T2: LCC002 | U2: LAD001 | V2: LAD002 | W2: LCD001 | X2: LCD002 | Y2: LAZ002 | Z2: LAZ003 | AA2: LAZ004 | AB2: LAZ101 | AC2: LAZ102 | AD2: LAZ103 | AE2: LAZ201 | AF2: LAH001
A3: メンテ 台数 Maintenance Quantity | B3: =COUNTIFS(Ｖ８星取表!$Q$7:$Q$1600,$A$2,Ｖ８星取表!$R$7:$R$1600,"M",Ｖ８星取表!S$7:S$1600,"<>") -> 0 | C3: =COUNTIFS(Ｖ８星取表!$Q$7:$Q$1600,$A$2,Ｖ８星取表!$R$7:$R$1600,"M",Ｖ８星取表!T$7:T$1600,"<>") -> 0 | D3: =COUNTIFS(Ｖ８星取表!$Q$7:$Q$1600,$A$2,Ｖ８星取表!$R$7:$R$1600,"M",Ｖ８星取表!U$7:U$1600,"<>") -> 0 | E3: =COUNTIFS(Ｖ８星取表!$Q$7:$Q$1600,$A$2,Ｖ８星取表!$R$7:$R$1600,"M",Ｖ８星取表!V$7:V$1600,"<>") -> 0 | F3: =COUNTIFS(Ｖ８星取表!$Q$7:$Q$1600,$A$2,Ｖ８星取表!$R$7:$R$1600,"M",Ｖ８星取表!W$7:W$1600,"<>") -> 3 | G3: =COUNTIFS(Ｖ８星取表!$Q$7:$Q$1600,$A$2,Ｖ８星取表!$R$7:$R$1600,"M",Ｖ８星取表!X$7:X$1600,"<>") -> 0 | H3: =COUNTIFS(Ｖ８星取表!$Q$7:$Q$1600,$A$2,Ｖ８星取表!$R$7:$R$1600,"M",Ｖ８星取表!Y$7:Y$1600,"<>") -> 0 | I3: =COUNTIFS(Ｖ８星取表!$Q$7:$Q$1600,$A$2,Ｖ８星取表!$R$7:$R$1600,"M",Ｖ８星取表!Z$7:Z$1600,"<>") -> 0 | ... X3: =COUNTIFS(Ｖ８星取表!$Q$7:$Q$1600,$A$2,Ｖ８星取表!$R$7:$R$1600,"M",Ｖ８星取表!AO$7:AO$1600,"<>") -> 0 | AF3: =COUNTIFS(Ｖ８星取表!$Q$7:$Q$1600,$A$2,Ｖ８星取表!$R$7:$R$1600,"M",Ｖ８星取表!AY$7:AY$1600,"<>") -> 0
A4: メンテ 号機 Maintenance Serial Number
A5: 台数 Quantity | K5: =COUNTIFS(Ｖ８星取表!$Q$7:$Q$1600,$A$2,Ｖ８星取表!$R$7:$R$1600,"",Ｖ８星取表!AB$7:AB$1600,"<>") -> 0 | L5: =COUNTIFS(Ｖ８星取表!$Q$7:$Q$1600,$A$2,Ｖ８星取表!$R$7:$R$1600,"",Ｖ８星取表!AC$7:AC$1600,"<>") -> 0 | M5: =COUNTIFS(Ｖ８星取表!$Q$7:$Q$1600,$A$2,Ｖ８星取表!$R$7:$R$1600,"",Ｖ８星取表!AD$7:AD$1600,"<>") -> 0 | N5: =COUNTIFS(Ｖ８星取表!$Q$7:$Q$1600,$A$2,Ｖ８星取表!$R$7:$R$1600,"",Ｖ８星取表!AE$7:AE$1600,"<>") -> 0 | O5: =COUNTIFS(Ｖ８星取表!$Q$7:$Q$1600,$A$2,Ｖ８星取表!$R$7:$R$1600,"",Ｖ８星取表!AF$7:AF$1600,"<>") -> 0 | P5: =COUNTIFS(Ｖ８星取表!$Q$7:$Q$1600,$A$2,Ｖ８星取表!$R$7:$R$1600,"",Ｖ８星取表!AG$7:AG$1600,"<>") -> 0 | Q5: =COUNTIFS(Ｖ８星取表!$Q$7:$Q$1600,$A$2,Ｖ８星取表!$R$7:$R$1600,"",Ｖ８星取表!AH$7:AH$1600,"<>") -> 0 | R5: =COUNTIFS(Ｖ８星取表!$Q$7:$Q$1600,$A$2,Ｖ８星取表!$R$7:$R$1600,"",Ｖ８星取表!AI$7:AI$1600,"<>") -> 0 | ... AE5: =COUNTIFS(Ｖ８星取表!$Q$7:$Q$1600,$A$2,Ｖ８星取表!$R$7:$R$1600,"",Ｖ８星取表!AV$7:AV$1600,"<>") -> 0
A6: 号機 Serial Number

Sheet ＫＭＰ出荷スケジュール
A1: 今後のKMP出荷スケジュール（案） | X1: =TODAY() -> 46051
K3: 物流実績/予測
A4: Ｎo | B4: KMP ﾊﾟｰﾂ納期 | C4: ＫＭＰ 出荷日 | D4: 曜日 | E4: 日本到着 | F4: 光真ss 必要日 | I4: 光真稼働 カバー日数 | J4: 曜日 | K4: Ｖ７ ユニット数 | L4: Ｖ８ ユニット数 | M4: Ｖ９ ユニット | N4: 合計 ユニット数 | O4: Ｖ７ 重量 | P4: Ｖ８ 重量 | Q4: Ｖ９ 重量 | R4: 重量 (kg） | S4: ﾊﾟﾚｯﾄ数 | T4: BOX 数 | U4: 運送 業者 | V4: 備考 | W4: 1ﾊﾟﾚ ﾕﾆｯﾄ重量 | Y4: assigned HAWB# | Z4: 輸送Ｌ／Ｔ (暦日） | AB4: 備考
A5: 29 | B5: 3月中旬 | C5: 42462 | E5: 42466 | F5: 42466 | G5: ～ | H5: 42480 | I5: 11 | K5: 31 | L5: 332 | N5: =SUM(K5:M5) -> 363 | R5: 1104.666 | S5: 5 | U5: ＵＰＳ | V5: 実績 | W5: =R5/S5 -> 220.9332
A6: 30 | B6: 4月初旬 | C6: 42478 | E6: 42481 | F6: 42481 | G6: ～ | H6: 42501 | I6: 10 | K6: 17 | L6: 299 | N6: =SUM(K6:M6) -> 316 | R6: 1019.506 | S6: 5 | U6: ＵＰＳ | V6: 実績 | W6: =R6/S6 -> 203.9012
A7: 1 | B7: 4月中旬 | C7: 42496 | E7: 42502 | F7: 42502 | G7: ～ | H7: 42515 | I7: 10 | K7: 13 | L7: 383 | N7: =SUM(K7:M7) -> 396 | R7: 1248.463 | S7: 6 | U7: ＭＩＦＦＩ | V7: 実績 | W7: =R7/S7 -> 208.07717
A8: 2 | B8: 5月初旬 | C8: 42513 | E8: 42516 | F8: 42516 | G8: ～ | H8: 42529 | I8: 10 | K8: 87 | L8: 388 | N8: =SUM(K8:M8) -> 475 | R8: 1377.626 | S8: 7 | U8: ＭＩＦＦＩ | V8: 実績 | W8: =R8/S8 -> 196.80371
A9: 3 | B9: 5月中旬 | C9: 42527 | E9: 42530 | F9: 42530 | G9: ～ | H9: 42544 | I9: 11 | K9: 114 | L9: 390 | N9: =SUM(K9:M9) -> 504 | R9: 1449.06 | S9: 7 | U9: ＵＰＳ | V9: 実績 | W9: =R9/S9 -> 207.00857
A10: 4 | B10: 6月初旬 | C10: 42542 | E10: 42545 | F10: 42545 | G10: ～ | H10: 42559 | I10: 11 | K10: 19 | L10: 513 | N10: =SUM(K10:M10) -> 532 | R10: 1824.913 | S10: 8 | U10: ＵＰＳ | V10: 実績 | W10: =R10/S10 -> 228.11413
A11: 5 | B11: 6月中旬 | C11: 42557 | E11: 42562 | F11: 42562 | G11: ～ | H11: 42576 | I11: 10 | K11: 12 | L11: 382 | N11: =SUM(K11:M11) -> 394 | R11: 1387.478 | S11: 6 | U11: ＵＰＳ | V11: 実績 | W11: =R11/S11 -> 231.24633
A12: 6 | B12: 7月初旬 | C12: 42572 | E12: 42577 | F12: 42577 | G12: ～ | H12: 42591 | I12: 11 | K12: 60 | L12: 539 | N12: =SUM(K12:M12) -> 599 | R12: 1930.585 | S12: 9 | U12: UPS | V12: 実績 | W12: =R12/S12 -> 214.50944
A13: 7 | B13: 7月中旬 | C13: 42587 | E13: 42592 | F13: 42592 | G13: ～ | H13: 42607 | I13: 7 | K13: 28 | L13: 504 | N13: =SUM(K13:M13) -> 532 | R13: 1832.276 | S13: 8 | U13: UPS | V13: 実績 | W13: =R13/S13 -> 229.0345
A14: 8 | B14: 8月初旬 | C14: 42605 | E14: 42608 | F14: 42608 | G14: ～ | H14: 42620 | I14: 9 | K14: 39 | L14: 624 | N14: =SUM(K14:M14) -> 663 | R14: 2299.424 | S14: 10 | U14: UPS | V14: 実績 | W14: =R14/S14 -> 229.9424
A15: 9 | B15: 8月中旬 | C15: 42618 | E15: 42621 | F15: 42621 | G15: ～ | H15: 42634 | I15: 8 | K15: 33 | L15: 528 | N15: =SUM(K15:M15) -> 561 | R15: 1907.03 | S15: 8 | U15: UPS | V15: 実績 | W15: =R15/S15 -> 238.37875
A16: 10 | B16: 9月初旬 | C16: 42633 | E16: 42637 | F16: 42636 | G16: ～ | H16: 42648 | I16: 10 | K16: 45 | L16: 654 | N16: =SUM(K16:M16) -> 699 | R16: 2353.042 | S16: 10 | U16: UPS | V16: 実績 | W16: =R16/S16 -> 235.3042
... A19: 13 | B19: 10月初旬 | C19: 42667 | E19: 42670 | F19: 42670 | G19: ～ | H19: 42681 | I19: 7 | K19: 13 | L19: 702 | N19: =SUM(K19:M19) -> 715 | R19: 2564 | S19: 11 | U19: UPS | V19: 実績 | W19: =R19/S19 -> 233.09091
A20: 14 | B20: 10月初旬 | C20: 42670 | E20: 42678 | G20: ～ | K20: 0 | L20: 21 | N20: =SUM(K20:M20) -> 21 | R20: 43.1 | S20: 1 | U20: UPS | V20: 実績 | W20: =R20/S20 -> 43.1 | X20: LAE 日本部品の欠品のため別送
A21: 15 | B21: 10月中旬 | C21: 42678 | E21: 42682 | F21: 42682 | G21: ～ | H21: 42692 | I21: 9 | K21: 31 | L21: 653 | N21: =SUM(K21:M21) -> 684 | R21: 2305.481 | S21: 11 | U21: UPS | V21: 実績 | W21: =R21/S21 -> 209.58918
A22: 16 | B22: 11月初旬 | C22: 42684 | E22: 42688 | F22: 42685 | G22: ～ | H22: 42704 | I22: 13 | K22: 0 | L22: 523 | N22: =SUM(K22:M22) -> 523 | R22: 1687.7 | S22: 8 | U22: UPS | V22: 実績 | W22: =R22/S22 -> 210.9625
A23: 17 | B23: 11月中旬 | C23: 42698 | E23: 42703 | F23: 42703 | G23: ～ | H23: 42710 | I23: 6 | K23: 6 | L23: 503 | N23: =SUM(K23:M23) -> 509 | R23: 1855 | S23: 8 | U23: UPS | V23: 実績 | W23: =R23/S23 -> 231.875
A24: 18 | B24: 11月中旬 | C24: 42706 | E24: 42710 | F24: 42711 | G24: ～ | H24: 42717 | I24: 5 | K24: 3 | L24: 507 | N24: =SUM(K24:M24) -> 510 | R24: 1697 | S24: 7 | U24: UPS | V24: 実績 | W24: =R24/S24 -> 242.42857
A25: 19 | B25: 12月初旬 | C25: 42713 | E25: 42718 | F25: 42718 | G25: ～ | H25: 42726 | I25: 7 | K25: 12 | L25: 500 | N25: =SUM(K25:M25) -> 512 | R25: 1888.722 | S25: 9 | U25: UPS | V25: 実績 | W25: =R25/S25 -> 209.858
A26: 20 | B26: 12月中旬 | C26: 42725 | E26: 43096 | F26: 42730 | G26: ～ | H26: 42745 | I26: 6 | K26: 50 | L26: 458 | N26: =SUM(K26:M26) -> 508 | R26: 1741.983 | S26: 9 | U26: UPS | V26: 実績 | W26: =R26/S26 -> 193.55367
A27: 21 | B27: 12月中旬 | C27: 42741 | E27: 42746 | F27: 42746 | G27: ～ | H27: 42752 | I27: 5 | K27: 3 | L27: 452 | N27: =SUM(K27:M27) -> 455 | R27: 1640.203 | S27: 8 | U27: UPS | V27: 実績 | W27: =R27/S27 -> 205.02537
A28: 22 | B28: 1月初旬 | C28: 42747 | E28: 42752 | F28: 42753 | G28: ～ | H28: 42759 | I28: 5 | K28: 10 | L28: 458 | N28: =SUM(K28:M28) -> 468 | R28: 1543.794 | S28: 7 | U28: UPS | V28: 実績 | W28: =R28/S28 -> 220.542
A29: 23 | B29: 1月中旬 | C29: 42755 | E29: 42759 | F29: 42760 | G29: ～ | H29: 42766 | I29: 5 | K29: 0 | L29: 478 | N29: =SUM(K29:M29) -> 478 | R29: 1613.161 | S29: 7 | U29: UPS | V29: 実績 | W29: =R29/S29 -> 230.45157
A30: 24 | B30: 1月中旬 | C30: 42762 | E30: 42766 | F30: 42767 | G30: ～ | H30: 42774 | I30: 6 | K30: 0 | L30: 564 | N30: =SUM(K30:M30) -> 564 | R30: 1958.495 | S30: 8 | U30: UPS | V30: 実績 | W30: =R30/S30 -> 244.81187
A31: 25 | B31: 1月中旬 | C31: 42772 | E31: 42776 | F31: 42775 | G31: ～ | H31: 42781 | I31: 5 | K31: 7 | L31: 484 | N31: =SUM(K31:M31) -> 491 | R31: 1641.4 | S31: 7 | U31: UPS | V31: 実績 | W31: =R31/S31 -> 234.48571
A32: 26 | B32: 2月初旬 | C32: 42780 | E32: 42782 | F32: 42782 | G32: ～ | H32: 42787 | I32: 4 | K32: 0 | L32: 288 | N32: =SUM(K32:M32) -> 288 | R32: 985.1 | S32: 4 | U32: UPS | V32: 実績 | W32: =R32/S32 -> 246.275 | X32: ﾌﾟﾘｽﾞﾑ誤入荷により分割出荷（もと2/13：476台）
A33: 27 | B33: 2月初旬 | C33: 42780 | E33: 42782 | F33: 42782 | G33: ～ | H33: 42787 | I33: 4 | K33: 4 | L33: 188 | N33: =SUM(K33:M33) -> 192 | R33: 635.3 | S33: 3 | U33: UPS | V33: 実績 | W33: =R33/S33 -> 211.76667 | X33: ﾌﾟﾘｽﾞﾑ誤入荷により分割出荷
A34: 28 | B34: 2月初旬 | C34: 42787 | E34: 42790 | F34: 42788 | G34: ～ | H34: 42795 | I34: 4 | K34: 18 | L34: 342 | N34: =SUM(K34:M34) -> 360 | R34: 1209.5 | S34: 5 | U34: UPS | V34: 実績 | W34: =R34/S34 -> 241.9 | X34: ﾌﾟﾘｽﾞﾑ誤入荷により分割出荷（もと2/20：546台）
A35: 29 | B35: 2月初旬 | C35: 42789 | E35: 42794 | F35: 42794 | G35: ～ | H35: 42795 | I35: 2 | K35: 0 | L35: 271 | N35: =SUM(K35:M35) -> 271 | R35: 938.2 | S35: 4 | U35: UPS | V35: 実績 | W35: =R35/S35 -> 234.55 | X35: ﾌﾟﾘｽﾞﾑ誤入荷により分割出荷（2/27出荷分を前倒し出荷67台）
A36: 30 | B36: 2月中旬 | C36: 42793 | E36: 42796 | F36: 42796 | G36: ～ | H36: 42800 | I36: 3 | K36: 43 | L36: 254 | N36: =SUM(K36:M36) -> 297 | R36: 955.4 | S36: 5 | U36: UPS | V36: 実績 | W36: =R36/S36 -> 191.08 | X36: ﾌﾟﾘｽﾞﾑ誤入荷による取戻しおよびｻﾝﾘﾂ欠品により分割出荷（もと2/27出荷561台）
A37: 31 | B37: 2月中旬 | C37: 42796 | E37: 42801 | F37: 42801 | G37: ～ | H37: 42803 | I37: 3 | K37: 0 | L37: 289 | N37: =SUM(K37:M37) -> 289 | R37: 975.9 | S37: 4 | U37: UPS | V37: 実績 | W37: =R37/S37 -> 243.975 | X37: ﾌﾟﾘｽﾞﾑ誤入荷による取戻しおよびｻﾝﾘﾂ欠品により分割出荷
A38: 32 | B38: 2月中旬 | C38: 42801 | E38: 42807 | F38: 42804 | G38: ～ | H38: 42822 | I38: 12 | K38: 5 | L38: 340 | N38: =SUM(K38:M38) -> 345 | R38: 1159 | S38: 5 | U38: UPS | V38: 実績 | W38: =R38/S38 -> 231.8 | X38: ｻﾝﾘﾂ欠品により分轄（元3/7V8出荷537台）
A39: 33 | B39: 2月中旬 | C39: 42805 | E39: 42809 | F39: 42808 | G39: ～ | H39: 42822 | K39: 0 | L39: 145 | N39: =SUM(K39:M39) -> 145 | R39: 506 | S39: 3 | U39: UPS | V39: 実績 | W39: =R39/S39 -> 168.66667 | X39: ｻﾝﾘﾂ欠品により分轄（元3/7V8出荷537台）
A40: 34 | B40: 3月初旬 | C40: 42817 | E40: 42822 | F40: 42822 | G40: ～ | H40: 42836 | K40: 62 | L40: 479 | N40: =SUM(K40:M40) -> 541 | R40: 1714.657 | S40: 8 | U40: UPS | V40: 実績 | W40: =R40/S40 -> 214.33213
A41: 35 | B41: 3月中旬 | C41: 42832 | E41: 42836 | F41: 42837 | G41: ～ | H41: 42851 | I41: 10 | K41: 33 | L41: 512 | N41: =SUM(K41:M41) -> 545 | R41: 1795 | S41: 8 | U41: UPS | V41: 実績 | W41: =R41/S41 -> 224.375
A42: 36 | B42: 4月初旬 | C42: 42846 | E42: 42850 | F42: 42852 | G42: ～ | H42: 42870 | I42: 9 | K42: 15 | L42: 469 | N42: =SUM(K42:M42) -> 484 | R42: 1645 | S42: 8 | U42: UPS | V42: 実績 | W42: =R42/S42 -> 205.625
A43: 1 | B43: 4月中旬 | C43: 42866 | E43: 42871 | F43: 42871 | G43: ～ | H43: 42880 | I43: 10 | K43: 0 | L43: 460 | N43: =SUM(K43:M43) -> 460 | R43: =SUM(O43:Q43) -> 0 | S43: 7 | U43: UPS | V43: 実績 | W43: =R43/S43 -> 0 | AB43: UPS5932023020
...

Sheet KMP MPS
AB3: Ａｄｄ qyt→
AB4: Add ship date→
AB5: Add of maintenance→
AB6: Change qity→
AB7: Change type→
AB8: Change ship day→
AB9: Change qty&add→
AB10: Cancel→
AB11: All revised edition→
B13: KMP NEW ＭＰＳ（04/25/2020）
D14: 5948184-8 | E14: 5911267-2 | F14: 7961962-5 | G14: 5911295-8 | H14: 5911210-9 | I14: 5981329-8 | J14: 5964105-5 | K14: 5964106-3 | L14: 1889107-1 | M14: 5992295-0 | N14: 5981353-0 | O14: 1858395-4 | P14: 6911025-2 | Q14: 5992238-0 | R14: 6993321-6 | S14: 1870994-0 | T14: 1870955-9 | U14: 1874748-5 | V14: 1881236-8 | W14: 3734917-2 | AC14: Comparison with the last time
B15: MPS date | C15: KMP Shipment | D15: LAR101 | E15: LAJ101 | F15: LAE100 | G15: LAG101 | H15: LAL101 | I15: LAC101 | J15: LAD101 | K15: LAF101 | L15: LAF093 | M15: LAC092 | N15: LAC093 | O15: LAC094 | P15: LAD001 | Q15: LAD001 | R15: LAC034 | S15: LAC071 | T15: LAD071 | U15: LAC098 | V15: LAC099 | W15: LAC081 | AA15: TOTAL | AC15: LAR101 | AD15: LAJ101 | AE15: LAE100 | AF15: LAG101 | AG15: LAL101 | AH15: LAC101 | AI15: LAD101 | AJ15: LAF101 | AK15: LAF093 | AL15: LAC092 | AM15: LAC093 | AN15: LAC094 | AO15: LAD025 | AP15: LAD238 | AQ15: LAC034 | AR15: LAC071 | AS15: LAD071 | AT15: LAC098 | AU15: LAC099 | AV15: LAC081
C16: 43956 | D16: 0 | E16: 0 | F16: 0 | G16: 0 | H16: 0 | I16: 0 | J16: 0 | K16: 0 | L16: 0 | M16: 0 | N16: 0 | O16: 0 | P16: 0 | Q16: 0 | R16: 0 | S16: 0 | T16: 0 | U16: 0 | V16: 0 | W16: 0 | AA16: =SUM(D16:W16) -> 0 | AC16: 0 | AD16: 0 | AE16: 0 | AF16: 0 | AG16: 0 | AH16: 0 | AI16: 0 | AJ16: 0 | AK16: 0 | AL16: 0 | AM16: 0 | AN16: 0 | AO16: 0 | AP16: 0 | AQ16: 0 | AR16: 0 | AS16: 0 | AT16: 0 | AU16: 0 | AV16: 0
C17: 43969 | D17: 0 | E17: 0 | F17: 0 | G17: 0 | H17: 0 | I17: 0 | J17: 0 | K17: 0 | L17: 0 | M17: 0 | N17: 0 | O17: 0 | P17: 0 | Q17: 0 | R17: 0 | S17: 0 | T17: 0 | U17: 0 | V17: 0 | W17: 0 | AA17: =SUM(D17:W17) -> 0 | AC17: 0 | AD17: 0 | AE17: 0 | AF17: 0 | AG17: 0 | AH17: 0 | AI17: 0 | AJ17: 0 | AK17: 0 | AL17: 0 | AM17: 0 | AN17: 0 | AO17: 0 | AP17: 0 | AQ17: 0 | AR17: 0 | AS17: 0 | AT17: 0 | AU17: 0 | AV17: 0
C18: 43974 | D18: 0 | E18: 0 | F18: 0 | G18: 0 | H18: 0 | I18: 0 | J18: 0 | K18: 0 | L18: 0 | M18: 0 | N18: 0 | O18: 0 | P18: 0 | Q18: 0 | R18: 0 | S18: 0 | T18: 0 | U18: 0 | V18: 0 | W18: 0 | AA18: =SUM(D18:W18) -> 0 | AC18: 0 | AD18: 0 | AE18: 0 | AF18: 0 | AG18: 0 | AH18: 0 | AI18: 0 | AJ18: 0 | AK18: 0 | AL18: 0 | AM18: 0 | AN18: 0 | AO18: 0 | AP18: 0 | AQ18: 0 | AR18: 0 | AS18: 0 | AT18: 0 | AU18: 0 | AV18: 0
C19: 43981 | D19: 0 | E19: 0 | F19: 0 | G19: 0 | H19: 0 | I19: 0 | J19: 0 | K19: 0 | L19: 0 | M19: 0 | N19: 0 | O19: 0 | P19: 0 | Q19: 0 | R19: 0 | S19: 0 | T19: 0 | U19: 0 | V19: 0 | W19: 0 | AA19: =SUM(D19:W19) -> 0 | AC19: 0 | AD19: 0 | AE19: 0 | AF19: 0 | AG19: 0 | AH19: 0 | AI19: 0 | AJ19: 0 | AK19: 0 | AL19: 0 | AM19: 0 | AN19: 0 | AO19: 0 | AP19: 0 | AQ19: 0 | AR19: 0 | AS19: 0 | AT19: 0 | AU19: 0 | AV19: 0
C20: 43985 | D20: 0 | E20: 0 | F20: 0 | G20: 0 | H20: 0 | I20: 0 | J20: 0 | K20: 0 | L20: 0 | M20: 0 | N20: 0 | O20: 0 | P20: 0 | Q20: 0 | R20: 0 | S20: 0 | T20: 0 | U20: 0 | V20: 0 | W20: 0 | AA20: =SUM(D20:W20) -> 0 | AC20: 0 | AD20: 0 | AE20: 0 | AF20: 0 | AG20: 0 | AH20: 0 | AI20: 0 | AJ20: 0 | AK20: 0 | AL20: 0 | AM20: 0 | AN20: 0 | AO20: 0 | AP20: 0 | AQ20: 0 | AR20: 0 | AS20: 0 | AT20: 0 | AU20: 0 | AV20: 0
C21: 43991 | D21: 0 | E21: 0 | F21: 0 | G21: 0 | H21: 0 | I21: 0 | J21: 0 | K21: 0 | L21: 0 | M21: 0 | N21: 0 | O21: 0 | P21: 0 | Q21: 0 | R21: 0 | S21: 0 | T21: 0 | U21: 0 | V21: 0 | W21: 0 | AA21: =SUM(D21:W21) -> 0 | AC21: 0 | AD21: 0 | AE21: 0 | AF21: 0 | AG21: 0 | AH21: 0 | AI21: 0 | AJ21: 0 | AK21: 0 | AL21: 0 | AM21: 0 | AN21: 0 | AO21: 0 | AP21: 0 | AQ21: 0 | AR21: 0 | AS21: 0 | AT21: 0 | AU21: 0 | AV21: 0
C22: 43995 | D22: 0 | E22: 0 | F22: 0 | G22: 0 | H22: 0 | I22: 0 | J22: 0 | K22: 0 | L22: 0 | M22: 0 | N22: 0 | O22: 0 | P22: 0 | Q22: 0 | R22: 0 | S22: 0 | T22: 0 | U22: 0 | V22: 0 | W22: 0 | AA22: =SUM(D22:W22) -> 0 | AC22: 0 | AD22: 0 | AE22: 0 | AF22: 0 | AG22: 0 | AH22: 0 | AI22: 0 | AJ22: 0 | AK22: 0 | AL22: 0 | AM22: 0 | AN22: 0 | AO22: 0 | AP22: 0 | AQ22: 0 | AR22: 0 | AS22: 0 | AT22: 0 | AU22: 0 | AV22: 0
