Workbook
Name __DAT1: #REF!
Name __DAT10: #REF!
Name __DAT11: #REF!
Name __DAT12: #REF!
Name __DAT2: #REF!
Name __DAT3: #REF!
Name __DAT4: #REF!
Name __DAT5: #REF!
Name __DAT6: #REF!
Name __DAT7: #REF!
Name __DAT8: #REF!
Name __DAT9: #REF!
Name _DAT1: #REF!
Name _DAT10: #REF!
Name _DAT11: #REF!
Name _DAT12: #REF!
Name _DAT2: #REF!
Name _DAT3: #REF!
Name _DAT4: #REF!
Name _DAT5: #REF!
Name _DAT6: #REF!
Name _DAT7: #REF!
Name _DAT8: #REF!
Name _DAT9: #REF!
Name KEN_ALL: #REF!
Name PS: '[1]DCH-PS'!$A$1:$BA$906
Name Sheet1_クエリ: #REF!
Name TEST1: #REF!
Name TESTHKEY: #REF!
Name TESTKEYS: #REF!
Name TESTVKEY: #REF!
Name V8structure2: #REF!
Name Ｖ８構成: #REF!
Name クエリ1: '[2]06下期協定'!$A$13:$BZ$2217
Name クエリ5: #REF!
Name ダイフクＰ１計: #REF!
Name ダイフクＰ２計: #REF!
Name 委託先ﾁｬｰｼﾞ間: #REF!
Name 委託先ﾁｬｰｼﾞ計: #REF!
Name 委託先ﾁｬｰｼﾞ直: #REF!
Name 委託先外加工費: #REF!
Name 委託先外間: #REF!
Name 委託先間接費: #REF!
Name 委託先工費: #REF!
Name 委託先直労費: #REF!
Name 委託先内間: #REF!
Name 運賃: #REF!
Name 外間ＳＴ: #REF!
Name 管販費: [3]光真!#REF!
Name 希望ﾁｬｰｼﾞ: #REF!
Name 希望加工費: #REF!
Name 希望外加工費: #REF!
Name 希望外間: #REF!
Name 希望管理費: #REF!
Name 希望間ﾁｬｰｼﾞ: #REF!
Name 希望仕切値: #REF!
Name 希望総合ﾁｬｰｼﾞ: #REF!
Name 希望直ﾁｬｰｼﾞ: #REF!
Name 希望直労費: #REF!
Name 希望内間: #REF!

Sheet Ｖ８星取表
M1: 1 | N1: 2 | O1: 3 | P1: 4 | Q1: 5 | R1: 6 | S1: 7 | T1: 8 | U1: 9 | V1: 10 | W1: 11 | X1: 12 | Y1: 13 | Z1: 14 | AA1: 15 | AB1: 16 | AC1: 17 | AD1: 18 | AE1: 19 | AF1: 20 | AG1: 21 | AH1: 22 | AI1: 23 | AJ1: 24 | AK1: 25 | AL1: 26 | AM1: 27 | AN1: 28 | AO1: 29 | AP1: 30 | AQ1: 31 | AR1: 32 | AS1: 33 | AT1: 34 | AU1: 35 | AV1: 36 | AW1: 37 | AX1: 38 | AY1: 39 | AZ1: 40 | BA1: 41 | BB1: 42 | BC1: 43 | BD1: 44 | BE1: 45 | BF1: 46 | BG1: 47 | BH1: 48 | BI1: 49 | BJ1: 50
S2: KMP UNITS | AP2: KOUSHIN JAPAN UNITS
P3: =COUNTIF(#REF!,"・") -> #REF! | R3: ・→ | S3: =COUNTIF(#REF!,"・") -> #REF! | T3: =COUNTIF(#REF!,"・") -> #REF! | U3: =COUNTIF(#REF!,"・") -> #REF! | V3: =COUNTIF(#REF!,"・") -> #REF! | W3: =COUNTIF(#REF!,"・") -> #REF! | X3: =COUNTIF(#REF!,"・") -> #REF! | Y3: =COUNTIF(#REF!,"・") -> #REF! | Z3: =COUNTIF(#REF!,"・") -> #REF! | ... AY3: =COUNTIF(#REF!,"・") -> #REF!
P4: =COUNTIF(#REF!,"1/13") -> #REF! | S4: 0184429-0 | T4: 1876212-3 | U4: 3249850-1 | V4: 3139386-2 | W4: 1876278-6 | X4: 3729591-9 | Y4: 0184763-0 | Z4: 9064355-4 | AA4: 9912506-8 | AB4: 1876267-0 | AC4: 3729668-0 | AD4: 1876265-4 | AE4: 1876242-5 | AF4: 3139392-7 | AG4: 1876244-1 | AH4: 1868741-5 | AI4: 3139382-0 | AJ4: 1868739-3 | AK4: 5343350-7 | AL4: 1868742-3 | AM4: 3139404-4 | AN4: 1868740-7 | AO4: 5343349-3 | AP4: 1892440-9 | AQ4: 3729514-5 | AR4: 3247289-8 | AS4: 0184427-4 | AT4: 9066030-0 | AU4: 3139406-0 | AV4: 9912561-0 | AW4: 1876275-1 | AX4: 1892439-5 | AY4: 1876277-8
A5: ＊5/17生産計画 | K5: ａ (OCｶﾚ） | N5: b (光真ｶﾚ） | O5: b-4日 (光真ｶﾚ） | P5: ａ-3日 (光真ｶﾚ） | Q5: ａ (OCｶﾚ） | S5: ﾊﾝｿｳﾌﾞ | T5: 5000ｴﾝﾌﾞ | U5: 5000ｴﾝﾌﾞ | V5: 5000ｴﾝﾌﾞ | W5: ﾂﾘｼﾍｲ ﾎﾘﾕｳﾌﾞ | X5: ﾂﾘｼﾍｲ ﾎﾘﾕｳﾌﾞ | Y5: ｿｳﾆﾕｳｳﾌﾞ | Z5: ｿｳﾆﾕｳｳﾌﾞ | AA5: ｿｳﾆﾕｳｳﾌﾞ | AB5: ﾎｷﾕｳﾌﾞ ｺｳﾎｳ | AC5: ﾎｷﾕｳﾌﾞ ｺｳﾎｳ | AD5: ﾀｲﾋﾌﾞ | AE5: ｶｲｼﾕｳﾌﾞ （固定式） | AF5: ｶｲｼﾕｳﾌﾞ （固定式） | AG5: ｶｲｼﾕｳﾌﾞ （可搬式） | AH5: 10000ｴﾝﾌﾞ （固定式） | AI5: 10000ｴﾝﾌﾞ （固定式） | AJ5: 10000ｴﾝﾌﾞ （可搬式） | AK5: 10000ｴﾝﾌﾞ （可搬式） | AL5: 1000ｴﾝ ｶｾﾂﾄﾌﾞ （固定式） | AM5: 1000ｴﾝ ｶｾﾂﾄﾌﾞ （固定式） | AN5: 1000ｴﾝ ｶｾﾂﾄﾌﾞ （可搬式） | AO5: 1000ｴﾝ ｶｾﾂﾄﾌﾞ （可搬式） | AP5: ｷﾎﾝﾌﾞ BH | AQ5: ｷﾎﾝﾌﾞ BH | AR5: ｷﾎﾝﾌﾞ BH | AS5: ｷﾎﾝﾌﾞ BH | AT5: ｷﾎﾝﾌﾞ BH | AU5: ｷﾎﾝﾌﾞ BH | AV5: ｷﾎﾝﾌﾞ BH | AW5: ﾌﾚ-ﾑﾌﾞ | AX5: ﾌﾚ-ﾑﾌﾞ | AY5: ﾚ-ﾙﾌﾞ
A6: T-No （LAY） | B6: Z002 号機 | C6: Z003 号機 | D6: Z004 号機 | E6: Z101 号機 | F6: Z102 号機 | G6: Z103 号機 | H6: Z201 号機 | I6: ＢＨ型式 | J6: 順序 確定日 | K6: 光真 順序 出荷日 | L6: 実出荷 | M6: KP-No | N6: LAZ 完了 計画 | O6: KMP ユニット 日本着日 | P6: KMP ユニット 日本着日 | Q6: LAZ/ｶｾｯﾄ LAL/LBL J-光真 出荷計画 | R6: メンテ | S6: LAA101 | T6: LAF001 | U6: LAF002 | V6: LAF003 | W6: LAG001 | X6: LAG002 | Y6: LAE101 | Z6: LAE102 | AA6: LAE201 | AB6: LBL001 | AC6: LBL002 | AD6: LAL001 | AE6: LAN001 | AF6: LAN002 | AG6: LCN001 | AH6: LAC001 | AI6: LAC002 | AJ6: LCC001 | AK6: LCC002 | AL6: LAD001 | AM6: LAD002 | AN6: LCD001 | AO6: LCD002 | AP6: LAZ002 | AQ6: LAZ003 | AR6: LAZ004 | AS6: LAZ101 | AT6: LAZ102 | AU6: LAZ103 | AV6: LAZ201 | AW6: LAY001 | AX6: LAY002 | AY6: LAH001 | AZ6: 生産 計画 No | BA6: 客先名 | BB6: 駅名 ﾒﾝﾃﾕﾆｯﾄ型式（個/ﾛｯﾄ） | BC6: コーナー メンテ：情報提供者 （情報入手日） | BD6: ﾕﾆｯﾄ 種類数 | BE6: BH型式 | BF6: 出荷日 | BG6: T-No （LAY） | BH6: LAZ ﾕﾆｯﾄ | BI6: 1F 出荷 | BJ6: ﾒﾝﾃﾕﾆｯﾄ 型式
J7: 45750 | K7: 45785 | L7: 45785 | M7: MB-07688 | O7: 45771 | Q7: 45785 | R7: M | S7: 45742 | AZ7: 000367644 | BA7: OFET | BB7: LAA101（1/1） | BC7: （10/18平嶌様情報） | BD7: =COUNTA(S7:AY7) -> 1 | BE7: =I7 -> 0 | BF7: =K7 -> 45785 | BG7: =A7 -> 0 | BH7: =COUNTA(S7:AA7) -> 1 | BI7: =COUNTA(AB7:AO7) -> 0 | BJ7: LAA101
J8: 45754 | K8: 45789 | L8: 45789 | M8: MB-07691 | O8: 45784 | Q8: 45789 | R8: M | S8: 45772 | AZ8: 000369841 | BA8: OFET | BB8: LAA101（1/2） | BC8: （24/12/07DB公開） | BD8: =COUNTA(S8:AY8) -> 1 | BE8: =I8 -> 0 | BF8: =K8 -> 45789 | BG8: =A8 -> 0 | BH8: =COUNTA(S8:AA8) -> 1 | BI8: =COUNTA(AB8:AO8) -> 0 | BJ8: LAA101
J9: 45754 | K9: 45789 | L9: 45789 | M9: MB-07691 | O9: 45784 | Q9: 45789 | R9: M | S9: 45772 | AZ9: 000369841 | BA9: OFET | BB9: LAA101（2/2） | BC9: （24/12/07DB公開） | BD9: =COUNTA(S9:AY9) -> 1 | BE9: =I9 -> 0 | BF9: =K9 -> 45789 | BG9: =A9 -> 0 | BH9: =COUNTA(S9:AA9) -> 1 | BI9: =COUNTA(AB9:AO9) -> 0 | BJ9: LAA101
A10: 21115 | B10: 3131 | I10: VU-LA007 | J10: 45770 | K10: 45790 | L10: 45790 | M10: MC-50218 | N10: 45789 | O10: 45784 | P10: 45786 | Q10: 45790 | S10: 45772 | T10: 45772 | W10: 45772 | Y10: 45772 | AD10: 45772 | AE10: 45772 | AH10: 45772 | AL10: 45772 | AP10: ・ | AX10: ・ | AY10: ・ | AZ10: 000373824 | BA10: N社（Ｎ） | BC10: VU-LA007 | BD10: 11 | BE10: =I10 -> VU-LA007 | BF10: =K10 -> 45790 | BG10: =A10 -> 21115 | BH10: =COUNTA(S10:AA10) -> 4 | BI10: =COUNTA(AB10:AO10) -> 4
A11: 21116 | B11: 3132 | I11: VU-LA007 | J11: 45770 | K11: 45790 | L11: 45790 | M11: MC-50219 | N11: 45789 | O11: 45784 | P11: 45786 | Q11: 45790 | S11: 45772 | T11: 45772 | W11: 45772 | Y11: 45772 | AD11: 45772 | AE11: 45772 | AH11: 45772 | AL11: 45772 | AP11: ・ | AX11: ・ | AY11: ・ | AZ11: 000377304 | BA11: N社（Ｎ） | BC11: VU-LA007 | BD11: 11 | BE11: =I11 -> VU-LA007 | BF11: =K11 -> 45790 | BG11: =A11 -> 21116 | BH11: =COUNTA(S11:AA11) -> 4 | BI11: =COUNTA(AB11:AO11) -> 4
A12: 21117 | B12: 3133 | I12: VU-LA007 | J12: 45771 | K12: 45791 | L12: 45791 | M12: MC-50223 | N12: 45790 | O12: 45785 | P12: 45787 | Q12: 45791 | S12: 45772 | T12: 45772 | W12: 45772 | Y12: 45772 | AD12: 45772 | AE12: 45772 | AH12: 45772 | AL12: 45772 | AP12: ・ | AX12: ・ | AY12: ・ | AZ12: 000377306 | BA12: N社（Ｎ） | BC12: VU-LA007 | BD12: 11 | BE12: =I12 -> VU-LA007 | BF12: =K12 -> 45791 | BG12: =A12 -> 21117 | BH12: =COUNTA(S12:AA12) -> 4 | BI12: =COUNTA(AB12:AO12) -> 4
A13: 21118 | B13: 3134 | I13: VU-LA007 | J13: 45771 | K13: 45791 | L13: 45791 | M13: MC-50224 | N13: 45790 | O13: 45785 | P13: 45787 | Q13: 45791 | S13: 45772 | T13: 45772 | W13: 45772 | Y13: 45772 | AD13: 45772 | AE13: 45772 | AH13: 45772 | AL13: 45772 | AP13: ・ | AX13: ・ | AY13: ・ | AZ13: 000377308 | BA13: N社（Ｎ） | BC13: VU-LA007 | BD13: 11 | BE13: =I13 -> VU-LA007 | BF13: =K13 -> 45791 | BG13: =A13 -> 21118 | BH13: =COUNTA(S13:AA13) -> 4 | BI13: =COUNTA(AB13:AO13) -> 4
A14: 21119 | B14: 3135 | I14: VU-LA007 | J14: 45772 | K14: 45792 | L14: 45792 | M14: MC-50227 | N14: 45791 | O14: 45786 | P14: 45789 | Q14: 45792 | S14: 45772 | T14: 45772 | W14: 45772 | Y14: 45772 | AD14: 45772 | AE14: 45772 | AH14: 45772 | AL14: 45772 | AP14: ・ | AX14: ・ | AY14: ・ | AZ14: 000377305 | BA14: N社（Ｎ） | BC14: VU-LA007 | BD14: 11 | BE14: =I14 -> VU-LA007 | BF14: =K14 -> 45792 | BG14: =A14 -> 21119 | BH14: =COUNTA(S14:AA14) -> 4 | BI14: =COUNTA(AB14:AO14) -> 4
A15: 21120 | B15: 3136 | I15: VU-LA007 | J15: 45772 | K15: 45792 | L15: 45792 | M15: MC-50228 | N15: 45791 | O15: 45786 | P15: 45789 | Q15: 45792 | S15: 45772 | T15: 45772 | W15: 45772 | Y15: 45772 | AD15: 45772 | AE15: 45772 | AH15: 45772 | AL15: 45772 | AP15: ・ | AX15: ・ | AY15: ・ | AZ15: 000377307 | BA15: N社（Ｎ） | BC15: VU-LA007 | BD15: 11 | BE15: =I15 -> VU-LA007 | BF15: =K15 -> 45792 | BG15: =A15 -> 21120 | BH15: =COUNTA(S15:AA15) -> 4 | BI15: =COUNTA(AB15:AO15) -> 4
A16: 21121 | B16: 3137 | I16: VU-LA007 | J16: 45775 | K16: 45793 | L16: 45793 | M16: MC-50231 | N16: 45792 | O16: 45787 | P16: 45790 | Q16: 45793 | S16: 45772 | T16: 45772 | W16: 45772 | Y16: 45772 | AD16: 45772 | AE16: 45772 | AH16: 45772 | AL16: 45772 | AP16: ・ | AX16: ・ | AY16: ・ | AZ16: 000366813 | BA16: N社（Ｎ） | BC16: VU-LA007 | BD16: 11 | BE16: =I16 -> VU-LA007 | BF16: =K16 -> 45793 | BG16: =A16 -> 21121 | BH16: =COUNTA(S16:AA16) -> 4 | BI16: =COUNTA(AB16:AO16) -> 4
A17: 21122 | B17: 3138 | I17: VU-LA007 | J17: 45775 | K17: 45793 | L17: 45793 | M17: MC-50232 | N17: 45792 | O17: 45787 | P17: 45790 | Q17: 45793 | S17: 45772 | T17: 45772 | W17: 45772 | Y17: 45772 | AD17: 45772 | AE17: 45772 | AH17: 45772 | AL17: 45772 | AP17: ・ | AX17: ・ | AY17: ・ | AZ17: 000377315 | BA17: N社（Ｎ） | BC17: VU-LA007 | BD17: 11 | BE17: =I17 -> VU-LA007 | BF17: =K17 -> 45793 | BG17: =A17 -> 21122 | BH17: =COUNTA(S17:AA17) -> 4 | BI17: =COUNTA(AB17:AO17) -> 4
J18: 45758 | K18: 45793 | L18: 45793 | M18: MB-07702 | O18: 45789 | Q18: 45793 | R18: M | T18: 45772 | AZ18: 000368748 | BA18: OFET | BB18: LAF001（1/5） | BC18: （11/7平嶌様情報） | BD18: =COUNTA(S18:AY18) -> 1 | BE18: =I18 -> 0 | BF18: =K18 -> 45793 | BG18: =A18 -> 0 | BH18: =COUNTA(S18:AA18) -> 1 | BI18: =COUNTA(AB18:AO18) -> 0 | BJ18: LAF001
J19: 45758 | K19: 45793 | L19: 45793 | M19: MB-07702 | O19: 45789 | Q19: 45793 | R19: M | T19: 45772 | AZ19: 000368748 | BA19: OFET | BB19: LAF001（2/5） | BC19: （11/7平嶌様情報） | BD19: =COUNTA(S19:AY19) -> 1 | BE19: =I19 -> 0 | BF19: =K19 -> 45793 | BG19: =A19 -> 0 | BH19: =COUNTA(S19:AA19) -> 1 | BI19: =COUNTA(AB19:AO19) -> 0 | BJ19: LAF001
J20: 45758 | K20: 45793 | L20: 45793 | M20: MB-07702 | O20: 45789 | Q20: 45793 | R20: M | T20: 45772 | AZ20: 000368748 | BA20: OFET | BB20: LAF001（3/5） | BC20: （11/7平嶌様情報） | BD20: =COUNTA(S20:AY20) -> 1 | BE20: =I20 -> 0 | BF20: =K20 -> 45793 | BG20: =A20 -> 0 | BH20: =COUNTA(S20:AA20) -> 1 | BI20: =COUNTA(AB20:AO20) -> 0 | BJ20: LAF001
J21: 45758 | K21: 45793 | L21: 45793 | M21: MB-07702 | O21: 45789 | Q21: 45793 | R21: M | T21: 45772 | AZ21: 000368748 | BA21: OFET | BB21: LAF001（4/5） | BC21: （11/7平嶌様情報） | BD21: =COUNTA(S21:AY21) -> 1 | BE21: =I21 -> 0 | BF21: =K21 -> 45793 | BG21: =A21 -> 0 | BH21: =COUNTA(S21:AA21) -> 1 | BI21: =COUNTA(AB21:AO21) -> 0 | BJ21: LAF001
J22: 45758 | K22: 45793 | L22: 45793 | M22: MB-07702 | O22: 45789 | Q22: 45793 | R22: M | T22: 45772 | AZ22: 000368748 | BA22: OFET | BB22: LAF001（5/5） | BC22: （11/7平嶌様情報） | BD22: =COUNTA(S22:AY22) -> 1 | BE22: =I22 -> 0 | BF22: =K22 -> 45793 | BG22: =A22 -> 0 | BH22: =COUNTA(S22:AA22) -> 1 | BI22: =COUNTA(AB22:AO22) -> 0 | BJ22: LAF001
J23: 45758 | K23: 45793 | L23: 45793 | M23: MB-07700 | P23: 45790 | Q23: 45793 | R23: M | AH23: 45772 | AZ23: 000368747 | BA23: OFET | BB23: LAC001（1/5） | BC23: （11/7平嶌様情報） | BD23: =COUNTA(S23:AY23) -> 1 | BE23: =I23 -> 0 | BF23: =K23 -> 45793 | BG23: =A23 -> 0 | BH23: =COUNTA(S23:AA23) -> 0 | BI23: =COUNTA(AB23:AO23) -> 1 | BJ23: LAC001
J24: 45758 | K24: 45793 | L24: 45793 | M24: MB-07700 | P24: 45790 | Q24: 45793 | R24: M | AH24: 45772 | AZ24: 000368747 | BA24: OFET | BB24: LAC001（2/5） | BC24: （11/7平嶌様情報） | BD24: =COUNTA(S24:AY24) -> 1 | BE24: =I24 -> 0 | BF24: =K24 -> 45793 | BG24: =A24 -> 0 | BH24: =COUNTA(S24:AA24) -> 0 | BI24: =COUNTA(AB24:AO24) -> 1 | BJ24: LAC001
J25: 45758 | K25: 45793 | L25: 45793 | M25: MB-07700 | P25: 45790 | Q25: 45793 | R25: M | AH25: 45772 | AZ25: 000368747 | BA25: OFET | BB25: LAC001（3/5） | BC25: （11/7平嶌様情報） | BD25: =COUNTA(S25:AY25) -> 1 | BE25: =I25 -> 0 | BF25: =K25 -> 45793 | BG25: =A25 -> 0 | BH25: =COUNTA(S25:AA25) -> 0 | BI25: =COUNTA(AB25:AO25) -> 1 | BJ25: LAC001
J26: 45758 | K26: 45793 | L26: 45793 | M26: MB-07700 | P26: 45790 | Q26: 45793 | R26: M | AH26: 45772 | AZ26: 000368747 | BA26: OFET | BB26: LAC001（4/5） | BC26: （11/7平嶌様情報） | BD26: =COUNTA(S26:AY26) -> 1 | BE26: =I26 -> 0 | BF26: =K26 -> 45793 | BG26: =A26 -> 0 | BH26: =COUNTA(S26:AA26) -> 0 | BI26: =COUNTA(AB26:AO26) -> 1 | BJ26: LAC001
J27: 45758 | K27: 45793 | L27: 45793 | M27: MB-07700 | P27: 45790 | Q27: 45793 | R27: M | AH27: 45772 | AZ27: 000368747 | BA27: OFET | BB27: LAC001（5/5） | BC27: （11/7平嶌様情報） | BD27: =COUNTA(S27:AY27) -> 1 | BE27: =I27 -> 0 | BF27: =K27 -> 45793 | BG27: =A27 -> 0 | BH27: =COUNTA(S27:AA27) -> 0 | BI27: =COUNTA(AB27:AO27) -> 1 | BJ27: LAC001
J28: 45758 | K28: 45793 | L28: 45793 | M28: MB-07701 | P28: 45790 | Q28: 45793 | R28: M | AL28: 45772 | AZ28: 000368746 | BA28: OFET | BB28: LAD001（1/5） | BC28: （11/7平嶌様情報） | BD28: =COUNTA(S28:AY28) -> 1 | BE28: =I28 -> 0 | BF28: =K28 -> 45793 | BG28: =A28 -> 0 | BH28: =COUNTA(S28:AA28) -> 0 | BI28: =COUNTA(AB28:AO28) -> 1 | BJ28: LAD001
J29: 45758 | K29: 45793 | L29: 45793 | M29: MB-07701 | P29: 45790 | Q29: 45793 | R29: M | AL29: 45772 | AZ29: 000368746 | BA29: OFET | BB29: LAD001（2/5） | BC29: （11/7平嶌様情報） | BD29: =COUNTA(S29:AY29) -> 1 | BE29: =I29 -> 0 | BF29: =K29 -> 45793 | BG29: =A29 -> 0 | BH29: =COUNTA(S29:AA29) -> 0 | BI29: =COUNTA(AB29:AO29) -> 1 | BJ29: LAD001
J30: 45758 | K30: 45793 | L30: 45793 | M30: MB-07701 | P30: 45790 | Q30: 45793 | R30: M | AL30: 45772 | AZ30: 000368746 | BA30: OFET | BB30: LAD001（3/5） | BC30: （11/7平嶌様情報） | BD30: =COUNTA(S30:AY30) -> 1 | BE30: =I30 -> 0 | BF30: =K30 -> 45793 | BG30: =A30 -> 0 | BH30: =COUNTA(S30:AA30) -> 0 | BI30: =COUNTA(AB30:AO30) -> 1 | BJ30: LAD001
J31: 45758 | K31: 45793 | L31: 45793 | M31: MB-07701 | P31: 45790 | Q31: 45793 | R31: M | AL31: 45772 | AZ31: 000368746 | BA31: OFET | BB31: LAD001（4/5） | BC31: （11/7平嶌様情報） | BD31: =COUNTA(S31:AY31) -> 1 | BE31: =I31 -> 0 | BF31: =K31 -> 45793 | BG31: =A31 -> 0 | BH31: =COUNTA(S31:AA31) -> 0 | BI31: =COUNTA(AB31:AO31) -> 1 | BJ31: LAD001
J32: 45758 | K32: 45793 | L32: 45793 | M32: MB-07701 | P32: 45790 | Q32: 45793 | R32: M | AL32: 45772 | AZ32: 000368746 | BA32: OFET | BB32: LAD001（5/5） | BC32: （11/7平嶌様情報） | BD32: =COUNTA(S32:AY32) -> 1 | BE32: =I32 -> 0 | BF32: =K32 -> 45793 | BG32: =A32 -> 0 | BH32: =COUNTA(S32:AA32) -> 0 | BI32: =COUNTA(AB32:AO32) -> 1 | BJ32: LAD001
A33: 21123 | B33: 3139 | I33: VU-LA007 | J33: 45784 | K33: 45796 | L33: 45796 | M33: MC-50283 | N33: 45793 | O33: 45789 | P33: 45791 | Q33: 45796 | S33: 45772 | T33: 45772 | W33: 45772 | Y33: 45772 | AD33: 45772 | AE33: 45772 | AH33: 45772 | AL33: 45772 | AP33: ・ | AX33: ・ | AY33: ・ | AZ33: 000377313 | BA33: N社（Ｎ） | BC33: VU-LA007 | BD33: 11 | BE33: =I33 -> VU-LA007 | BF33: =K33 -> 45796 | BG33: =A33 -> 21123 | BH33: =COUNTA(S33:AA33) -> 4 | BI33: =COUNTA(AB33:AO33) -> 4
A34: 21124 | B34: 3140 | I34: VU-LA007 | J34: 45784 | K34: 45796 | L34: 45796 | M34: MC-50284 | N34: 45793 | O34: 45789 | P34: 45791 | Q34: 45796 | S34: 45772 | T34: 45772 | W34: 45772 | Y34: 45772 | AD34: 45772 | AE34: 45772 | AH34: 45772 | AL34: 45772 | AP34: ・ | AX34: ・ | AY34: ・ | AZ34: 000377316 | BA34: N社（Ｎ） | BC34: VU-LA007 | BD34: 11 | BE34: =I34 -> VU-LA007 | BF34: =K34 -> 45796 | BG34: =A34 -> 21124 | BH34: =COUNTA(S34:AA34) -> 4 | BI34: =COUNTA(AB34:AO34) -> 4
A35: 21125 | B35: 3141 | I35: VU-LA007 | J35: 45785 | K35: 45797 | L35: 45797 | M35: MC-50287 | N35: 45796 | O35: 45790 | P35: 45792 | Q35: 45797 | S35: 45772 | T35: 45772 | W35: 45772 | Y35: 45772 | AD35: 45772 | AE35: 45772 | AH35: 45772 | AL35: 45772 | AP35: ・ | AX35: ・ | AY35: ・ | AZ35: 000377314 | BA35: N社（Ｎ） | BC35: VU-LA007 | BD35: 11 | BE35: =I35 -> VU-LA007 | BF35: =K35 -> 45797 | BG35: =A35 -> 21125 | BH35: =COUNTA(S35:AA35) -> 4 | BI35: =COUNTA(AB35:AO35) -> 4
A36: 21126 | B36: 3142 | I36: VU-LA007 | J36: 45786 | K36: 45798 | L36: 45798 | M36: MC-50289 | N36: 45797 | O36: 45791 | P36: 45793 | Q36: 45798 | S36: 45772 | T36: 45772 | W36: 45772 | Y36: 45772 | AD36: 45772 | AE36: 45772 | AH36: 45772 | AL36: 45772 | AP36: ・ | AX36: ・ | AY36: ・ | AZ36: 000377311 | BA36: N社（Ｎ） | BC36: VU-LA007 | BD36: 11 | BE36: =I36 -> VU-LA007 | BF36: =K36 -> 45798 | BG36: =A36 -> 21126 | BH36: =COUNTA(S36:AA36) -> 4 | BI36: =COUNTA(AB36:AO36) -> 4
J37: 45763 | K37: 45798 | L37: 45798 | M37: MB-07703 | P37: 45793 | Q37: 45798 | R37: M | AC37: 45772 | AZ37: 000369708 | BA37: 高見沢サービス | BB37: LBL002（1/3） | BC37: （11/7平嶌様情報） | BD37: =COUNTA(S37:AY37) -> 1 | BE37: =I37 -> 0 | BF37: =K37 -> 45798 | BG37: =A37 -> 0 | BH37: =COUNTA(S37:AA37) -> 0 | BI37: =COUNTA(AB37:AO37) -> 1 | BJ37: LBL002
J38: 45763 | K38: 45798 | L38: 45798 | M38: MB-07703 | P38: 45793 | Q38: 45798 | R38: M | AC38: 45772 | AZ38: 000369708 | BA38: 高見沢サービス | BB38: LBL002（2/3） | BC38: （11/7平嶌様情報） | BD38: =COUNTA(S38:AY38) -> 1 | BE38: =I38 -> 0 | BF38: =K38 -> 45798 | BG38: =A38 -> 0 | BH38: =COUNTA(S38:AA38) -> 0 | BI38: =COUNTA(AB38:AO38) -> 1 | BJ38: LBL002
J39: 45763 | K39: 45798 | L39: 45798 | M39: MB-07703 | P39: 45793 | Q39: 45798 | R39: M | AC39: 45772 | AZ39: 000369708 | BA39: 高見沢サービス | BB39: LBL002（3/3） | BC39: （11/7平嶌様情報） | BD39: =COUNTA(S39:AY39) -> 1 | BE39: =I39 -> 0 | BF39: =K39 -> 45798 | BG39: =A39 -> 0 | BH39: =COUNTA(S39:AA39) -> 0 | BI39: =COUNTA(AB39:AO39) -> 1 | BJ39: LBL002
A40: 21127 | B40: 3143 | I40: VU-LA007 | J40: 45789 | K40: 45799 | L40: 45799 | M40: MC-50291 | N40: 45798 | O40: 45792 | P40: 45796 | Q40: 45799 | S40: 45772 | T40: 45772 | W40: 45772 | Y40: 45772 | AD40: 45772 | AE40: 45772 | AH40: 45772 | AL40: 45772 | AP40: ・ | AX40: ・ | AY40: ・ | AZ40: 000373826 | BA40: N社（Ｎ） | BC40: VU-LA007 | BD40: 11 | BE40: =I40 -> VU-LA007 | BF40: =K40 -> 45799 | BG40: =A40 -> 21127 | BH40: =COUNTA(S40:AA40) -> 4 | BI40: =COUNTA(AB40:AO40) -> 4
...
